Workbook

Sheet INSTRUCTIONS
A1: DO NOT EDIT MASTER Market Analysis
A13: To Copy this sheet: File -> Make a copy
A17: Rename File with Title: {INSERT CITY}, {INSERT STATE} Market Analysis
A21: Make sure you move file to Shared Drive Sales and into the Market Analysis Folder

Sheet Accounts
A1: =IFERROR(__xludf.DUMMYFUNCTION("if(eq(COUNTA(A2:A199) - COUNTUNIQUE(A2:A199),0),""Accounts"", ""Accounts - Duplicate Found"")"),"Accounts") | B1: Account Type | C1: Contact Created? | D1: Address | E1: Uptown (Yes or No) | F1: Phone Number | G1: Email | H1: URL | I1: Self Parking Rate | J1: Valet Rate | K1: # of Rooms | L1: Parking Reviews % | M1: Parking Reviews # | N1: GM Name | O1: Management Group | P1: Linked Accounts | Q1: Garage Operator | R1: Valet Operator | S1: Sourcing Notes | T1: Location Notes
A2: Aloft Charlotte City Center | B2: Hotel | D2: 210 E Trade Street, Charlotte, NC, 28202 | E2: YES | F2: =17043331999 | H2: https://www.marriott.com/en-us/Hotels/cltul-aloft-charlotte-city-center/overview/ | I2: 30 | J2: 25 | K2: 175 | L2: 0.17 | M2: 156 | N2: Jay Brown | Q2: Preferred | R2: Preferred Parking
A3: Courtyard By Marriott | B3: Hotel | D3: 237 S Tryon St, Charlotte, NC 28202 | E3: YES | F3: (704) 926-5800 | H3: https://www.marriott.com/en-us/Hotels/cltup-courtyard-charlotte-city-center/overview/?scid=f2ae0541-1279-4f24-b197-a979c79310b0 | I3: 30 | K3: 181 | L3: 0.28 | M3: 95 | N3: Eric Knesel | Q3: LAZ | R3: None | T3: poor parking reviews, security maybe an issue
A4: Fairfield Inn & Suites | B4: Hotel | D4: 201 S McDowell St, Charlotte, NC 28204 | E4: YES | F4: (704) 372-7550 | H4: https://www.marriott.com/en-us/Hotels/cltut-fairfield-inn-and-suites-charlotte-uptown/overview/?scid=f2ae0541-1279-4f24-b197-a979c79310b0 | I4: 25 | K4: 196 | L4: 0.38 | M4: 103 | N4: Bill Moore - Left VM | R4: None | T4: Has really easy parking front drive for enterance, own their own parking deck
A5: Hampton Inn Uptown | B5: Hotel | D5: 530 E M.L.K. Jr Blvd, Charlotte, NC 28202 | E5: YES | H5: https://www.hilton.com/en/Hotels/cltsphx-hampton-suites-charlotte-south-park-at-phillips-place/?SEO_id=GMB-AMER-HX-CLTSPHX&y_source=1_MjA4NDc5MC03MTUtbG9jYXRpb24ud2Vic2l0ZQ%3D%3D | I5: 25 | K5: 250 | L5: 0.38 | M5: 156 | R5: None | T5: Valet only there in the evenings on weekends. no morning valet, left message with the AGM Michelle 6/6/23
A6: Hilton Garden Inn (SouthPark) | B6: Hotel | D6: 4808 Sharon Rd, Charlotte, NC 28210 | E6: NO | F6: (704) 362-5080 | H6: https://www.hilton.com/en/Hotels/cltskgi-hilton-garden-inn-charlotte-southpark/?SEO_id=GMB-AMER-GI-CLTSKGI&y_source=1_ODIxMTQxNS03MTUtbG9jYXRpb24ud2Vic2l0ZQ%3D%3D | I6: 10 | K6: 160 | L6: 0.79 | M6: 38 | N6: Tom Payne (Hours are usually 9-5 | R6: None
A7: Hilton/Hilton Garden Inn | B7: Hotel | D7: 508 E M.L.K. Jr Blvd, Charlotte, NC 28202 | E7: YES | F7: (704) 347-5972 | H7: https://www.hilton.com/en/Hotels/cltupgi-hilton-garden-inn-charlotte-uptown/ | I7: 25 | K7: 181 | L7: 0.39 | M7: 115 | R7: None | T7: Left a message with the GM on 6/6/23 letting them know about us and to give us a call back if valet service was of interested, for the Garden inn.
A8: Home2Suites | B8: Hotel | D8: 610 S Caldwell St, Charlotte, NC 28202 | E8: YES | F8: (980) 500-0085 Ext. for GM is 5002 Email for GM: stephanie.parisi@hilton.com NEW GM COMING 5/31/2022 | H8: https://www.hilton.com/en/Hotels/cltowht-home2-suites-charlotte-uptown/?SEO_id=GMB-AMER-HT-CLTOWHT&y_source=1_MTQ3MjI2OTAtNzE1LWxvY2F0aW9uLndlYnNpdGU%3D | I8: 25 | K8: 180 | L8: 0.26 | M8: 101 | N8: Tameka | R8: None | T8: Poor parking reviews
A9: Hilton Charlotte Uptown | B9: Hotel | D9: 222 East Third Street Charlotte NC 20802 | E9: YES | F9: 7043771500 | I9: 24 | J9: 34 | K9: 149 | L9: 0.51 | M9: 224 | R9: PMC
A10: Le Meridien Charlotte | B10: Hotel | D10: 555 S McDowell St Tower, Charlotte, NC 28204 | E10: YES | I10: 25 | J10: 35 | K10: 300 | L10: 0.25 | M10: 162 | T10: Currently No GM or Director of Ops
A11: Sheraton Hotel | B11: Hotel | D11: 555 S McDowell St Tower, Charlotte, NC 28204 | E11: YES | H11: https://www.marriott.com/en-us/Hotels/cltws-sheraton-charlotte-Hotel/overview/ | I11: 25 | J11: 35 | K11: 305 | L11: 0.24 | M11: 157
A12: The Ivey's Hotel | B12: Hotel | D12: 127 N Tryon St, Charlotte, NC 28202 | E12: YES | H12: https://www.theiveysHotel.com/ | J12: 35 | K12: 47 | L12: 0.52 | M12: 89 | Q12: LAZ | R12: PMC
A13: Hyatt Place | B13: Hotel | D13: 222 S Caldwell St, Charlotte NC 28202 | E13: YES | F13: 7042270500 | G13: Check your email/texts for contact updated | H13: tien.ning@hyatt.com | I13: n/a | J13: 38 | K13: 172 | L13: 0.72 | M13: 484 | N13: Tien Ning | R13: PMC | T13: pretty solid valet reviews. maybe bundled services or damage claim pitching
A14: The Dunhill | B14: Hotel | D14: 237 N Tryon St, Charlotte, NC 28202 | E14: YES | F14: (704) 332-4141 GM Ext. 7101 | H14: https://dunhillHotel.com/ | I14: 23 | J14: 38 | K14: 60 | L14: 0.43 | M14: 74 | Q14: LAZ | R14: In House
A15: AC Hotel Residents inn | B15: Hotel | D15: 220 East Trade Street, Suite 1400, Charlotte, NC, 28202 | E15: YES | F15: 7043484002 | G15: rob.cote@marriott.com | H15: https://www.marriott.com/en-us/Hotels/cltad-ac-Hotel-charlotte-city-center/overview/?scid=f2ae0541-1279-4f24-b197-a979c79310b0 | I15: 29 | J15: 40 | K15: 149 | L15: 0.52 | M15: 117 | N15: Rob Cote | Q15: Preferred | R15: PMC
A16: DoubleTree by Hilton Charlotte-Center City | B16: Hotel | D16: 230 N College Street, Charlotte, NC 28202 | E16: YES | I16: 32 | J16: 40 | K16: 187 | L16: 0.36 | M16: 182 | Q16: Preferred | T16: Not interested, Valet owned by brother of Hotel owner. GM Hung up on me when I asked for point of contact.
A17: Omni Hotel | B17: Hotel | D17: 132 E Trade St, Charlotte, NC 28202 | E17: YES | H17: https://www.omniHotels.com/Hotels/charlotte | J17: 40 | K17: 373 | L17: 0.39 | M17: 270 | Q17: LAZ | R17: PMC
A18: SpringHill | B18: Hotel | D18: 311 E 5th St, Charlotte, NC 28202 | E18: YES | F18: shsuptown@sree.com | H18: https://www.marriott.com/en-us/Hotels/cltsd-springhill-suites-charlotte-city-center/overview/?scid=f2ae0541-1279-4f24-b197-a979c79310b0 | I18: Not available | J18: 40 | K18: 195 | L18: 0.38 | M18: 190 | N18: Karen Owens | R18: PMC
A19: Element Charlotte Uptown | B19: Hotel | D19: 650 S Caldwell Street, Charlotte | E19: YES | F19: abethell@midashospitality.com 980-785-1900 | H19: https://www.marriott.com/search/findHotels.mi?pageType=advanced&searchType=NearAddress&destinationAddress.location=Element+Charlotte+Uptown&nst=paid&cid=PAI_GLB0004YXD_GLE000BIM5_GLF000OETA&ppc=ppc&pId=ustbppc&gad_source=1&gclid=CjwKCAjwvr--BhB5EiwAd5YbXnN16LTeyeEMZgiOqVjMxJLbm-3ljbJBxum8-isbcRtiH4LLoomBrRoCZToQAvD_BwE&gclsrc=aw.ds | J19: 42 | K19: 173 | L19: 0.18 | M19: 22 | N19: Ava Bethell | T19: terrible valet reviews, 67% negative. poor schedule, needs staff, annoyed for tips
A20: Hyatt House Charlotte Center City | B20: Hotel | D20: 435 E Trade St, Charlotte, NC 28202 | E20: YES | I20: n/a | J20: 42 | K20: 163 | L20: 0.41 | M20: 217
A21: Homewood Suites by Hilton Charlotte Uptown | B21: Hotel | D21: 508 N College St, Charlotte, NC 28202 | E21: YES | H21: https://www.hilton.com/en/Hotels/cltuchw-homewood-suites-charlotte-uptown-first-ward/?flexibleDates=false&numRooms=1&numAdults=1&numChildren=0&room1ChildAges=&room1AdultAges=&sessionToken=035f1355-cf11-48a0-a093-93e5c0a0926f | J21: 45 | K21: 211 | L21: 0.39 | M21: 79
A22: Embassy Suites by Hilton Charlotte Uptown | B22: Hotel | D22: 401 E M.L.K. Jr Blvd, Charlotte, NC 28202 | E22: YES | G22: mike.masri@hilton.com | H22: https://www.hilton.com/en/Hotels/cltmles-embassy-suites-charlotte-uptown/?SEO_id=GMB-AMER-ES-CLTMLES&y_source=1_OTUwNTM3MC03MTUtbG9jYXRpb24ud2Vic2l0ZQ%3D%3D | J22: 45 | L22: 0.36 | M22: 296 | N22: Mike Masri
A23: The Westin Charlotte | B23: Hotel | D23: 601 S College St, Charlotte, NC 28202 | E23: YES | F23: (704) 375-2600 | G23: Geoffrey.Cousineau @westin.com | H23: https://www.marriott.com/en-us/Hotels/cltcw-the-westin-charlotte/overview/?scid=f2ae0541-1279-4f24-b197-a979c79310b0 | I23: 35 | J23: 45 | K23: 700 | L23: 0.33 | M23: 243 | N23: Geoffrey Cousineau | R23: LAZ | S23: Marinna.tucker@marriott.com
A24: Grand Bohemian Hotel | B24: Hotel | D24: 201 W Trade St, Charlotte, NC 28202 | E24: YES | F24: (704) 372-1877 | G24: hugh.templeman@kesslercollection.com | H24: https://www.kesslercollection.com/bohemian-charlotte/ | I24: unknown | J24: 48 | K24: 254 | L24: 0.65 | M24: 122 | N24: Hugh Templeman | R24: PMC | T24: Wait for new GM
A25: JW Marriott Charlotte | B25: Hotel | D25: 600 S College St, Charlotte, NC 28202 | E25: YES | F25: David.malmberg@whitelodging.com | H25: https://www.marriott.com/en-us/Hotels/cltjw-jw-marriott-charlotte/overview/ | I25: n/a | J25: 48 | K25: 381 | L25: 0.48 | M25: 87 | R25: PMC | T25: Reviews about the valet are mostly terrible.
A26: Kimpton Tryon Park Hotel | B26: Hotel | D26: 303 S Church St, Charlotte, NC 28202 | E26: YES | F26: 7044477662 (Direct line) | H26: https://www.tryonparkHotel.com/ | J26: 48 | K26: 217 | L26: 0.54 | M26: 162 | N26: Yvette Bullock | Q26: Preferred | R26: PMC | T26: $30 4 hours max Valet
A27: Charlotte Marriott City Center | B27: Hotel | D27: 100 W Trade St, Charlotte, NC 28202 | E27: YES | G27: Annette.Crispin@marriott.com | H27: https://www.marriott.com/en-us/Hotels/cltcc-charlotte-marriott-city-center/overview/?scid=f2ae0541-1279-4f24-b197-a979c79310b0 | J27: 48 | K27: 440 | L27: 0.4 | M27: 181 | N27: Annette Crispin | R27: PMC | T27: poor reviews
A28: Ritz Carlton | B28: Hotel | D28: 201 E Trade St, Charlotte, NC 28202 | E28: YES | F28: Karen.Ayad@Ritzcarlton.com | H28: https://www.ritzcarlton.com/en/Hotels/cltrz-the-ritz-carlton-charlotte/overview/ | J28: 50 | K28: 146 | L28: 0.52 | M28: 48 | R28: In House
A29: Kasa FreeMoreWest Charlotte | B29: Hotel | D29: 2109 Morton St, Charlotte, NC 28208 | E29: South End | F29: (704) 368-4082 | H29: https://kasa.com/properties/kasa-freemorewest-charlotte?utm_source=Google&utm_medium=nonpaid&utm_campaign=GMB&utm_term=VisitHotelWebsiteButton&utm_content=BRY&propertyType=&petsAllowed=&parking&bedCount=1&bedroomCount=0&bathroomCount=1&amenities=&adultGuestCount=1&childGuestCount=0&infantGuestCount=0&travelingForBusiness=false
A30: Canopy by Hilton Charlotte Southpark | B30: Hotel | D30: 4905 Barclay Downs Dr, Charlotte, NC 28210 | E30: NO | F30: 704-552-1715 | G30: Gary.colbert@hilton.com, kerisha2113@gmail.com | I30: 15 | N30: Gary Colbert | S30: Left a voicemail and emailed, they used to have valet and are in talks about bringing it back
A31: Courtyard by Marriott Charlotte SouthPark | B31: Hotel | C31: ='Sales Candence'!B75 | E31: NO | F31: 704-552-7333 | I31: 10 | N31: Matthew Wilhelm | S31: not interested at this time, thanked me for introducing myself
A32: Residence Inn by Marriott Charlotte SouthPark | B32: Hotel | C32: ='Sales Candence'!B76 | D32: 6030 Piedmont Row Dr S, Charlotte, NC 28210 | E32: NO | F32: 704-554-7001 | I32: 10 | S32: Couldn't get past front desk
A33: Renaissance Charlotte SouthPark Hotel | B33: Hotel | C33: ='Sales Candence'!B77 | D33: 5501 Carnegie Blvd, Charlotte, NC 28209 | E33: NO | F33: 704-364-8220 | I33: free | N33: James Gratton, area GM 3x hotels | S33: Called got james email, goes by jim supposedly, sent him an email. no paid parking at 3 locaitons when all rest of hotels in area are charging
A34: Charlotte Marriott SouthPark | B34: Hotel | C34: ='Sales Candence'!B78 | D34: 2200 Rexford Rd, Charlotte, NC 28211 | E34: NO | I34: free | N34: James Gratton, area GM 3x hotels
A35: AC Hotel Charlotte SouthPark | B35: Hotel | C35: ='Sales Candence'!B79 | D35: 1824 Roxborough Rd, Charlotte, NC 28211 | E35: NO | G35: jim.gratton@marriott.com | I35: free | N35: James Gratton, area GM 3x hotels
A36: Hyatt Centric Charlotte SouthPark | B36: Hotel | C36: ='Sales Candence'!B80 | D36: 3100 Apex Dr, Charlotte, NC 28211 | E36: NO | F36: =19802997123 | I36: 10
A37: Homewood Suites by Hilton Charlotte/SouthPark | B37: Hotel | C37: ='Sales Candence'!B81 | D37: 4808 Sharon Rd, Charlotte, NC 28210 | E37: NO | F37: =17044424050 | G37: hgihws@chartwellhospitality.com | I37: 10
A38: DoubleTree Suites by Hilton Hotel Charlotte - SouthPark | B38: Hotel | C38: ='Sales Candence'!B82 | D38: 6300 Carnegie Blvd, Charlotte, NC 28211 | E38: NO | I38: 10
A39: UNC Charlotte Marriott Hotel & Conference Center | B39: Hotel | C39: ='Sales Candence'!B83 | D39: 9041 Robert D. Snyder Rd, Charlotte, NC 28262 | E39: NO | F39: =17049788000 | G39: Thomas.Caramucci@unccharlottemarriott.com | J39: 31 | N39: Thomas Caramucci
A40: Steak 48 | B40: Restaurant | D40: 4425 Sharon Rd, Charlotte, NC 28211 | E40: NO | F40: (704) 996-5586 | I40: 0 | J40: 7 | N40: Katie Kathman
...

Sheet Sales Candence
A1: =Accounts!A1 | B1: Contact Created? | C1: =Accounts!N1 | D1: GM Contact Info | E1: =Accounts!F1 | F1: =Accounts!Q1 | G1: =Accounts!R1 | H1: =Accounts!I1 | I1: =Accounts!J1 | J1: =Accounts!S1 | K1: SALES NOTES | M1: 1 | N1: 2 | O1: 3 | P1: 4 | Q1: 5 | R1: 6 | S1: 7 | T1: 8 | U1: 9 | V1: 10
A2: =Accounts!A2 | B2: TRUE | C2: =Accounts!N2 | E2: =Accounts!F2 | F2: =Accounts!Q2 | G2: =Accounts!R2 | H2: =Accounts!I2 | I2: =Accounts!J2 | J2: =Accounts!S2 | K2: This is the section to write down notes while in calls or meetings. However, make sure to still track in hubspot. | M2: FALSE | N2: FALSE | O2: FALSE | P2: FALSE | Q2: FALSE | R2: FALSE | S2: FALSE | T2: FALSE | U2: FALSE | V2: FALSE
A3: =Accounts!A3 | B3: FALSE | C3: =Accounts!N3 | E3: =Accounts!F3 | F3: =Accounts!Q3 | G3: =Accounts!R3 | H3: =Accounts!I3 | I3: =Accounts!J3 | J3: =Accounts!S3 | K3: ->> Add drop downs instead of check boxes to give more information | M3: FALSE | N3: FALSE | O3: FALSE | P3: FALSE | Q3: FALSE | R3: FALSE | S3: FALSE | T3: FALSE | U3: FALSE | V3: FALSE
A4: =Accounts!A4 | B4: FALSE | C4: =Accounts!N4 | E4: =Accounts!F4 | F4: =Accounts!Q4 | G4: =Accounts!R4 | H4: =Accounts!I4 | I4: =Accounts!J4 | J4: =Accounts!S4 | M4: FALSE | N4: FALSE | O4: FALSE | P4: FALSE | Q4: FALSE | R4: FALSE | S4: FALSE | T4: FALSE | U4: FALSE | V4: FALSE
A5: =Accounts!A5 | B5: FALSE | C5: =Accounts!N5 | E5: =Accounts!F5 | F5: =Accounts!Q5 | G5: =Accounts!R5 | H5: =Accounts!I5 | I5: =Accounts!J5 | J5: =Accounts!S5 | M5: FALSE | N5: FALSE | O5: FALSE | P5: FALSE | Q5: FALSE | R5: FALSE | S5: FALSE | T5: FALSE | U5: FALSE | V5: FALSE
A6: =Accounts!A6 | B6: FALSE | C6: =Accounts!N6 | E6: =Accounts!F6 | F6: =Accounts!Q6 | G6: =Accounts!R6 | H6: =Accounts!I6 | I6: =Accounts!J6 | J6: =Accounts!S6 | M6: FALSE | N6: FALSE | O6: FALSE | P6: FALSE | Q6: FALSE | R6: FALSE | S6: FALSE | T6: FALSE | U6: FALSE | V6: FALSE
A7: =Accounts!A7 | B7: FALSE | C7: =Accounts!N7 | E7: =Accounts!F7 | F7: =Accounts!Q7 | G7: =Accounts!R7 | H7: =Accounts!I7 | I7: =Accounts!J7 | J7: =Accounts!S7 | M7: FALSE | N7: FALSE | O7: FALSE | P7: FALSE | Q7: FALSE | R7: FALSE | S7: FALSE | T7: FALSE | U7: FALSE | V7: FALSE
A8: =Accounts!A8 | B8: FALSE | C8: =Accounts!N8 | E8: =Accounts!F8 | F8: =Accounts!Q8 | G8: =Accounts!R8 | H8: =Accounts!I8 | I8: =Accounts!J8 | J8: =Accounts!S8 | M8: FALSE | N8: FALSE | O8: FALSE | P8: FALSE | Q8: FALSE | R8: FALSE | S8: FALSE | T8: FALSE | U8: FALSE | V8: FALSE
A9: =Accounts!A9 | B9: FALSE | C9: =Accounts!N9 | E9: =Accounts!F9 | F9: =Accounts!Q9 | G9: =Accounts!R9 | H9: =Accounts!I9 | I9: =Accounts!J9 | J9: =Accounts!S9 | M9: FALSE | N9: FALSE | O9: FALSE | P9: FALSE | Q9: FALSE | R9: FALSE | S9: FALSE | T9: FALSE | U9: FALSE | V9: FALSE
A10: =Accounts!A10 | B10: FALSE | C10: =Accounts!N10 | E10: =Accounts!F10 | F10: =Accounts!Q10 | G10: =Accounts!R10 | H10: =Accounts!I10 | I10: =Accounts!J10 | J10: =Accounts!S10 | M10: FALSE | N10: FALSE | O10: FALSE | P10: FALSE | Q10: FALSE | R10: FALSE | S10: FALSE | T10: FALSE | U10: FALSE | V10: FALSE
A11: =Accounts!A11 | B11: FALSE | C11: =Accounts!N11 | E11: =Accounts!F11 | F11: =Accounts!Q11 | G11: =Accounts!R11 | H11: =Accounts!I11 | I11: =Accounts!J11 | J11: =Accounts!S11 | M11: FALSE | N11: FALSE | O11: FALSE | P11: FALSE | Q11: FALSE | R11: FALSE | S11: FALSE | T11: FALSE | U11: FALSE | V11: FALSE
A12: =Accounts!A12 | B12: FALSE | C12: =Accounts!N12 | E12: =Accounts!F12 | F12: =Accounts!Q12 | G12: =Accounts!R12 | H12: =Accounts!I12 | I12: =Accounts!J12 | J12: =Accounts!S12 | M12: FALSE | N12: FALSE | O12: FALSE | P12: FALSE | Q12: FALSE | R12: FALSE | S12: FALSE | T12: FALSE | U12: FALSE | V12: FALSE
A13: =Accounts!A13 | B13: FALSE | C13: =Accounts!N13 | E13: =Accounts!F13 | F13: =Accounts!Q13 | G13: =Accounts!R13 | H13: =Accounts!I13 | I13: =Accounts!J13 | J13: =Accounts!S13 | M13: FALSE | N13: FALSE | O13: FALSE | P13: FALSE | Q13: FALSE | R13: FALSE | S13: FALSE | T13: FALSE | U13: FALSE | V13: FALSE
A14: =Accounts!A14 | B14: FALSE | C14: =Accounts!N14 | E14: =Accounts!F14 | F14: =Accounts!Q14 | G14: =Accounts!R14 | H14: =Accounts!I14 | I14: =Accounts!J14 | J14: =Accounts!S14 | M14: FALSE | N14: FALSE | O14: FALSE | P14: FALSE | Q14: FALSE | R14: FALSE | S14: FALSE | T14: FALSE | U14: FALSE | V14: FALSE
A15: =Accounts!A15 | B15: FALSE | C15: =Accounts!N15 | E15: =Accounts!F15 | F15: =Accounts!Q15 | G15: =Accounts!R15 | H15: =Accounts!I15 | I15: =Accounts!J15 | J15: =Accounts!S15 | M15: FALSE | N15: FALSE | O15: FALSE | P15: FALSE | Q15: FALSE | R15: FALSE | S15: FALSE | T15: FALSE | U15: FALSE | V15: FALSE
... A75: =Accounts!A75 | B75: FALSE | C75: =Accounts!N75 | E75: =Accounts!F75 | F75: =Accounts!Q75 | G75: =Accounts!R75 | H75: =Accounts!I75 | I75: =Accounts!J75 | J75: =Accounts!S75 | M75: FALSE | N75: FALSE | O75: FALSE | P75: FALSE | Q75: FALSE | R75: FALSE | S75: FALSE | T75: FALSE | U75: FALSE | V75: FALSE
A76: =Accounts!A76 | B76: FALSE | C76: =Accounts!N77 | E76: =Accounts!F76 | F76: =Accounts!Q76 | G76: =Accounts!R76 | H76: =Accounts!I76 | I76: =Accounts!J76 | J76: =Accounts!S76 | M76: FALSE | N76: FALSE | O76: FALSE | P76: FALSE | Q76: FALSE | R76: FALSE | S76: FALSE | T76: FALSE | U76: FALSE | V76: FALSE
A77: =Accounts!A77 | B77: FALSE | C77: =#REF! | E77: =Accounts!F77 | F77: =Accounts!Q77 | G77: =Accounts!R77 | H77: =Accounts!I77 | I77: =Accounts!J77 | J77: =Accounts!S77 | M77: FALSE | N77: FALSE | O77: FALSE | P77: FALSE | Q77: FALSE | R77: FALSE | S77: FALSE | T77: FALSE | U77: FALSE | V77: FALSE
A78: =Accounts!A78 | B78: FALSE | C78: =Accounts!N78 | E78: =Accounts!F78 | F78: =Accounts!Q78 | G78: =Accounts!R78 | H78: =Accounts!I78 | I78: =Accounts!J78 | J78: =Accounts!S78 | M78: FALSE | N78: FALSE | O78: FALSE | P78: FALSE | Q78: FALSE | R78: FALSE | S78: FALSE | T78: FALSE | U78: FALSE | V78: FALSE
A79: =Accounts!A79 | B79: FALSE | C79: =Accounts!N79 | E79: =Accounts!F79 | F79: =Accounts!Q79 | G79: =Accounts!R79 | H79: =Accounts!I79 | I79: =Accounts!J79 | J79: =Accounts!S79 | M79: FALSE | N79: FALSE | O79: FALSE | P79: FALSE | Q79: FALSE | R79: FALSE | S79: FALSE | T79: FALSE | U79: FALSE | V79: FALSE
A80: =Accounts!A80 | B80: FALSE | C80: =Accounts!N80 | E80: =Accounts!F80 | F80: =Accounts!Q80 | G80: =Accounts!R80 | H80: =Accounts!I80 | I80: =Accounts!J80 | J80: =Accounts!S80 | M80: FALSE | N80: FALSE | O80: FALSE | P80: FALSE | Q80: FALSE | R80: FALSE | S80: FALSE | T80: FALSE | U80: FALSE | V80: FALSE
A81: =Accounts!A81 | B81: FALSE | C81: =Accounts!N81 | E81: =Accounts!F81 | F81: =Accounts!Q81 | G81: =Accounts!R81 | H81: =Accounts!I81 | I81: =Accounts!J81 | J81: =Accounts!S81 | M81: FALSE | N81: FALSE | O81: FALSE | P81: FALSE | Q81: FALSE | R81: FALSE | S81: FALSE | T81: FALSE | U81: FALSE | V81: FALSE
A82: =Accounts!A82 | B82: FALSE | C82: =Accounts!N82 | E82: =Accounts!F82 | F82: =Accounts!Q82 | G82: =Accounts!R82 | H82: =Accounts!I82 | I82: =Accounts!J82 | J82: =Accounts!S82 | M82: FALSE | N82: FALSE | O82: FALSE | P82: FALSE | Q82: FALSE | R82: FALSE | S82: FALSE | T82: FALSE | U82: FALSE | V82: FALSE
A83: =Accounts!A83 | B83: FALSE | C83: =Accounts!N83 | E83: =Accounts!F83 | F83: =Accounts!Q83 | G83: =Accounts!R83 | H83: =Accounts!I83 | I83: =Accounts!J83 | J83: =Accounts!S83 | M83: FALSE | N83: FALSE | O83: FALSE | P83: FALSE | Q83: FALSE | R83: FALSE | S83: FALSE | T83: FALSE | U83: FALSE | V83: FALSE
A84: =Accounts!A84 | B84: FALSE | C84: =Accounts!N84 | E84: =Accounts!F84 | F84: =Accounts!Q84 | G84: =Accounts!R84 | H84: =Accounts!I84 | I84: =Accounts!J84 | J84: =Accounts!S84 | M84: FALSE | N84: FALSE | O84: FALSE | P84: FALSE | Q84: FALSE | R84: FALSE | S84: FALSE | T84: FALSE | U84: FALSE | V84: FALSE
A85: =Accounts!A85 | B85: FALSE | C85: =Accounts!N85 | E85: =Accounts!F85 | F85: =Accounts!Q85 | G85: =Accounts!R85 | H85: =Accounts!I85 | I85: =Accounts!J85 | J85: =Accounts!S85 | M85: FALSE | N85: FALSE | O85: FALSE | P85: FALSE | Q85: FALSE | R85: FALSE | S85: FALSE | T85: FALSE | U85: FALSE | V85: FALSE
A86: =Accounts!A86 | B86: FALSE | C86: =Accounts!N86 | E86: =Accounts!F86 | F86: =Accounts!Q86 | G86: =Accounts!R86 | H86: =Accounts!I86 | I86: =Accounts!J86 | J86: =Accounts!S86 | M86: FALSE | N86: FALSE | O86: FALSE | P86: FALSE | Q86: FALSE | R86: FALSE | S86: FALSE | T86: FALSE | U86: FALSE | V86: FALSE
A87: =Accounts!A87 | B87: FALSE | C87: =Accounts!N87 | E87: =Accounts!F87 | F87: =Accounts!Q87 | G87: =Accounts!R87 | H87: =Accounts!I87 | I87: =Accounts!J87 | J87: =Accounts!S87 | M87: FALSE | N87: FALSE | O87: FALSE | P87: FALSE | Q87: FALSE | R87: FALSE | S87: FALSE | T87: FALSE | U87: FALSE | V87: FALSE
A88: =Accounts!A88 | B88: FALSE | C88: =Accounts!N88 | E88: =Accounts!F88 | F88: =Accounts!Q88 | G88: =Accounts!R88 | H88: =Accounts!I88 | I88: =Accounts!J88 | J88: =Accounts!S88 | M88: FALSE | N88: FALSE | O88: FALSE | P88: FALSE | Q88: FALSE | R88: FALSE | S88: FALSE | T88: FALSE | U88: FALSE | V88: FALSE
A89: =Accounts!A89 | B89: FALSE | C89: =Accounts!N89 | E89: =Accounts!F89 | F89: =Accounts!Q89 | G89: =Accounts!R89 | H89: =Accounts!I89 | I89: =Accounts!J89 | J89: =Accounts!S89 | M89: FALSE | N89: FALSE | O89: FALSE | P89: FALSE | Q89: FALSE | R89: FALSE | S89: FALSE | T89: FALSE | U89: FALSE | V89: FALSE
... A1000: =Accounts!A1000 | B1000: FALSE | C1000: =Accounts!N1000 | E1000: =Accounts!F1000 | F1000: =Accounts!Q1000 | G1000: =Accounts!R1000 | H1000: =Accounts!I1000 | I1000: =Accounts!J1000 | J1000: =Accounts!S1000 | M1000: FALSE | N1000: FALSE | O1000: FALSE | P1000: FALSE | Q1000: FALSE | R1000: FALSE | S1000: FALSE | T1000: FALSE | U1000: FALSE | V1000: FALSE
B1001: FALSE | C1001: =Accounts!N1001 | E1001: =Accounts!F1001 | F1001: =Accounts!Q1001 | G1001: =Accounts!R1001 | H1001: =Accounts!I1001 | I1001: =Accounts!J1001 | J1001: =Accounts!S1001 | M1001: FALSE | N1001: FALSE | O1001: FALSE | P1001: FALSE | Q1001: FALSE | R1001: FALSE | S1001: FALSE | T1001: FALSE | U1001: FALSE | V1001: FALSE
B1002: FALSE | C1002: =Accounts!N1002 | E1002: =Accounts!F1002 | F1002: =Accounts!Q1002 | G1002: =Accounts!R1002 | H1002: =Accounts!I1002 | I1002: =Accounts!J1002 | J1002: =Accounts!S1002 | M1002: FALSE | N1002: FALSE | O1002: FALSE | P1002: FALSE | Q1002: FALSE | R1002: FALSE | S1002: FALSE | T1002: FALSE | U1002: FALSE | V1002: FALSE
B1003: FALSE | C1003: =Accounts!N1003 | E1003: =Accounts!F1003 | F1003: =Accounts!Q1003 | G1003: =Accounts!R1003 | H1003: =Accounts!I1003 | I1003: =Accounts!J1003 | J1003: =Accounts!S1003 | M1003: FALSE | N1003: FALSE | O1003: FALSE | P1003: FALSE | Q1003: FALSE | R1003: FALSE | S1003: FALSE | T1003: FALSE | U1003: FALSE | V1003: FALSE
B1004: FALSE | C1004: =Accounts!N1004 | E1004: =Accounts!F1004 | F1004: =Accounts!Q1004 | G1004: =Accounts!R1004 | H1004: =Accounts!I1004 | I1004: =Accounts!J1004 | J1004: =Accounts!S1004 | M1004: FALSE | N1004: FALSE | O1004: FALSE | P1004: FALSE | Q1004: FALSE | R1004: FALSE | S1004: FALSE | T1004: FALSE | U1004: FALSE | V1004: FALSE
B1005: FALSE | C1005: =Accounts!N1005 | E1005: =Accounts!F1005 | F1005: =Accounts!Q1005 | G1005: =Accounts!R1005 | H1005: =Accounts!I1005 | I1005: =Accounts!J1005 | J1005: =Accounts!S1005 | M1005: FALSE | N1005: FALSE | O1005: FALSE | P1005: FALSE | Q1005: FALSE | R1005: FALSE | S1005: FALSE | T1005: FALSE | U1005: FALSE | V1005: FALSE
B1006: FALSE | C1006: =Accounts!N1006 | E1006: =Accounts!F1006 | F1006: =Accounts!Q1006 | G1006: =Accounts!R1006 | H1006: =Accounts!I1006 | I1006: =Accounts!J1006 | J1006: =Accounts!S1006 | M1006: FALSE | N1006: FALSE | O1006: FALSE | P1006: FALSE | Q1006: FALSE | R1006: FALSE | S1006: FALSE | T1006: FALSE | U1006: FALSE | V1006: FALSE
B1007: FALSE | C1007: =Accounts!N1007 | E1007: =Accounts!F1007 | F1007: =Accounts!Q1007 | G1007: =Accounts!R1007 | H1007: =Accounts!I1007 | I1007: =Accounts!J1007 | J1007: =Accounts!S1007 | M1007: FALSE | N1007: FALSE | O1007: FALSE | P1007: FALSE | Q1007: FALSE | R1007: FALSE | S1007: FALSE | T1007: FALSE | U1007: FALSE | V1007: FALSE
B1008: FALSE | C1008: =Accounts!N1008 | E1008: =Accounts!F1008 | F1008: =Accounts!Q1008 | G1008: =Accounts!R1008 | H1008: =Accounts!I1008 | I1008: =Accounts!J1008 | J1008: =Accounts!S1008 | M1008: FALSE | N1008: FALSE | O1008: FALSE | P1008: FALSE | Q1008: FALSE | R1008: FALSE | S1008: FALSE | T1008: FALSE | U1008: FALSE | V1008: FALSE
B1009: FALSE | C1009: =Accounts!N1009 | E1009: =Accounts!F1009 | F1009: =Accounts!Q1009 | G1009: =Accounts!R1009 | H1009: =Accounts!I1009 | I1009: =Accounts!J1009 | J1009: =Accounts!S1009 | M1009: FALSE | N1009: FALSE | O1009: FALSE | P1009: FALSE | Q1009: FALSE | R1009: FALSE | S1009: FALSE | T1009: FALSE | U1009: FALSE | V1009: FALSE
...

Sheet Parking
A1: Loaction ID | B1: Location Name | C1: Location Type | D1: Address | E1: # Spaces | F1: Unreserved Monthly Rate | G1: Operator | H1: Point of Contact | I1: POC Number | J1: URL | K1: Notes | L1: PARCs Equipment Notes
B2: Charlotte Marriott City Center | C2: Underground | D2: 100 W Trade St | E2: 320 | F2: N/A | G2: Preferred | I2: (704)-333-9000 | K2: Customer parking only;
B3: Avenue Condominium | C3: Covered | D3: 210 N Church St | E3: N/A | F3: N/A | G3: N/A | J3: N/A
B4: IVEY's Garage | C4: Garage | D4: 120 N Church St | E4: 226 | F4: N/A | G4: LAZ | J4: https://lazparking.com/local/charlotte-nc/ivey-garage | K4: Monthly parking only
B5: Fifth-Third Center | C5: Garage | D5: 201 N Tryon St | E5: 930 | F5: N/A | G5: LAZ | J5: https://www.lazparking.com/local/charlotte-nc/fifth-third
B6: Discovery Place Science | C6: Garage | D6: 220 W 6th St | E6: 316 | F6: N/A | G6: Discovery Place | J6: https://science.discoveryplace.org/plan#parking | K6: Visitor Parking Only
B7: 401 W Pine St | C7: Lot | D7: 401 W Pine St | E7: 115 | F7: 135 | G7: Preferred | J7: https://www.preferredparking.com/dailyparking_clt/default.aspx
B8: The VUE Charlotte | C8: Garage | D8: 410 W 5th St | E8: N/A | F8: 250 | G8: The VUE | I8: (704)-333-2533 | K8: Free validation
B9: 309 W Trade St | C9: Lot | D9: 309 W Trade St | E9: 255 | F9: 190 | G9: Preferred | J9: https://www.preferredparking.com/dailyparking_clt/default.aspx | K9: Open all day Mon-Sat; No parking 6am-12N on Sunday
B10: 401 N. Tryon Garage | C10: Underground | D10: 401 N Tryon St | E10: 1101 | F10: N/A | G10: LAZ | J10: https://www.lazparking.com/local/charlotte-nc/401-north-tryon
B11: 101 Independance Center Parking Facility | C11: Underground | D11: 101 N Tryon St | E11: 320 | F11: N/A | G11: LAZ | J11: https://www.lazparking.com/local/charlotte-nc/101-independence-center | K11: On-sight car wash!
B12: 123 S Church St | C12: Garage | D12: 123 S Church St | E12: 275 | F12: 205 | G12: Preferred | J12: N/A | K12: Maximum stay 2 days
B13: Carillon Garage | C13: Garage | D13: 160 S Poplar St | E13: 832 | F13: N/A | G13: SP Plus Corparation | I13: (980)-224-1065
B14: 124 S Poplar St | C14: Lot | D14: 124 S Poplar St | E14: 105 | F14: 169 | G14: Preferred | J14: https://www.preferredparking.com/dailyparking_clt/default.aspx
B15: Auto Park | C15: Lot | D15: 206 S Church St | E15: 40 | F15: N/A | G15: Preferred | J15: https://www.preferredparking.com/dailyparking_clt/default.aspx
B16: Auto Park | C16: Garage | D16: 206 S Church St | E16: 690 | F16: 185 | G16: Preferred | J16: https://www.preferredparking.com/dailyparking_clt/default.aspx
B17: 208 S Poplar St | C17: Lot | D17: 208 S Poplar St | E17: 160 | F17: 169 | G17: Preferred | J17: https://www.preferredparking.com/dailyparking_clt/default.aspx
B18: 400 South Tryon Street Garage | C18: Garage | D18: 400 S Tryon St | E18: 495 | F18: N/A | G18: Preferred | J18: https://www.preferredparking.com/dailyparking_clt/default.aspx
B19: 330 South Tryon Street Garage | C19: Garage | D19: 330 S Tryon St | E19: 250 | F19: 198 | G19: Preferred | J19: https://www.preferredparking.com/dailyparking_clt/default.aspx
B20: 300 South Tryon Street Garage | C20: Garage | D20: 300 S Tryon St | E20: 408 | F20: N/A | G20: Preferred | J20: https://www.preferredparking.com/dailyparking_clt/default.aspx
B21: 230 South Tryon Street Garage | C21: Garage | D21: 100 W Third St | E21: 670 | F21: N/A | G21: Spectrum Parking LLC | I21: (704)-358-1000
B22: 228 S Church St | C22: Lot | D22: 228 S Church St | E22: 35 | F22: N/A | G22: Preferred | J22: https://www.preferredparking.com/dailyparking_clt/default.aspx
B23: First Citizens Bank Plaza Garage | C23: Garage | D23: 205 S Church St | E23: 697 | F23: 195 | G23: Preferred | J23: https://www.preferredparking.com/dailyparking_clt/default.aspx
B24: 121 West Trade | C24: Garage | D24: 121 W Trade St | E24: 264 | F24: N/A | G24: Preferred | J24: https://www.preferredparking.com/dailyparking_clt/default.aspx
B25: Epicentre Parking / Queen City Quarter | C25: Garage | D25: 101 S College St | E25: 982 | F25: 179 | G25: Preferred | J25: https://www.preferredparking.com/dailyparking_clt/default.aspx
B26: Bank of America Plaza (One South At the Plaza) | C26: Garage | D26: 101 S Tryon St | E26: 459 | F26: 200 | G26: LAZ | J26: https://go.lazparking.com/subnow?l=351&start=2023-11-15T22:00:00.000Z
B27: 300 S. Brevard Garage | C27: Garage | D27: 300 S. Brevard St. | E27: 720 | F27: $75/$173 | G27: Preferred | J27: https://www.preferredparking.com/dailyparking_clt/default.aspx
B28: 402 E 3rd St | C28: Lot | D28: 402 E 3rd St | E28: 45 | F28: $150 | G28: Preferred | J28: https://www.preferredparking.com/dailyparking_clt/default.aspx
B29: 415 E. 4th St | C29: Lot | D29: 415 E 4th St | E29: 29 | F29: 140 | G29: Preferred | J29: https://www.preferredparking.com/dailyparking_clt/default.aspx
B30: 402 E 4th St | C30: Lot | D30: 402 E 4th St | E30: 180 | F30: 150 | G30: Preferred | J30: https://www.preferredparking.com/dailyparking_clt/default.aspx
B31: Location #20 | C31: Lot | D31: 210 S Brevard St | E31: 380 | F31: 160 | G31: Preferred | J31: https://www.preferredparking.com/dailyparking_clt/default.aspx
B32: Preferred Parking Lot #406 | C32: Lot | D32: 407 E 4th St | E32: 180 | F32: 150 | G32: Preferred | J32: https://www.preferredparking.com/dailyparking_clt/default.aspx
B33: 426 E Trade St | C33: Lot | D33: 426 E Trade St | E33: 47 | F33: 150 | G33: Preferred | J33: https://www.preferredparking.com/dailyparking_clt/default.aspx
B34: Charlotte Plaza | C34: Garage | D34: 201 S College St | E34: 980 | F34: 175 | G34: Charlotte | J34: https://parking.com/charlotte/parking-near/35.22462560/-80.84200160/306-e-4th-st/?lot_id=20383&showListOnly=1&view=daily&facility&valet&general=&displayFullCity=0&start=2023-12-28T14%3A00&stop=2023-12-28T14%3A30&sw=35.21071788363375,-80.86408062727335&ne=35.2381351005086,-80.8207577726999 | K34: 5pm to 4am 10 sat-sun allday untill 4 am 10
B35: One Wells Fargo Center Parking Garage | C35: Garage | D35: 301 S College St | E35: 1119 | F35: $165/$205 | G35: CK Parking | I35: (704)-342-9030 | K35: Customer parking only
B36: Two Wells Fargo Center Parking Garage | C36: Garage | D36: 301 S Tryon St | E36: 525 | F36: 152 | G36: CK Parking | I36: (704)-944-1830
B37: Omni Charlotte | C37: Garage | D37: 132 E Trade St | E37: N/A | F37: N/A | G37: In-house | I37: (704)-377-0400
B38: 237 S Tryon Garage | C38: Garage | D38: 237 S Tryon St | E38: 689 | F38: 195 | G38: Preferred | J38: https://www.preferredparking.com/dailyparking_clt/default.aspx
B39: 200 S College St | C39: Garage | D39: 200 S College St | E39: 1500 | F39: 200 | G39: LAZ | J39: https://www.lazparking.com/local/charlotte--nc/bbt-center | K39: $17 early bird mon-fri 8am out 3pm
B40: Bank of America Center Garage | C40: Garage | D40: 150 N College St | E40: 1200 | F40: N/A | G40: LAZ | I40: (704)-331-0055
...

Sheet RevenueForecasting
A1: Account | B1: Account Type | C1: Valet Operator | D1: # of Rooms | E1: Occupancy Rate | F1: Forecast | G1: Valet Conversion Rate | H1: Estimated Daily Valet Count | I1: Estimated Daily Revenue | J1: Estimated Annual Revenue | K1: Estimate Net Operating Income Annually | L1: Total Daily Rev | M1: Total Annual Rev | N1: Total Annual NOI
A2: =Accounts!A2 | B2: Restaurant | D2: =Accounts!K2 | E2: 0.6 | F2: =Accounts!K2*E2 | G2: 0.4 | H2: =F2*G2 | I2: =if(or(eq(Accounts!J2,"No Valet"),eq(Accounts!J2,"Has Valet")), H2 * AVERAGE(Accounts!J$2:J$36),H2*Accounts!J2) | J2: =iferror(I2*360,"") | K2: =J2*0.1 | L2: =sum(I2:I72) | M2: =sum(J2:J72) | N2: =sum(K2:K72)
A3: =Accounts!A3 | B3: Hotel | C3: Preferred Parking | D3: =Accounts!K3 | E3: 0.6 | F3: =Accounts!K3*E3 | G3: 0.4 | H3: =F3*G3 | I3: =if(or(eq(Accounts!J3,"No Valet"),eq(Accounts!J3,"Has Valet")), H3 * AVERAGE(Accounts!J$2:J$36),H3*Accounts!J3) | J3: =iferror(I3*360,"") | K3: =J3*0.2 | M3: =sum(J3:J72) | N3: =sum(K3:K72)*2
A4: =Accounts!A4 | B4: Hotel | C4: None | D4: =Accounts!K4 | E4: 0.6 | F4: =Accounts!K4*E4 | G4: 0.4 | H4: =F4*G4 | I4: =H4*40 | J4: =iferror(I4*360,"") | K4: =J4*0.2
A5: =Accounts!A5 | B5: Restaurant | C5: SOPHI | D5: =Accounts!K5 | E5: 0.6 | F5: =Accounts!K5*E5 | G5: 0.4 | H5: =F5*G5 | I5: =if(or(eq(Accounts!J5,"No Valet"),eq(Accounts!J5,"Has Valet")), H5 * AVERAGE(Accounts!J$2:J$36),H5*Accounts!J5) | J5: 100000 | K5: =J5*0.25
A6: =Accounts!A6 | B6: Restaurant | C6: Park Inc | D6: =Accounts!K6 | E6: 0.6 | F6: =Accounts!K6*E6 | G6: 0.4 | H6: =F6*G6 | I6: =if(or(eq(Accounts!J6,"No Valet"),eq(Accounts!J6,"Has Valet")), H6 * AVERAGE(Accounts!J$2:J$36),H6*Accounts!J6) | J6: 150000 | K6: =J6*0.25
A7: =Accounts!A7 | B7: Hotel | C7: None | D7: =Accounts!K7 | E7: 0.6 | F7: =Accounts!K7*E7 | G7: 0.4 | H7: =F7*G7 | I7: =H7*40 | J7: =iferror(I7*360,"") | K7: =J7*0.1
A8: =Accounts!A8 | B8: Restaurant | C8: Park Inc | D8: =Accounts!K8 | E8: 0.6 | F8: =Accounts!K8*E8 | G8: 0.4 | H8: =F8*G8 | I8: =if(or(eq(Accounts!J8,"No Valet"),eq(Accounts!J8,"Has Valet")), H8 * AVERAGE(Accounts!J$2:J$36),H8*Accounts!J8) | J8: 150000 | K8: =J8*0.25
A9: =Accounts!A9 | B9: Hotel | C9: None | D9: =Accounts!K9 | E9: 0.6 | F9: =Accounts!K9*E9 | G9: 0.4 | H9: =F9*G9 | I9: =H9*40 | J9: =iferror(I9*360,"") | K9: =J9*0.1
A10: =Accounts!A10 | B10: Restaurant | C10: Park Inc | D10: =Accounts!K10 | E10: 0.6 | F10: =Accounts!K10*E10 | G10: 0.4 | H10: =F10*G10 | I10: =if(or(eq(Accounts!J10,"No Valet"),eq(Accounts!J10,"Has Valet")), H10 * AVERAGE(Accounts!J$2:J$36),H10*Accounts!J10) | J10: 150000 | K10: =J10*0.25
A11: =Accounts!A11 | B11: Hotel | C11: None | D11: =Accounts!K11 | E11: 0.6 | F11: =Accounts!K11*E11 | G11: 0.4 | H11: =F11*G11 | I11: =H11*40 | J11: =iferror(I11*360,"") | K11: =J11*0.1
A12: =Accounts!A12 | B12: Hotel | C12: None | D12: =Accounts!K12 | E12: 0.6 | F12: =Accounts!K12*E12 | G12: 0.4 | H12: =F12*G12 | I12: =H12*40 | J12: =iferror(I12*360,"") | K12: =J12*0.1
A13: =Accounts!A13 | B13: Hotel | C13: None | D13: =Accounts!K13 | E13: 0.6 | F13: =Accounts!K13*E13 | G13: 0.4 | H13: =F13*G13 | I13: =H13*40 | J13: =iferror(I13*360,"") | K13: =J13*0.1
A14: =Accounts!A14 | B14: Restaurant | C14: SOPHI | D14: =Accounts!K14 | E14: 0.6 | F14: =Accounts!K14*E14 | G14: 0.4 | H14: =F14*G14 | I14: =if(or(eq(Accounts!J14,"No Valet"),eq(Accounts!J14,"Has Valet")), H14 * AVERAGE(Accounts!J$2:J$36),H14*Accounts!J14) | J14: 150000 | K14: =J14*0.25
A15: =Accounts!A15 | B15: Hotel | C15: PMC | D15: =Accounts!K15 | E15: 0.6 | F15: =Accounts!K15*E15 | G15: 0.4 | H15: =F15*G15 | I15: =if(or(eq(Accounts!J15,"No Valet"),eq(Accounts!J15,"Has Valet")), H15 * AVERAGE(Accounts!J$2:J$36),H15*Accounts!J15) | J15: =iferror(I15*360,"") | K15: =J15*0.1
A16: =Accounts!A16 | B16: Hotel | D16: =Accounts!K16 | E16: 0.6 | F16: =Accounts!K16*E16 | G16: 0.4 | H16: =F16*G16 | I16: =if(or(eq(Accounts!J16,"No Valet"),eq(Accounts!J16,"Has Valet")), H16 * AVERAGE(Accounts!J$2:J$36),H16*Accounts!J16) | J16: =iferror(I16*360,"") | K16: =J16*0.1
A17: =Accounts!A17 | B17: Hotel | D17: =Accounts!K17 | E17: 0.6 | F17: =Accounts!K17*E17 | G17: 0.4 | H17: =F17*G17 | I17: =if(or(eq(Accounts!J17,"No Valet"),eq(Accounts!J17,"Has Valet")), H17 * AVERAGE(Accounts!J$2:J$36),H17*Accounts!J17) | J17: =iferror(I17*360,"") | K17: =J17*0.1
A18: =Accounts!A18 | B18: Hotel | C18: PMC | D18: =Accounts!K18 | E18: 0.6 | F18: =Accounts!K18*E18 | G18: 0.4 | H18: =F18*G18 | I18: =if(or(eq(Accounts!J18,"No Valet"),eq(Accounts!J18,"Has Valet")), H18 * AVERAGE(Accounts!J$2:J$36),H18*Accounts!J18) | J18: =iferror(I18*360,"") | K18: =J18*0.1
A19: =Accounts!A19 | B19: Hotel | C19: PMC | D19: =Accounts!K19 | E19: 0.6 | F19: =Accounts!K19*E19 | G19: 0.4 | H19: =F19*G19 | I19: =if(or(eq(Accounts!J19,"No Valet"),eq(Accounts!J19,"Has Valet")), H19 * AVERAGE(Accounts!J$2:J$36),H19*Accounts!J19) | J19: =iferror(I19*360,"") | K19: =J19*0.1
A20: =Accounts!A20 | B20: Hotel | C20: In House | D20: =Accounts!K20 | E20: 0.6 | F20: =Accounts!K20*E20 | G20: 0.4 | H20: =F20*G20 | I20: =if(or(eq(Accounts!J20,"No Valet"),eq(Accounts!J20,"Has Valet")), H20 * AVERAGE(Accounts!J$2:J$36),H20*Accounts!J20) | J20: =iferror(I20*360,"") | K20: =J20*0.1
A21: =Accounts!A21 | B21: Hotel | C21: PMC | D21: =Accounts!K21 | E21: 0.6 | F21: =Accounts!K21*E21 | G21: 0.4 | H21: =F21*G21 | I21: =if(or(eq(Accounts!J21,"No Valet"),eq(Accounts!J21,"Has Valet")), H21 * AVERAGE(Accounts!J$2:J$36),H21*Accounts!J21) | J21: =iferror(I21*360,"") | K21: =J21*0.1
A22: =Accounts!A22 | B22: Hotel | D22: =Accounts!K22 | E22: 0.6 | F22: =Accounts!K22*E22 | G22: 0.4 | H22: =F22*G22 | I22: =if(or(eq(Accounts!J22,"No Valet"),eq(Accounts!J22,"Has Valet")), H22 * AVERAGE(Accounts!J$2:J$36),H22*Accounts!J22) | J22: =iferror(I22*360,"") | K22: =J22*0.1
A23: =Accounts!A23 | B23: Hotel | C23: PMC | D23: =Accounts!K23 | E23: 0.6 | F23: =Accounts!K23*E23 | G23: 0.4 | H23: =F23*G23 | I23: =if(or(eq(Accounts!J23,"No Valet"),eq(Accounts!J23,"Has Valet")), H23 * AVERAGE(Accounts!J$2:J$36),H23*Accounts!J23) | J23: =iferror(I23*360,"") | K23: =J23*0.1
A24: =Accounts!A24 | B24: Restaurant | C24: None | D24: =Accounts!K24 | E24: 0.6 | F24: =Accounts!K24*E24 | G24: 0.4 | H24: =F24*G24 | I24: =if(or(eq(Accounts!J24,"No Valet"),eq(Accounts!J24,"Has Valet")), H24 * AVERAGE(Accounts!J$2:J$36),H24*Accounts!J24) | J24: 100000 | K24: =J24*0.1
A25: =Accounts!A25 | B25: Restaurant | C25: Park Inc | D25: =Accounts!K25 | E25: 0.6 | F25: =Accounts!K25*E25 | G25: 0.4 | H25: =F25*G25 | I25: =if(or(eq(Accounts!J25,"No Valet"),eq(Accounts!J25,"Has Valet")), H25 * AVERAGE(Accounts!J$2:J$36),H25*Accounts!J25) | J25: 150000 | K25: =J25*0.25
A26: =Accounts!A26 | B26: Hotel | C26: PMC | D26: =Accounts!K26 | E26: 0.6 | F26: =Accounts!K26*E26 | G26: 0.4 | H26: =F26*G26 | I26: =if(or(eq(Accounts!J26,"No Valet"),eq(Accounts!J26,"Has Valet")), H26 * AVERAGE(Accounts!J$2:J$36),H26*Accounts!J26) | J26: =iferror(I26*360,"") | K26: =J26*0.1
A27: =Accounts!A27 | B27: Restaurant | C27: None | D27: =Accounts!K27 | E27: 0.6 | F27: =Accounts!K27*E27 | G27: 0.4 | H27: =F27*G27 | I27: =if(or(eq(Accounts!J27,"No Valet"),eq(Accounts!J27,"Has Valet")), H27 * AVERAGE(Accounts!J$2:J$36),H27*Accounts!J27) | J27: 100000 | K27: =J27*0.1
A28: =Accounts!A28 | B28: Restaurant | C28: None | D28: =Accounts!K28 | E28: 0.6 | F28: =Accounts!K28*E28 | G28: 0.4 | H28: =F28*G28 | I28: =if(or(eq(Accounts!J28,"No Valet"),eq(Accounts!J28,"Has Valet")), H28 * AVERAGE(Accounts!J$2:J$36),H28*Accounts!J28) | J28: 100000 | K28: =J28*0.1
A29: =Accounts!A29 | B29: Restaurant | C29: None | D29: =Accounts!K29 | E29: 0.6 | F29: =Accounts!K29*E29 | G29: 0.4 | H29: =F29*G29 | I29: =if(or(eq(Accounts!J29,"No Valet"),eq(Accounts!J29,"Has Valet")), H29 * AVERAGE(Accounts!J$2:J$36),H29*Accounts!J29) | J29: 100000 | K29: =J29*0.1
A30: =Accounts!A30 | B30: Restaurant | D30: =Accounts!K30 | E30: 0.6 | F30: =Accounts!K30*E30 | G30: 0.4 | H30: =F30*G30 | I30: =if(or(eq(Accounts!J30,"No Valet"),eq(Accounts!J30,"Has Valet")), H30 * AVERAGE(Accounts!J$2:J$36),H30*Accounts!J30) | J30: =iferror(I30*360,"") | K30: =J30*0.1
A31: =Accounts!A31 | B31: Restaurant | C31: None | D31: =Accounts!K31 | E31: 0.6 | F31: =Accounts!K31*E31 | G31: 0.4 | H31: =F31*G31 | I31: =if(or(eq(Accounts!J31,"No Valet"),eq(Accounts!J31,"Has Valet")), H31 * AVERAGE(Accounts!J$2:J$36),H31*Accounts!J31) | J31: 100000 | K31: =J31*0.1
A32: =Accounts!A32 | B32: Restaurant | C32: None | D32: =Accounts!K32 | E32: 0.6 | F32: =Accounts!K32*E32 | G32: 0.4 | H32: =F32*G32 | I32: =if(or(eq(Accounts!J32,"No Valet"),eq(Accounts!J32,"Has Valet")), H32 * AVERAGE(Accounts!J$2:J$36),H32*Accounts!J32) | J32: 100000 | K32: =J32*0.1
A33: =Accounts!A33 | B33: Restaurant | C33: None | D33: =Accounts!K33 | E33: 0.6 | F33: =Accounts!K33*E33 | G33: 0.4 | H33: =F33*G33 | I33: =if(or(eq(Accounts!J33,"No Valet"),eq(Accounts!J33,"Has Valet")), H33 * AVERAGE(Accounts!J$2:J$36),H33*Accounts!J33) | J33: 100000 | K33: =J33*0.1
A34: =Accounts!A34 | B34: Hotel | D34: =Accounts!K34 | E34: 0.6 | F34: =Accounts!K34*E34 | G34: 0.4 | H34: =F34*G34 | I34: =if(or(eq(Accounts!J34,"No Valet"),eq(Accounts!J34,"Has Valet")), H34 * AVERAGE(Accounts!J$2:J$36),H34*Accounts!J34) | J34: =iferror(I34*360,"") | K34: =J34*0.1
A35: =Accounts!A35 | B35: Restaurant | C35: None | D35: =Accounts!K35 | E35: 0.6 | F35: =Accounts!K35*E35 | G35: 0.4 | H35: =F35*G35 | I35: =if(or(eq(Accounts!J35,"No Valet"),eq(Accounts!J35,"Has Valet")), H35 * AVERAGE(Accounts!J$2:J$36),H35*Accounts!J35) | J35: 100000 | K35: =J35*0.1
A36: =Accounts!A36 | B36: Restaurant | C36: None | D36: =Accounts!K36 | E36: 0.6 | F36: =Accounts!K36*E36 | G36: 0.4 | H36: =F36*G36 | I36: =if(or(eq(Accounts!J36,"No Valet"),eq(Accounts!J36,"Has Valet")), H36 * AVERAGE(Accounts!J$2:J$36),H36*Accounts!J36) | J36: 100000 | K36: =J36*0.1
A37: =Accounts!A37 | B37: Restaurant | C37: None | D37: =Accounts!K37 | E37: 0.6 | F37: =Accounts!K37*E37 | G37: 0.4 | H37: =F37*G37 | I37: =if(or(eq(Accounts!J37,"No Valet"),eq(Accounts!J37,"Has Valet")), H37 * AVERAGE(Accounts!J$2:J$36),H37*Accounts!J37) | J37: 100000 | K37: =J37*0.1
A38: =Accounts!A38 | B38: Restaurant | C38: None | D38: =Accounts!K38 | E38: 0.6 | F38: =Accounts!K38*E38 | G38: 0.4 | H38: =F38*G38 | I38: =if(or(eq(Accounts!J38,"No Valet"),eq(Accounts!J38,"Has Valet")), H38 * AVERAGE(Accounts!J$2:J$36),H38*Accounts!J38) | J38: 100000 | K38: =J38*0.1
A39: =Accounts!A39 | B39: Hotel | D39: =Accounts!K39 | E39: 0.6 | F39: =Accounts!K39*E39 | G39: 0.4 | H39: =F39*G39 | I39: =if(or(eq(Accounts!J39,"No Valet"),eq(Accounts!J39,"Has Valet")), H39 * AVERAGE(Accounts!J$2:J$36),H39*Accounts!J39) | J39: =iferror(I39*360,"") | K39: =J39*0.1
A40: =Accounts!A40 | B40: Restaurant | C40: None | D40: =Accounts!K40 | E40: 0.6 | F40: =Accounts!K40*E40 | G40: 0.4 | H40: =F40*G40 | I40: =if(or(eq(Accounts!J40,"No Valet"),eq(Accounts!J40,"Has Valet")), H40 * AVERAGE(Accounts!J$2:J$36),H40*Accounts!J40) | J40: 100000 | K40: =J40*0.1
...

Sheet Analysis
A1: SOPHI's MARKET SCORE | B1: =G2 | C1: TAM | D1: SAM | E1: SOM | G1: Total | H1: Location | I1: Connections | J1: Garage | K1: Growth | L1: capacity | M1: cash flow | O1: Connection 3 | P1: Volume 2 170 + 2 100 + 1 | Q1: Location Downtown 1 Far -1 | R1: High End | S1: Garage Connection 2 location 1 | T1: Valet & Paid Self Park | U1: Points | V1: Priority
C2: =SUM(RevenueForecasting!J:J) | D2: =SUMIF(#REF!,1,RevenueForecasting!J2:J36) | E2: =D2/SUM(#REF!) | G2: =SUM(H2:L2)*2 & " /100" | H2: 7 | I2: 0 | J2: 8 | K2: 7
C3: sum of predicted revenues | D3: Guess of locations that I could see being interested in introducing valet | E3: SAM / # of locations in SAM. Representing 1 Hotel landed
C4: all valet, all parking contracts, additional services, bell etc | D4: realistically obtained | E4: going to get | H4: 257 miles | I4: locations? 0/7 | J4: public? 8/8 | K4: Population? 2/4 | L4: personal bandwidth 0/4 | M4: costs
H5: SB X | I5: 1 connection -> 5 2+ connections -> 7 | J5: yes or no | K5: small city, medium city, large city, metropolis
H6: CH | I6: employees? 3 | J6: connection? 2 | K6: Events Space? 4 | L6: hire 0/3
A7: Average Self Park | B7: Average Valet | I7: # of possible employees | J7: yes or no | K7: # of markets
A8: =AVERAGE(Accounts!I:I) | B8: =AVERAGE(Accounts!J:J) | H8: 0 -> 1000+ | K8: Parking? 2 | L8: management 0/3
H9: 3 -> 700 - 1000 | K9: reducing, steady, increasing
H10: 5 -> 500 - 700
H11: 7 -> 250 - 500
H12: 10 -> 0 - 250

Sheet Detail2-PMC-Hotel
A1: Accounts | B1: Account Type | C1: Contact Created? | D1: Address | E1: Phone Number | F1: Email | G1: URL | H1: Self Parking Rate | I1: Valet Rate | J1: # of Rooms | K1: Parking Reviews % | L1: Parking Reviews # | M1: GM Name | N1: Management Group | O1: Linked Accounts | P1: Garage Operator | Q1: Valet Operator | R1: Sourcing Notes | S1: Location Notes
A2: Hilton Charlotte Uptown | B2: Hotel | D2: 222 East vThird Street Charlotte NC 20802 | E2: 7043771500 | H2: 24 | I2: 34 | J2: 149 | K2: 0.51 | L2: 224 | Q2: PMC
A3: The Ivey's Hotel | B3: Hotel | D3: 127 N Tryon St, Charlotte, NC 28202 | G3: https://www.theiveysHotel.com/ | I3: 35 | J3: 47 | K3: 0.52 | L3: 89 | P3: LAZ | Q3: PMC
A4: Hyatt Place | B4: Hotel | D4: 222 S Caldwell St, Charlotte NC 28202 | E4: 7042270500 | F4: Check your email/texts for contact updated | G4: tien.ning@hyatt.com | H4: n/a | I4: 38 | J4: 172 | K4: 0.72 | L4: 484 | M4: Tien Ning | Q4: PMC | S4: pretty solid valet reviews. maybe bundled services or damage claim pitching
A5: AC Hotel Residents inn | B5: Hotel | D5: 220 East Trade Street, Suite 1400, Charlotte, NC, 28202 | E5: 7043484002 | F5: rob.cote@marriott.com | G5: https://www.marriott.com/en-us/Hotels/cltad-ac-Hotel-charlotte-city-center/overview/?scid=f2ae0541-1279-4f24-b197-a979c79310b0 | H5: 29 | I5: 40 | J5: 149 | K5: 0.52 | L5: 117 | M5: Rob Cote | P5: Preferred | Q5: PMC
A6: Omni Hotel | B6: Hotel | D6: 132 E Trade St, Charlotte, NC 28202 | G6: https://www.omniHotels.com/Hotels/charlotte | I6: 40 | J6: 373 | K6: 0.39 | L6: 270 | P6: LAZ | Q6: PMC
A7: SpringHill | B7: Hotel | D7: 311 E 5th St, Charlotte, NC 28202 | E7: shsuptown@sree.com | G7: https://www.marriott.com/en-us/Hotels/cltsd-springhill-suites-charlotte-city-center/overview/?scid=f2ae0541-1279-4f24-b197-a979c79310b0 | H7: Not available | I7: 40 | J7: 195 | K7: 0.38 | L7: 190 | M7: Karen Owens | Q7: PMC
A8: Grand Bohemian Hotel | B8: Hotel | D8: 201 W Trade St, Charlotte, NC 28202 | E8: (704) 372-1877 | F8: hugh.templeman@kesslercollection.com | G8: https://www.kesslercollection.com/bohemian-charlotte/ | H8: unknown | I8: 48 | J8: 254 | K8: 0.65 | L8: 122 | M8: Hugh Templeman | Q8: PMC | S8: Wait for new GM
A9: JW Marriott Charlotte | B9: Hotel | D9: 600 S College St, Charlotte, NC 28202 | E9: David.malmberg@whitelodging.com | G9: https://www.marriott.com/en-us/Hotels/cltjw-jw-marriott-charlotte/overview/ | H9: n/a | I9: 48 | J9: 381 | K9: 0.48 | L9: 87 | Q9: PMC | S9: Reviews about the valet are mostly terrible.
A10: Kimpton Tryon Park Hotel | B10: Hotel | D10: 303 S Church St, Charlotte, NC 28202 | E10: 7044477662 (Direct line) | G10: https://www.tryonparkHotel.com/ | I10: 48 | J10: 217 | K10: 0.54 | L10: 162 | M10: Yvette Bullock | P10: Preferred | Q10: PMC | S10: $30 4 hours max Valet
A11: Charlotte Marriott City Center | B11: Hotel | D11: 100 W Trade St, Charlotte, NC 28202 | F11: jennifer.correa@marriott.com | G11: https://www.marriott.com/en-us/Hotels/cltcc-charlotte-marriott-city-center/overview/?scid=f2ae0541-1279-4f24-b197-a979c79310b0 | I11: 48 | J11: 440 | K11: 0.4 | L11: 181 | M11: Jennifer Correa | Q11: PMC | S11: poor reviews

Sheet TAM_Conservative
A1: Account | B1: Account Type | C1: TAM Class | D1: Rooms/Beds | E1: Seats | F1: Occupancy % | G1: Turnover | H1: Valet Conv % | I1: Valet Rate | J1: Op Days | K1: Peak Mod | L1: Daily Rev | M1: TAM | N1: TAM Status | O1: Notes / Source
A2: Aloft Charlotte City Center | B2: Hotel | C2: Hotel — Downtown Select-Service | D2: 175 | F2: 0.6 | H2: 0.25 | I2: 25 | J2: 360 | L2: 656.25 | M2: 236250 | N2: Active TAM | O2: Auto-class: downtown + select-service flag. Occ 60% flat (refine w/STR).
A3: Courtyard By Marriott | B3: Hotel | C3: Hotel — Downtown Select-Service | D3: 181 | F3: 0.6 | H3: 0.25 | J3: 360 | N3: No Valet / TAM = $0 | O3: Hotel has no valet (rate field: None). Auto-class: downtown + select-service flag. Qualitative pipeline only.
A4: Fairfield Inn & Suites | B4: Hotel | C4: Hotel — Downtown Select-Service | D4: 196 | F4: 0.6 | H4: 0.25 | J4: 360 | N4: No Valet / TAM = $0 | O4: Hotel has no valet (rate field: None). Auto-class: downtown + select-service flag. Qualitative pipeline only.
A5: Hampton Inn Uptown | B5: Hotel | C5: Hotel — Downtown Select-Service | D5: 250 | F5: 0.6 | H5: 0.25 | J5: 360 | N5: No Valet / TAM = $0 | O5: Hotel has no valet (rate field: None). Auto-class: downtown + select-service flag. Qualitative pipeline only.
A6: Hilton Garden Inn (SouthPark) | B6: Hotel | C6: Hotel — Suburban/Airport | D6: 160 | F6: 0.6 | H6: 0.15 | J6: 360 | N6: No Valet / TAM = $0 | O6: Hotel has no valet (rate field: None). Auto-class: not downtown (by flag or name). Qualitative pipeline only.
A7: Hilton/Hilton Garden Inn | B7: Hotel | C7: Hotel — Downtown Select-Service | D7: 181 | F7: 0.6 | H7: 0.25 | J7: 360 | N7: No Valet / TAM = $0 | O7: Hotel has no valet (rate field: None). Auto-class: downtown full-service <300 rooms. Qualitative pipeline only.
A8: Home2Suites | B8: Hotel | C8: Hotel — Downtown Select-Service | D8: 180 | F8: 0.6 | H8: 0.25 | J8: 360 | N8: No Valet / TAM = $0 | O8: Hotel has no valet (rate field: None). Auto-class: downtown + select-service flag. Qualitative pipeline only.
A9: Hilton Charlotte Uptown | B9: Hotel | C9: Hotel — Downtown Select-Service | D9: 149 | F9: 0.6 | H9: 0.25 | I9: 34 | J9: 360 | L9: 759.9 | M9: 273564 | N9: Active TAM | O9: Auto-class: downtown full-service <300 rooms. Occ 60% flat (refine w/STR).
A10: Le Meridien Charlotte | B10: Hotel | C10: Hotel — Downtown+Convention | D10: 300 | F10: 0.6 | H10: 0.4 | I10: 35 | J10: 360 | L10: 2520 | M10: 907200 | N10: Active TAM | O10: Auto-class: downtown + 300 rooms. Occ 60% flat (refine w/STR).
A11: Sheraton Hotel | B11: Hotel | C11: Hotel — Downtown+Convention | D11: 305 | F11: 0.6 | H11: 0.4 | I11: 35 | J11: 360 | L11: 2562 | M11: 922320 | N11: Active TAM | O11: Auto-class: downtown + 305 rooms. Occ 60% flat (refine w/STR).
A12: The Ivey's Hotel | B12: Hotel | C12: Hotel — Downtown Select-Service | D12: 47 | F12: 0.6 | H12: 0.25 | I12: 35 | J12: 360 | L12: 246.75 | M12: 88830 | N12: Active TAM | O12: Auto-class: downtown full-service <300 rooms. Occ 60% flat (refine w/STR).
A13: Hyatt Place | B13: Hotel | C13: Hotel — Downtown Select-Service | D13: 172 | F13: 0.6 | H13: 0.25 | I13: 38 | J13: 360 | L13: 980.4 | M13: 352944 | N13: Active TAM | O13: Auto-class: downtown + select-service flag. Occ 60% flat (refine w/STR).
A14: The Dunhill | B14: Hotel | C14: Hotel — Downtown Select-Service | D14: 60 | F14: 0.6 | H14: 0.25 | I14: 38 | J14: 360 | L14: 342 | M14: 123120 | N14: Active TAM | O14: Auto-class: downtown full-service <300 rooms. Occ 60% flat (refine w/STR).
A15: AC Hotel Residents inn | B15: Hotel | C15: Hotel — Downtown Select-Service | D15: 149 | F15: 0.6 | H15: 0.25 | I15: 40 | J15: 360 | L15: 894 | M15: 321840 | N15: Active TAM | O15: Auto-class: downtown + select-service flag. Occ 60% flat (refine w/STR).
A16: DoubleTree by Hilton Charlotte-Center City | B16: Hotel | C16: Hotel — Downtown Select-Service | D16: 187 | F16: 0.6 | H16: 0.25 | I16: 40 | J16: 360 | L16: 1122 | M16: 403920 | N16: Active TAM | O16: Auto-class: downtown full-service <300 rooms. Occ 60% flat (refine w/STR).
A17: Omni Hotel | B17: Hotel | C17: Hotel — Downtown+Convention | D17: 373 | F17: 0.6 | H17: 0.4 | I17: 40 | J17: 360 | L17: 3580.8 | M17: 1289088 | N17: Active TAM | O17: Auto-class: downtown + 373 rooms. Occ 60% flat (refine w/STR).
A18: SpringHill | B18: Hotel | C18: Hotel — Downtown Select-Service | D18: 195 | F18: 0.6 | H18: 0.25 | I18: 40 | J18: 360 | L18: 1170 | M18: 421200 | N18: Active TAM | O18: Auto-class: downtown + select-service flag. Occ 60% flat (refine w/STR).
A19: Element Charlotte Uptown | B19: Hotel | C19: Hotel — Downtown Select-Service | D19: 173 | F19: 0.6 | H19: 0.25 | I19: 42 | J19: 360 | L19: 1089.9 | M19: 392364 | N19: Active TAM | O19: Auto-class: downtown + select-service flag. Occ 60% flat (refine w/STR).
A20: Hyatt House Charlotte Center City | B20: Hotel | C20: Hotel — Downtown Select-Service | D20: 163 | F20: 0.6 | H20: 0.25 | I20: 42 | J20: 360 | L20: 1026.9 | M20: 369684 | N20: Active TAM | O20: Auto-class: downtown + select-service flag. Occ 60% flat (refine w/STR).
A21: Homewood Suites by Hilton Charlotte Uptown | B21: Hotel | C21: Hotel — Downtown Select-Service | D21: 211 | F21: 0.6 | H21: 0.25 | I21: 45 | J21: 360 | L21: 1424.25 | M21: 512730 | N21: Active TAM | O21: Auto-class: downtown + select-service flag. Occ 60% flat (refine w/STR).
A22: Embassy Suites by Hilton Charlotte Uptown | B22: Hotel | C22: Hotel — Downtown Select-Service | F22: 0.6 | H22: 0.25 | I22: 45 | J22: 360 | N22: Active TAM | O22: Auto-class: downtown full-service <300 rooms. Occ 60% flat (refine w/STR).
A23: The Westin Charlotte | B23: Hotel | C23: Hotel — Downtown+Convention | D23: 700 | F23: 0.6 | H23: 0.4 | I23: 45 | J23: 360 | L23: 7560 | M23: 2721600 | N23: Active TAM | O23: Auto-class: downtown + 700 rooms (>=400). Occ 60% flat (refine w/STR).
A24: Grand Bohemian Hotel | B24: Hotel | C24: Hotel — Downtown Select-Service | D24: 254 | F24: 0.6 | H24: 0.25 | I24: 48 | J24: 360 | L24: 1828.8 | M24: 658368 | N24: Active TAM | O24: Auto-class: downtown full-service <300 rooms. Occ 60% flat (refine w/STR).
A25: JW Marriott Charlotte | B25: Hotel | C25: Hotel — Downtown+Convention | D25: 381 | F25: 0.6 | H25: 0.4 | I25: 48 | J25: 360 | L25: 4389.12 | M25: 1580083.2 | N25: Active TAM | O25: Auto-class: downtown + 381 rooms. Occ 60% flat (refine w/STR).
A26: Kimpton Tryon Park Hotel | B26: Hotel | C26: Hotel — Downtown Select-Service | D26: 217 | F26: 0.6 | H26: 0.25 | I26: 48 | J26: 360 | L26: 1562.4 | M26: 562464 | N26: Active TAM | O26: Auto-class: downtown full-service <300 rooms. Occ 60% flat (refine w/STR).
A27: Charlotte Marriott City Center | B27: Hotel | C27: Hotel — Downtown+Convention | D27: 440 | F27: 0.6 | H27: 0.4 | I27: 48 | J27: 360 | L27: 5068.8 | M27: 1824768 | N27: Active TAM | O27: Auto-class: downtown + 440 rooms (>=400). Occ 60% flat (refine w/STR).
A28: Ritz Carlton | B28: Hotel | C28: Hotel — Downtown Select-Service | D28: 146 | F28: 0.6 | H28: 0.25 | I28: 50 | J28: 360 | L28: 1095 | M28: 394200 | N28: Active TAM | O28: Auto-class: downtown full-service <300 rooms. Occ 60% flat (refine w/STR).
A29: Kasa FreeMoreWest Charlotte | B29: Hotel | C29: Hotel — Suburban/Airport | F29: 0.6 | H29: 0.15 | J29: 360 | N29: No Valet / TAM = $0 | O29: Hotel has no valet (rate field: None). Auto-class: not downtown (by flag or name). Qualitative pipeline only.
A30: Canopy by Hilton Charlotte Southpark | B30: Hotel | C30: Hotel — Suburban/Airport | F30: 0.6 | H30: 0.15 | J30: 360 | N30: No Valet / TAM = $0 | O30: Hotel has no valet (rate field: None). Auto-class: not downtown (by flag or name). Qualitative pipeline only.
A31: Courtyard by Marriott Charlotte SouthPark | B31: Hotel | C31: Hotel — Suburban/Airport | F31: 0.6 | H31: 0.15 | J31: 360 | N31: No Valet / TAM = $0 | O31: Hotel has no valet (rate field: None). Auto-class: not downtown (by flag or name). Qualitative pipeline only.
A32: Residence Inn by Marriott Charlotte SouthPark | B32: Hotel | C32: Hotel — Suburban/Airport | F32: 0.6 | H32: 0.15 | J32: 360 | N32: No Valet / TAM = $0 | O32: Hotel has no valet (rate field: None). Auto-class: not downtown (by flag or name). Qualitative pipeline only.
A33: Renaissance Charlotte SouthPark Hotel | B33: Hotel | C33: Hotel — Suburban/Airport | F33: 0.6 | H33: 0.15 | J33: 360 | N33: No Valet / TAM = $0 | O33: Hotel has no valet (rate field: None). Auto-class: not downtown (by flag or name). Qualitative pipeline only.
A34: Charlotte Marriott SouthPark | B34: Hotel | C34: Hotel — Suburban/Airport | F34: 0.6 | H34: 0.15 | J34: 360 | N34: No Valet / TAM = $0 | O34: Hotel has no valet (rate field: None). Auto-class: not downtown (by flag or name). Qualitative pipeline only.
A35: AC Hotel Charlotte SouthPark | B35: Hotel | C35: Hotel — Suburban/Airport | F35: 0.6 | H35: 0.15 | J35: 360 | N35: No Valet / TAM = $0 | O35: Hotel has no valet (rate field: None). Auto-class: not downtown (by flag or name). Qualitative pipeline only.
A36: Hyatt Centric Charlotte SouthPark | B36: Hotel | C36: Hotel — Suburban/Airport | F36: 0.6 | H36: 0.15 | J36: 360 | N36: No Valet / TAM = $0 | O36: Hotel has no valet (rate field: None). Auto-class: not downtown (by flag or name). Qualitative pipeline only.
A37: Homewood Suites by Hilton Charlotte/SouthPark | B37: Hotel | C37: Hotel — Suburban/Airport | F37: 0.6 | H37: 0.15 | J37: 360 | N37: No Valet / TAM = $0 | O37: Hotel has no valet (rate field: None). Auto-class: not downtown (by flag or name). Qualitative pipeline only.
A38: DoubleTree Suites by Hilton Hotel Charlotte - SouthPark | B38: Hotel | C38: Hotel — Suburban/Airport | F38: 0.6 | H38: 0.15 | J38: 360 | N38: No Valet / TAM = $0 | O38: Hotel has no valet (rate field: None). Auto-class: not downtown (by flag or name). Qualitative pipeline only.
A39: UNC Charlotte Marriott Hotel & Conference Center | B39: Hotel | C39: Hotel — Suburban/Airport | F39: 0.6 | H39: 0.15 | I39: 31 | J39: 360 | N39: Active TAM | O39: Auto-class: not downtown (by flag or name). Occ 60% flat (refine w/STR).
A40: Steak 48 | B40: Restaurant | C40: Restaurant — Steakhouse — flagship | E40: 300 | G40: 1.5 | H40: 0.125 | I40: 7 | J40: 250 | K40: 1.08 | L40: 843.75 | M40: 227812.5 | N40: Active TAM (MED confidence) | O40: Charlotte uptown location, active paid valet $7 on file | industry brand avg (Steak 48 flagship ~280-320 seats)
...

Sheet TAM_Summary
A1: Charlotte — Conservative TAM Summary
A3: Account Type | B3: # Accounts | C3: TAM | D3: Status
A4: Hotel | B4: 38 | C4: 14356537 | D4: Active TAM
A5: Restaurant | B5: 12 | C5: 2217375 | D5: Active TAM
A6: TOTAL | B6: 50 | C6: 16573912
A8: HOTEL BREAKDOWN BY CLASS
A9: Class | B9: # Hotels | C9: Conv %
A10: Downtown+Convention | B10: 6 | C10: 0.4
A11: Downtown Select-Service | B11: 20 | C11: 0.25
A12: Resort | B12: 0 | C12: 0.5
A13: Suburban/Airport | B13: 12 | C13: 0.15
A15: RESTAURANTS WITH ACTIVE TAM
A16: Restaurant | B16: Seats | C16: TAM
A17: Del Frisco's Double Eagle Steakhouse | B17: 400 | C17: 303750
A18: Steak 48 | B18: 300 | C18: 227812.5
A19: STK Steakhouse | B19: 275 | C19: 208828.12
A20: The Capital Grille | B20: 250 | C20: 189843.75
A21: Eddie V's Prime Seafood | B21: 250 | C21: 189843.75
A22: Ruth's Chris | B22: 250 | C22: 189843.75
A23: Fahrenheit CLT | B23: 225 | C23: 170859.38
A24: Chima Steakhouse | B24: 220 | C24: 167062.5
A25: Morton's Steakhouse | B25: 200 | C25: 151875
A26: Dean's Italian Steakhouse | B26: 200 | C26: 151875
A27: Fleming's Prime Steakhouse & Wine Bar | B27: 175 | C27: 132890.62
A28: Oak Steakhouse | B28: 175 | C28: 132890.62

Sheet TAM_Methodology
A1: SOPHI CONSERVATIVE TAM METHODOLOGY
A3: Replaces original RevenueForecasting formulas. Hospitals / Venues / Airports now qualitative only.
A5: HOTEL FORMULA
A6: TAM = Rooms × Occupancy × Valet Conversion (tiered) × Valet Rate × 360 days
A7: Occupancy: 60% flat across all hotels
A8: ⚠️ FLAG: Refine with STR actuals per-submarket before finalizing fundraise model
A9: Valet Conversion by archetype (auto-classified — review recommended):
