Workbook

Sheet INSTRUCTIONS
A1: DO NOT EDIT MASTER Market Analysis
A3: 2026 Denver, CO Market Analysis
A5: Sophi Mobility - Automated Valet Parking Services
A7: Generated: March 19, 2026
A9: Sheet Descriptions:
A11: Accounts | B11: Master list of all target accounts - hotels, restaurants, hospitals, event venues, airport
A12: Sales Cadence | B12: Outreach tracking with 11-touch sales cadence for each account
A13: To Copy this sheet: File -> Make a copy | B13: Inventory of public parking garages and lots with operators and rates
A14: RevenueForecasting | B14: Revenue model: rooms × occupancy × valet conversion × rate = annual revenue/NOI
A15: Analysis | B15: TAM/SAM/SOM market sizing, market score, and prioritization matrix
A16: Market Notes | B16: Key market data, rate benchmarks, tourism stats, and competitive landscape

Sheet Accounts
A1: Accounts | B1: Account Type | C1: Contact Created? | D1: Address | E1: Downtown (Yes or No) | F1: Phone Number | G1: Email | H1: URL | I1: Self Parking Rate | J1: Valet Rate | K1: # of Rooms/Beds | L1: Parking Reviews % | M1: Parking Reviews # | N1: GM Name | O1: Management Group | P1: Linked Accounts | Q1: Garage Operator | R1: Valet Operator | S1: Sourcing Notes | T1: Location Notes
A2: Le Méridien Denver Downtown | B2: Hotel | C2: False | D2: 1475 California St, Denver, CO 80202 | E2: YES | F2: (303) 893-1888 | H2: https://www.marriott.com/en-us/hotels/denmd-le-meridien-denver-downtown/overview/ | J2: 72 | K2: 272 | N2: Ebrahim Ansari | O2: White Lodging | Q2: Marriott | S2: upper-upscale | T2: White Lodging managed. Shares GM with AC Hotel Denver Downtown. Valet-only parking.
A3: The Ritz-Carlton, Denver | B3: Hotel | C3: False | D3: 1881 Curtis Street, Denver, CO 80202 | E3: YES | F3: (303) 312-3800 | H3: https://www.ritzcarlton.com/en/hotels/denrz-the-ritz-carlton-denver/overview/ | J3: 72 | K3: 205 | N3: Brad Mills | O3: Marriott International | S3: luxury | T3: Denver's premier luxury Marriott property.
A4: AC Hotel Denver Downtown | B4: Hotel | C4: False | D4: 750 15th St, Denver, CO 80202 | E4: NO | F4: (303) 825-2888 | H4: https://www.marriott.com/en-us/hotels/denac-ac-hotel-denver-downtown/overview/ | J4: 72 | K4: 223 | N4: Ebrahim Ansari | O4: White Lodging | Q4: Towne Park | R4: Towne Park | S4: upscale | T4: White Lodging managed. Towne Park valet. Shares GM with Le Méridien.
A5: Embassy Suites by Hilton Denver Downtown Convention Center | B5: Hotel | C5: False | D5: 1420 Stout St, Denver, CO 80202 | E5: NO | F5: (303) 592-1000 | H5: https://www.hilton.com/en/hotels/deneses-embassy-suites-denver-downtown-convention-center/ | J5: 70 | K5: 403 | N5: Ed Decker | O5: Sage Hospitality | R5: SP+ | S5: upper-upscale | T5: Valet only - no self-park on site. Updated 2026 rate: $70/night. SP+ operates valet per reviews.
A6: Aloft Denver Downtown | B6: Hotel | C6: False | D6: 800 15th St, Denver, CO 80202 | E6: NO | F6: (303) 623-3063 | H6: https://www.marriott.com/en-us/hotels/dendw-aloft-denver-downtown/overview/ | J6: 68 | K6: 140 | Q6: LAZ | R6: LAZ | S6: upscale | T6: Aloft Marriott brand. LAZ operates parking/valet.
A7: Sheraton Denver Downtown Hotel | B7: Hotel | C7: False | D7: 1550 Court Place, Denver, CO 80202 | E7: YES | F7: (303) 893-3333 | H7: https://www.marriott.com/en-us/hotels/dends-sheraton-denver-downtown-hotel/overview/ | I7: 57 | J7: 67 | K7: 1238 | N7: Tony Dunn | S7: upper-upscale | T7: Largest hotel in Denver by rooms. 139,165 sq ft meeting space. Updated 2026 rates: self $57, valet $67.
A8: Hyatt Regency Denver at Colorado Convention Center | B8: Hotel | C8: False | D8: 650 15th St, Denver, CO 80202 | E8: NO | F8: (303) 436-1234 | H8: https://www.hyatt.com/hyatt-regency/en-US/dencc-hyatt-regency-denver-at-colorado-convention-center | I8: 64 | J8: 67 | K8: 1100 | N8: Gregory Leonard | S8: upper-upscale | T8: 1,100 rooms - second largest hotel in Denver. Adjacent to Colorado Convention Center. 2026 valet rate: $67 overnight per Hyatt website.
A9: The Jacquard, Autograph Collection | B9: Hotel | C9: False | D9: 222 Milwaukee St, Denver, CO 80206 | E9: NO | F9: (303) 515-2000 | H9: https://www.marriott.com/en-us/hotels/dencr-the-jacquard-autograph-collection/overview/ | I9: 65 | J9: 65 | K9: 198 | N9: Thomas Lloyd | R9: Pro Park | S9: upper-upscale | T9: Boutique upscale hotel in Cherry Creek shopping district.
A10: Four Seasons Hotel Denver | B10: Hotel | C10: False | D10: 1111 14th St, Denver, CO 80202 | E10: YES | F10: (303) 389-3000 | H10: https://www.fourseasons.com/denver/ | J10: 65 | K10: 239 | N10: Thierry Kennel | O10: Four Seasons Hotels and Resorts | Q10: Four Seasons | R10: In House | S10: luxury | T10: Only 5-star luxury hotel in Denver. Valet operated in-house.
A11: The Brown Palace Hotel and Spa, Autograph Collection | B11: Hotel | C11: False | D11: 321 17th St, Denver, CO 80202 | E11: YES | F11: (303) 297-3111 | H11: https://www.marriott.com/en-us/hotels/denak-the-brown-palace-hotel-and-spa-autograph-collection/overview/ | J11: 65 | K11: 241 | N11: George Hanna | S11: luxury | T11: Denver's most iconic historic luxury hotel (1892). Michelin One Key 2024. Autograph Collection.
A12: Thompson Denver, by Hyatt | B12: Hotel | C12: False | D12: 1616 Market St, Denver, CO 80202 | E12: YES | F12: (303) 572-1321 | H12: https://www.hyatt.com/thompson-hotels/denth-thompson-denver | J12: 64 | K12: 216 | N12: Julian Tucker | O12: McWhinney | S12: luxury | T12: Boutique luxury hotel in LoDo. Chez Maggy restaurant, rooftop lounge.
A13: Grand Hyatt Denver | B13: Hotel | C13: False | D13: 1750 Welton St, Denver, CO 80202 | E13: YES | F13: (303) 295-1234 | H13: https://www.hyatt.com/grand-hyatt/en-US/denrd-grand-hyatt-denver | I13: 50 | J13: 64 | K13: 516 | N13: Greg Leonard | S13: upper-upscale | T13: 516-room Grand Hyatt near 16th Street Mall, Coors Field, Ball Arena.
A14: Hyatt Place Denver/Downtown | B14: Hotel | C14: False | D14: 440 14th St, Denver, CO 80202 | E14: NO | F14: (303) 893-2900 | H14: https://www.hyatt.com/hyatt-place/en-US/denzd-hyatt-place-denver-downtown | J14: 64 | K14: 248 | N14: Kimberly Gagnon | O14: White Lodging | Q14: Towne Park | R14: Towne Park | S14: upscale | T14: White Lodging managed. Towne Park operates valet. Shares address with Hyatt House.
A15: Populus | B15: Hotel | C15: False | D15: 240 14th St, Denver, CO 80202 | E15: NO | F15: (303) 800-4240 | H15: https://populusdenver.com/ | J15: 64 | K15: 265 | N15: George Prine | O15: Aparium Hotel Group | S15: upper-upscale | T15: Opened October 2024. First carbon-positive hotel in the US. 13-story aspen-inspired architecture. Aparium managed.
A16: Hilton Denver City Center | B16: Hotel | C16: False | D16: 1701 California St, Denver, CO 80202 | E16: YES | F16: (303) 297-1300 | H16: https://www.hilton.com/en/hotels/dencyhh-hilton-denver-city-center/ | J16: 64 | K16: 613 | N16: Mike Case | O16: Sage Hospitality | S16: upper-upscale | T16: Large full-service Hilton in downtown financial district. Sage Hospitality managed (as of Dec 2024).
A17: Halcyon, a hotel in Cherry Creek | B17: Hotel | C17: False | D17: 245 Columbine St, Denver, CO 80206 | E17: NO | F17: (720) 772-5000 | H17: https://www.halcyonhotelcherrycreek.com/ | J17: 60 | K17: 154 | N17: McClinton Heil | S17: luxury | T17: Boutique luxury hotel in Cherry Creek.
A18: Hampton Inn & Suites Denver Downtown-Convention Center | B18: Hotel | C18: False | D18: 550 15th St, Denver, CO 80202 | E18: NO | F18: (303) 623-5900 | H18: https://www.hilton.com/en/hotels/dencvhx-hampton-suites-denver-downtown-convention-center/ | J18: 60 | K18: 120 | Q18: Parking Management | S18: upper-midscale | T18: Shares block with Homewood Suites at 550 15th.
A19: Tru by Hilton Denver Downtown Convention Center | B19: Hotel | C19: False | D19: 801 15th St, Denver, CO 80202 | E19: NO | F19: (303) 753-1201 | H19: https://www.hilton.com/en/hotels/dencsru-tru-denver-downtown-convention-center/ | J19: 60 | K19: 176 | N19: Kara van Beek | S19: midscale | T19: Tru by Hilton brand. Shares GM with Home2 Suites at same address.
A20: Home2 Suites by Hilton Denver Downtown Convention Center | B20: Hotel | C20: False | D20: 801 15th St, Denver, CO 80202 | E20: NO | F20: (303) 759-1301 | H20: https://www.hilton.com/en/hotels/dentiht-home2-suites-denver-downtown-convention-center/ | J20: 60 | K20: 206 | N20: Kara van Beek | S20: upper-midscale | T20: Shares address and GM with Tru by Hilton.
A21: Homewood Suites by Hilton Denver Downtown-Convention Center | B21: Hotel | C21: False | D21: 550 15th St, Denver, CO 80202 | E21: NO | F21: (303) 534-7800 | H21: https://www.hilton.com/en/hotels/dendchw-homewood-suites-denver-downtown-convention-center-co/ | J21: 60 | K21: 182 | S21: upper-midscale | T21: Shares block with Hampton Inn at 550 15th. Recent renovation.
A22: Hotel Clio, a Luxury Collection Hotel, Denver Cherry Creek | B22: Hotel | C22: False | D22: 150 Clayton Ln, Denver, CO 80206 | E22: NO | F22: (303) 316-2700 | H22: https://www.marriott.com/en-us/hotels/denld-hotel-clio-a-luxury-collection-hotel-denver-cherry-creek/overview/ | J22: 59 | K22: 199 | N22: Marc Blackford | O22: Sage Hospitality | R22: Pro Park | S22: luxury | T22: Formerly JW Marriott Denver Cherry Creek. Rebranded to Luxury Collection.
A23: Clayton Hotel & Members Club | B23: Hotel | C23: False | D23: 233 Clayton St, Denver, CO 80206 | E23: NO | F23: (303) 551-1600 | H23: https://claytondenver.com/ | J23: 59 | K23: 63 | N23: Alison Mitchell | O23: Aparium Hotel Group | S23: luxury | T23: Boutique luxury members club hotel in Cherry Creek. Aparium managed.
A24: The Slate Hotel Denver Downtown, Tapestry by Hilton | B24: Hotel | C24: False | D24: 1250 Welton St, Denver, CO 80204 | E24: YES | F24: (303) 292-5000 | H24: https://www.hilton.com/en/hotels/denvrup-the-slate-hotel-denver-downtown/ | J24: 59 | K24: 251 | N24: Kirby Kiner | O24: Stonebridge Companies | Q24: Parkwell | S24: upscale | T24: Tapestry Collection by Hilton. Stonebridge managed. Parkwell operates garage.
A25: Kimpton Hotel Monaco Denver | B25: Hotel | C25: False | D25: 1717 Champa St, Denver, CO 80202 | E25: YES | F25: (303) 296-1717 | H25: https://www.monaco-denver.com/ | J25: 59 | K25: 189 | N25: Kevin Panzano | O25: IHG / Kimpton | Q25: Towne Park | R25: Towne Park | S25: upper-upscale | T25: Kimpton flagship downtown. Towne Park operates valet. Panzano Italian restaurant on site.
A26: Magnolia Hotel Denver, a Tribute Portfolio Hotel | B26: Hotel | C26: False | D26: 818 17th St, Denver, CO 80202 | E26: YES | F26: (303) 607-9000 | H26: https://www.marriott.com/en-us/hotels/denmg-magnolia-hotel-denver-a-tribute-portfolio-hotel/overview/ | J26: 59 | K26: 297 | N26: James Ancona | Q26: Marriott | S26: upscale | T26: Tribute Portfolio by Marriott in historic downtown building.
A27: Hyatt Centric Downtown Denver | B27: Hotel | C27: False | D27: 1776 Champa St, Denver, CO 80202 | E27: YES | F27: (303) 529-2340 | H27: https://www.hyatt.com/hyatt-centric/en-US/denct-hyatt-centric-downtown-denver | J27: 59 | K27: 264 | N27: Michael Galligan | S27: upscale | T27: 264 rooms per TripAdvisor. Rooftop bar. Valet-only at $59/night.
A28: Hotel Indigo Denver Downtown-Union Station | B28: Hotel | C28: False | D28: 1801 Wewatta St, Denver, CO 80202 | E28: NO | F28: (303) 623-4422 | H28: https://www.ihg.com/hotelindigo/hotels/us/en/denver/denws/hoteldetail | I28: 45 | J28: 55 | K28: 180 | N28: Michael Keytel | O28: Sage Hospitality | Q28: Intercontinental | S28: upscale | T28: IHG boutique brand. Steps from Union Station.
A29: Hotel Teatro | B29: Hotel | C29: False | D29: 1100 14th St, Denver, CO 80202 | E29: NO | F29: (888) 727-1200 | H29: https://www.hotelteatro.com/ | J29: 55 | K29: 111 | N29: Courtney Griffith | O29: Sage Hospitality | Q29: LAZ | R29: LAZ | S29: upper-upscale | T29: Boutique luxury theater district hotel. LAZ likely operates valet per garage operator pattern. Sold June 2024.
A30: Kimpton Claret Hotel | B30: Hotel | C30: False | D30: 6985 E. Chenango Ave, Denver, CO 80237 | E30: NO | F30: (983) 999-0310 | H30: https://www.clarethotel.com/ | J30: 55 | K30: 190 | N30: Keith Siebenaler | O30: IHG / Kimpton | S30: upper-upscale | T30: Opened July 2024. 19-story Kimpton with rooftop Halo Bar. 190 rooms. $55/night valet. Near Belleview Station.
A31: Apiary Hotel Belleview Station | B31: Hotel | C31: False | D31: 4855 S Quebec, Suite 150, Denver, CO 80237 | E31: NO | F31: (720) 791-4700 | H31: https://www.apiaryhotel.com/ | J31: 55 | K31: 175 | O31: Marriott / Residence Inn | S31: upscale | T31: Opened January 2026. Boutique Residence Inn-affiliated extended stay. 175 suites with kitchenettes. Near DTC and Belleview Station lightrail. Valet $55/night.
A32: The Art Hotel Denver, Curio Collection by Hilton | B32: Hotel | C32: False | D32: 1201 Broadway, Denver, CO 80203 | E32: NO | F32: (303) 572-8000 | H32: https://www.hilton.com/en/hotels/denrtqq-the-art-hotel-denver/ | J32: 54 | K32: 165 | N32: Dorian Phillips | S32: upscale | T32: Near Denver Art Museum. Curio Collection by Hilton. Valet-only parking.
A33: The Westin Denver Downtown | B33: Hotel | C33: False | D33: 1672 Lawrence St, Denver, CO 80202 | E33: NO | F33: (303) 572-9100 | H33: https://www.marriott.com/en-us/hotels/denwi-the-westin-denver-downtown/overview/ | I33: 40 | J33: 54 | K33: 432 | N33: Jerry Caliguire | S33: upper-upscale | T33: Full-service Westin in LoDo. Large conference hotel.
A34: The Westin Denver International Airport | B34: Hotel | C34: False | D34: 8300 Peña Boulevard, Denver, CO 80249 | E34: NO | F34: (303) 317-1800 | H34: https://www.marriott.com/en-us/hotels/denaw-the-westin-denver-international-airport/overview/ | I34: 54 | J34: 54 | K34: 519 | O34: Marriott International | Q34: Pro Park | R34: Pro Park | S34: upper-upscale | T34: Only hotel connected to DIA terminal. 519 rooms. Pro Park is exclusive valet at DIA. Hotel guests $54/night; airport guests $59. After 5 days: $35/night.
A35: The Maven Hotel at Dairy Block | B35: Hotel | C35: False | D35: 1850 Wazee St, Denver, CO 80202 | E35: NO | F35: (720) 460-2727 | H35: https://www.themavenhotel.com/ | J35: 53 | K35: 172 | N35: Jennifer Cottingias | O35: Sage Hospitality | Q35: Sage Hospitality | S35: upscale | T35: Part of the Dairy Block mixed-use development. Sage operates garage.
A36: Catbird Hotel | B36: Hotel | C36: False | D36: 3770 Walnut St, Denver, CO 80205 | E36: NO | F36: (720) 990-5555 | H36: https://www.catbirdhotel.com/ | I36: 34 | J36: 52 | K36: 165 | O36: Sage Hospitality | S36: upscale | T36: Boutique lifestyle hotel in River North Arts District.
A37: Limelight Denver | B37: Hotel | C37: False | D37: 2020 Little Raven St, Denver, CO 80202 | E37: NO | F37: (303) 323-0024 | H37: https://limelighthotels.com/denver | J37: 50 | K37: 200 | N37: Kim Corrigan | O37: Aspen Hospitality | S37: upscale | T37: Formerly Kimpton Hotel Born. Rebranded 2023. Near Union Station. Aspen Hospitality flagship urban property.
A38: The Crawford Hotel | B38: Hotel | C38: False | D38: 1701 Wynkoop St, Denver, CO 80202 | E38: NO | F38: (720) 460-3700 | H38: https://thecrawfordhotel.com/ | J38: 50 | K38: 112 | O38: Sage Hospitality | S38: upper-upscale | T38: Historic hotel inside Denver Union Station. $11M renovation completed July 2024. Michelin One Key designation 2024.
A39: Warwick Denver | B39: Hotel | C39: False | D39: 1776 Grant St, Denver, CO 80203 | E39: NO | F39: (303) 861-2000 | H39: https://www.warwickhotels.com/warwick-denver | I39: 50 | J39: 50 | K39: 216 | N39: Chad Hansen | Q39: SP Plus Corporation | R39: SP+ | S39: upscale | T39: Independent European chain. SP+ operates both self-park and valet.
A40: Moxy Denver Cherry Creek | B40: Hotel | C40: False | D40: 2401 E. 2nd Ave, Denver, CO 80206 | E40: NO | F40: (720) 707-3247 | H40: https://www.marriott.com/en-us/hotels/denox-moxy-denver-cherry-creek/overview/ | J40: 49 | K40: 140 | N40: Emily Jackson | O40: Sage Hospitality | S40: upscale | T40: Trendy Marriott Moxy brand in Cherry Creek.
...

Sheet Sales Cadence
A1: Accounts | B1: Contact Created? | C1: GM Name | D1: GM Contact Info | E1: Phone Number | F1: Garage Operator | G1: Valet Operator | H1: Self Parking Rate | I1: Valet Rate | J1: Sourcing Notes | K1: SALES NOTES | M1: 1. LinkedIn | N1: 2. Cold Call | O1: 3. In Person Visit | P1: 4. First Email | Q1: 5. Cold Call | R1: 6. Second Follow Up Email | S1: 7. Cold Call | T1: 8. 2nd In Person Visit | U1: 9. Cold Call + VM | V1: 10. Video Email - Owner | W1: 11. 3rd Email - Temp Check
A2: Le Méridien Denver Downtown | B2: False | C2: Ebrahim Ansari | E2: (303) 893-1888 | F2: Marriott | I2: 72 | J2: upper-upscale | M2: False | N2: False | O2: False | P2: False | Q2: False | R2: False | S2: False | T2: False | U2: False | V2: False | W2: False
A3: The Ritz-Carlton, Denver | B3: False | C3: Brad Mills | E3: (303) 312-3800 | I3: 72 | J3: luxury | M3: False | N3: False | O3: False | P3: False | Q3: False | R3: False | S3: False | T3: False | U3: False | V3: False | W3: False
A4: AC Hotel Denver Downtown | B4: False | C4: Ebrahim Ansari | E4: (303) 825-2888 | F4: Towne Park | G4: Towne Park | I4: 72 | J4: upscale | M4: False | N4: False | O4: False | P4: False | Q4: False | R4: False | S4: False | T4: False | U4: False | V4: False | W4: False
A5: Embassy Suites by Hilton Denver Downtown Convention Center | B5: False | C5: Ed Decker | E5: (303) 592-1000 | G5: SP+ | I5: 70 | J5: upper-upscale | M5: False | N5: False | O5: False | P5: False | Q5: False | R5: False | S5: False | T5: False | U5: False | V5: False | W5: False
A6: Aloft Denver Downtown | B6: False | E6: (303) 623-3063 | F6: LAZ | G6: LAZ | I6: 68 | J6: upscale | M6: False | N6: False | O6: False | P6: False | Q6: False | R6: False | S6: False | T6: False | U6: False | V6: False | W6: False
A7: Sheraton Denver Downtown Hotel | B7: False | C7: Tony Dunn | E7: (303) 893-3333 | H7: 57 | I7: 67 | J7: upper-upscale | M7: False | N7: False | O7: False | P7: False | Q7: False | R7: False | S7: False | T7: False | U7: False | V7: False | W7: False
A8: Hyatt Regency Denver at Colorado Convention Center | B8: False | C8: Gregory Leonard | E8: (303) 436-1234 | H8: 64 | I8: 67 | J8: upper-upscale | M8: False | N8: False | O8: False | P8: False | Q8: False | R8: False | S8: False | T8: False | U8: False | V8: False | W8: False
A9: The Jacquard, Autograph Collection | B9: False | C9: Thomas Lloyd | E9: (303) 515-2000 | G9: Pro Park | H9: 65 | I9: 65 | J9: upper-upscale | M9: False | N9: False | O9: False | P9: False | Q9: False | R9: False | S9: False | T9: False | U9: False | V9: False | W9: False
A10: Four Seasons Hotel Denver | B10: False | C10: Thierry Kennel | E10: (303) 389-3000 | F10: Four Seasons | G10: In House | I10: 65 | J10: luxury | M10: False | N10: False | O10: False | P10: False | Q10: False | R10: False | S10: False | T10: False | U10: False | V10: False | W10: False
A11: The Brown Palace Hotel and Spa, Autograph Collection | B11: False | C11: George Hanna | E11: (303) 297-3111 | I11: 65 | J11: luxury | M11: False | N11: False | O11: False | P11: False | Q11: False | R11: False | S11: False | T11: False | U11: False | V11: False | W11: False
A12: Thompson Denver, by Hyatt | B12: False | C12: Julian Tucker | E12: (303) 572-1321 | I12: 64 | J12: luxury | M12: False | N12: False | O12: False | P12: False | Q12: False | R12: False | S12: False | T12: False | U12: False | V12: False | W12: False
A13: Grand Hyatt Denver | B13: False | C13: Greg Leonard | E13: (303) 295-1234 | H13: 50 | I13: 64 | J13: upper-upscale | M13: False | N13: False | O13: False | P13: False | Q13: False | R13: False | S13: False | T13: False | U13: False | V13: False | W13: False
A14: Hyatt Place Denver/Downtown | B14: False | C14: Kimberly Gagnon | E14: (303) 893-2900 | F14: Towne Park | G14: Towne Park | I14: 64 | J14: upscale | M14: False | N14: False | O14: False | P14: False | Q14: False | R14: False | S14: False | T14: False | U14: False | V14: False | W14: False
A15: Populus | B15: False | C15: George Prine | E15: (303) 800-4240 | I15: 64 | J15: upper-upscale | M15: False | N15: False | O15: False | P15: False | Q15: False | R15: False | S15: False | T15: False | U15: False | V15: False | W15: False
A16: Hilton Denver City Center | B16: False | C16: Mike Case | E16: (303) 297-1300 | I16: 64 | J16: upper-upscale | M16: False | N16: False | O16: False | P16: False | Q16: False | R16: False | S16: False | T16: False | U16: False | V16: False | W16: False
A17: Halcyon, a hotel in Cherry Creek | B17: False | C17: McClinton Heil | E17: (720) 772-5000 | I17: 60 | J17: luxury | M17: False | N17: False | O17: False | P17: False | Q17: False | R17: False | S17: False | T17: False | U17: False | V17: False | W17: False
A18: Hampton Inn & Suites Denver Downtown-Convention Center | B18: False | E18: (303) 623-5900 | F18: Parking Management | I18: 60 | J18: upper-midscale | M18: False | N18: False | O18: False | P18: False | Q18: False | R18: False | S18: False | T18: False | U18: False | V18: False | W18: False
A19: Tru by Hilton Denver Downtown Convention Center | B19: False | C19: Kara van Beek | E19: (303) 753-1201 | I19: 60 | J19: midscale | M19: False | N19: False | O19: False | P19: False | Q19: False | R19: False | S19: False | T19: False | U19: False | V19: False | W19: False
A20: Home2 Suites by Hilton Denver Downtown Convention Center | B20: False | C20: Kara van Beek | E20: (303) 759-1301 | I20: 60 | J20: upper-midscale | M20: False | N20: False | O20: False | P20: False | Q20: False | R20: False | S20: False | T20: False | U20: False | V20: False | W20: False
A21: Homewood Suites by Hilton Denver Downtown-Convention Center | B21: False | E21: (303) 534-7800 | I21: 60 | J21: upper-midscale | M21: False | N21: False | O21: False | P21: False | Q21: False | R21: False | S21: False | T21: False | U21: False | V21: False | W21: False
A22: Hotel Clio, a Luxury Collection Hotel, Denver Cherry Creek | B22: False | C22: Marc Blackford | E22: (303) 316-2700 | G22: Pro Park | I22: 59 | J22: luxury | M22: False | N22: False | O22: False | P22: False | Q22: False | R22: False | S22: False | T22: False | U22: False | V22: False | W22: False
A23: Clayton Hotel & Members Club | B23: False | C23: Alison Mitchell | E23: (303) 551-1600 | I23: 59 | J23: luxury | M23: False | N23: False | O23: False | P23: False | Q23: False | R23: False | S23: False | T23: False | U23: False | V23: False | W23: False
A24: The Slate Hotel Denver Downtown, Tapestry by Hilton | B24: False | C24: Kirby Kiner | E24: (303) 292-5000 | F24: Parkwell | I24: 59 | J24: upscale | M24: False | N24: False | O24: False | P24: False | Q24: False | R24: False | S24: False | T24: False | U24: False | V24: False | W24: False
A25: Kimpton Hotel Monaco Denver | B25: False | C25: Kevin Panzano | E25: (303) 296-1717 | F25: Towne Park | G25: Towne Park | I25: 59 | J25: upper-upscale | M25: False | N25: False | O25: False | P25: False | Q25: False | R25: False | S25: False | T25: False | U25: False | V25: False | W25: False
A26: Magnolia Hotel Denver, a Tribute Portfolio Hotel | B26: False | C26: James Ancona | E26: (303) 607-9000 | F26: Marriott | I26: 59 | J26: upscale | M26: False | N26: False | O26: False | P26: False | Q26: False | R26: False | S26: False | T26: False | U26: False | V26: False | W26: False
A27: Hyatt Centric Downtown Denver | B27: False | C27: Michael Galligan | E27: (303) 529-2340 | I27: 59 | J27: upscale | M27: False | N27: False | O27: False | P27: False | Q27: False | R27: False | S27: False | T27: False | U27: False | V27: False | W27: False
A28: Hotel Indigo Denver Downtown-Union Station | B28: False | C28: Michael Keytel | E28: (303) 623-4422 | F28: Intercontinental | H28: 45 | I28: 55 | J28: upscale | M28: False | N28: False | O28: False | P28: False | Q28: False | R28: False | S28: False | T28: False | U28: False | V28: False | W28: False
A29: Hotel Teatro | B29: False | C29: Courtney Griffith | E29: (888) 727-1200 | F29: LAZ | G29: LAZ | I29: 55 | J29: upper-upscale | M29: False | N29: False | O29: False | P29: False | Q29: False | R29: False | S29: False | T29: False | U29: False | V29: False | W29: False
A30: Kimpton Claret Hotel | B30: False | C30: Keith Siebenaler | E30: (983) 999-0310 | I30: 55 | J30: upper-upscale | M30: False | N30: False | O30: False | P30: False | Q30: False | R30: False | S30: False | T30: False | U30: False | V30: False | W30: False
A31: Apiary Hotel Belleview Station | B31: False | E31: (720) 791-4700 | I31: 55 | J31: upscale | M31: False | N31: False | O31: False | P31: False | Q31: False | R31: False | S31: False | T31: False | U31: False | V31: False | W31: False
A32: The Art Hotel Denver, Curio Collection by Hilton | B32: False | C32: Dorian Phillips | E32: (303) 572-8000 | I32: 54 | J32: upscale | M32: False | N32: False | O32: False | P32: False | Q32: False | R32: False | S32: False | T32: False | U32: False | V32: False | W32: False
A33: The Westin Denver Downtown | B33: False | C33: Jerry Caliguire | E33: (303) 572-9100 | H33: 40 | I33: 54 | J33: upper-upscale | M33: False | N33: False | O33: False | P33: False | Q33: False | R33: False | S33: False | T33: False | U33: False | V33: False | W33: False
A34: The Westin Denver International Airport | B34: False | E34: (303) 317-1800 | F34: Pro Park | G34: Pro Park | H34: 54 | I34: 54 | J34: upper-upscale | M34: False | N34: False | O34: False | P34: False | Q34: False | R34: False | S34: False | T34: False | U34: False | V34: False | W34: False
A35: The Maven Hotel at Dairy Block | B35: False | C35: Jennifer Cottingias | E35: (720) 460-2727 | F35: Sage Hospitality | I35: 53 | J35: upscale | M35: False | N35: False | O35: False | P35: False | Q35: False | R35: False | S35: False | T35: False | U35: False | V35: False | W35: False
A36: Catbird Hotel | B36: False | E36: (720) 990-5555 | H36: 34 | I36: 52 | J36: upscale | M36: False | N36: False | O36: False | P36: False | Q36: False | R36: False | S36: False | T36: False | U36: False | V36: False | W36: False
A37: Limelight Denver | B37: False | C37: Kim Corrigan | E37: (303) 323-0024 | I37: 50 | J37: upscale | M37: False | N37: False | O37: False | P37: False | Q37: False | R37: False | S37: False | T37: False | U37: False | V37: False | W37: False
A38: The Crawford Hotel | B38: False | E38: (720) 460-3700 | I38: 50 | J38: upper-upscale | M38: False | N38: False | O38: False | P38: False | Q38: False | R38: False | S38: False | T38: False | U38: False | V38: False | W38: False
A39: Warwick Denver | B39: False | C39: Chad Hansen | E39: (303) 861-2000 | F39: SP Plus Corporation | G39: SP+ | H39: 50 | I39: 50 | J39: upscale | M39: False | N39: False | O39: False | P39: False | Q39: False | R39: False | S39: False | T39: False | U39: False | V39: False | W39: False
A40: Moxy Denver Cherry Creek | B40: False | C40: Emily Jackson | E40: (720) 707-3247 | I40: 49 | J40: upscale | M40: False | N40: False | O40: False | P40: False | Q40: False | R40: False | S40: False | T40: False | U40: False | V40: False | W40: False
...

Sheet Parking
A1: Location ID | B1: Location Name | C1: Location Type | D1: Address | E1: # Spaces | F1: Unreserved Monthly Rate | G1: Operator | H1: Point of Contact | I1: POC Number | J1: URL | K1: Notes | L1: PARCs Equipment Notes
A2: 1 | B2: Denver Place Garage | C2: Garage | D2: 999 18th St, Denver, CO | E2: 1200 | F2: 235 | G2: ABM Parking
A3: 2 | B3: 16th Street Center Garage | C3: Garage | D3: 16th & Champa St, Denver, CO | E3: 800 | F3: 200 | G3: LAZ Parking
A4: 3 | B4: Tabor Center Garage | C4: Garage | D4: 1200 17th St, Denver, CO | E4: 1500 | F4: 225 | G4: SP+/Metropolis
A5: 4 | B5: Republic Plaza Garage | C5: Underground | D5: 370 17th St, Denver, CO | E5: 900 | F5: 250 | G5: SP+/Metropolis
A6: 5 | B6: Cherry Creek Shopping Center | C6: Garage | D6: 3000 E 1st Ave, Denver, CO | E6: 5700 | G6: Denison Parking | K6: Free for shoppers
A7: 6 | B7: Clayton Lane Garages | C7: Garage | D7: 225 Clayton Ln, Denver, CO | E7: 1200 | F7: 200 | G7: LAZ Parking | K7: Cherry Creek district
A8: 7 | B8: Union Station Block A | C8: Garage | D8: 1660 Wynkoop St, Denver, CO | E8: 500 | F8: 200 | G8: Interstate Parking | K8: LoDo area
A9: 8 | B9: LoDo Towers Garage | C9: Garage | D9: 1755 Wazee St, Denver, CO | E9: 400 | F9: 195 | G9: Interstate Parking | K9: Security robot deployed
A10: 9 | B10: Civic Center Park Garage | C10: Underground | D10: 101 W 14th Ave, Denver, CO | E10: 1100 | F10: 175 | G10: City of Denver
A11: 10 | B11: Convention Center Garage | C11: Garage | D11: 700 14th St, Denver, CO | E11: 2000 | F11: 210 | G11: City of Denver | K11: Adjacent to Colorado Convention Center
A12: 11 | B12: Ball Arena Lots | C12: Surface Lots | D12: 1000 Chopper Cir, Denver, CO | E12: 3000 | G12: LAZ Parking | K12: Event parking $35-$70
A13: 12 | B13: Coors Field Lots | C13: Surface Lots | D13: 2001 Blake St, Denver, CO | E13: 5000 | G13: SP+/Metropolis | K13: Game day parking $18-$35
A14: 13 | B14: Sheraton Denver Garage | C14: Garage | D14: 249 15th St, Denver, CO | E14: 800 | F14: 235 | G14: Propark Mobility | K14: Hotel/public parking
A15: 14 | B15: Hyatt Regency Garage | C15: Garage | D15: 650 15th St, Denver, CO | E15: 1000 | F15: 220 | G15: Propark Mobility | K15: Convention center adjacent
A16: 15 | B16: McGregor Square Garage | C16: Garage | D16: 1901 Wazee St, Denver, CO | E16: 500 | F16: 210 | G16: SP+/Metropolis | K16: Near Coors Field, Rally Hotel
A17: 16 | B17: DIA East Garage | C17: Garage | D17: Peña Blvd, Denver, CO | E17: 12000 | G17: LAZ Parking | K17: $30/day, $210/week
A18: 17 | B18: DIA West Garage | C18: Garage | D18: Peña Blvd, Denver, CO | E18: 12000 | G18: LAZ Parking | K18: $30/day, $210/week
A19: 18 | B19: DIA Economy East | C19: Surface Lot | D19: Peña Blvd, Denver, CO | E19: 8000 | G19: LAZ Parking | K19: $18/day
A20: 19 | B20: DIA Economy West | C20: Surface Lot | D20: Peña Blvd, Denver, CO | E20: 8000 | G20: LAZ Parking | K20: $18/day
A21: 20 | B21: DIA Pikes Peak Shuttle | C21: Surface Lot | D21: Peña Blvd, Denver, CO | E21: 5000 | G21: LAZ Parking | K21: $8/day shuttle

Sheet RevenueForecasting
A1: Account | B1: Account Type | C1: Valet Operator | D1: # of Rooms/Beds | E1: Occupancy Rate | F1: Forecast | G1: Valet Conversion Rate | H1: Estimated Daily Valet Count | I1: Estimated Daily Revenue | J1: Estimated Annual Revenue | K1: Estimate Net Operating Income Annually | L1: Total Daily Rev | M1: Total Annual Rev | N1: Total Annual NOI
A2: Le Méridien Denver Downtown | B2: Hotel | D2: 272 | E2: 0.6 | F2: =D2*E2 | G2: 0.4 | H2: =F2*G2 | I2: =H2*Accounts!J2 | J2: =I2*360 | K2: =J2*0.1 | L2: =SUM(I2:I136) | M2: =SUM(J2:J136) | N2: =SUM(K2:K136)
A3: The Ritz-Carlton, Denver | B3: Hotel | D3: 205 | E3: 0.6 | F3: =D3*E3 | G3: 0.4 | H3: =F3*G3 | I3: =H3*Accounts!J3 | J3: =I3*360 | K3: =J3*0.1
A4: AC Hotel Denver Downtown | B4: Hotel | C4: Towne Park | D4: 223 | E4: 0.6 | F4: =D4*E4 | G4: 0.4 | H4: =F4*G4 | I4: =H4*Accounts!J4 | J4: =I4*360 | K4: =J4*0.1
A5: Embassy Suites by Hilton Denver Downtown Convention Center | B5: Hotel | C5: SP+ | D5: 403 | E5: 0.6 | F5: =D5*E5 | G5: 0.4 | H5: =F5*G5 | I5: =H5*Accounts!J5 | J5: =I5*360 | K5: =J5*0.1
A6: Aloft Denver Downtown | B6: Hotel | C6: LAZ | D6: 140 | E6: 0.6 | F6: =D6*E6 | G6: 0.4 | H6: =F6*G6 | I6: =H6*Accounts!J6 | J6: =I6*360 | K6: =J6*0.1
A7: Sheraton Denver Downtown Hotel | B7: Hotel | D7: 1238 | E7: 0.6 | F7: =D7*E7 | G7: 0.4 | H7: =F7*G7 | I7: =H7*Accounts!J7 | J7: =I7*360 | K7: =J7*0.1
A8: Hyatt Regency Denver at Colorado Convention Center | B8: Hotel | D8: 1100 | E8: 0.6 | F8: =D8*E8 | G8: 0.4 | H8: =F8*G8 | I8: =H8*Accounts!J8 | J8: =I8*360 | K8: =J8*0.1
A9: The Jacquard, Autograph Collection | B9: Hotel | C9: Pro Park | D9: 198 | E9: 0.6 | F9: =D9*E9 | G9: 0.4 | H9: =F9*G9 | I9: =H9*Accounts!J9 | J9: =I9*360 | K9: =J9*0.1
A10: Four Seasons Hotel Denver | B10: Hotel | C10: In House | D10: 239 | E10: 0.6 | F10: =D10*E10 | G10: 0.4 | H10: =F10*G10 | I10: =H10*Accounts!J10 | J10: =I10*360 | K10: =J10*0.1
A11: The Brown Palace Hotel and Spa, Autograph Collection | B11: Hotel | D11: 241 | E11: 0.6 | F11: =D11*E11 | G11: 0.4 | H11: =F11*G11 | I11: =H11*Accounts!J11 | J11: =I11*360 | K11: =J11*0.1
A12: Thompson Denver, by Hyatt | B12: Hotel | D12: 216 | E12: 0.6 | F12: =D12*E12 | G12: 0.4 | H12: =F12*G12 | I12: =H12*Accounts!J12 | J12: =I12*360 | K12: =J12*0.1
A13: Grand Hyatt Denver | B13: Hotel | D13: 516 | E13: 0.6 | F13: =D13*E13 | G13: 0.4 | H13: =F13*G13 | I13: =H13*Accounts!J13 | J13: =I13*360 | K13: =J13*0.1
A14: Hyatt Place Denver/Downtown | B14: Hotel | C14: Towne Park | D14: 248 | E14: 0.6 | F14: =D14*E14 | G14: 0.4 | H14: =F14*G14 | I14: =H14*Accounts!J14 | J14: =I14*360 | K14: =J14*0.1
A15: Populus | B15: Hotel | D15: 265 | E15: 0.6 | F15: =D15*E15 | G15: 0.4 | H15: =F15*G15 | I15: =H15*Accounts!J15 | J15: =I15*360 | K15: =J15*0.1
A16: Hilton Denver City Center | B16: Hotel | D16: 613 | E16: 0.6 | F16: =D16*E16 | G16: 0.4 | H16: =F16*G16 | I16: =H16*Accounts!J16 | J16: =I16*360 | K16: =J16*0.1
A17: Halcyon, a hotel in Cherry Creek | B17: Hotel | D17: 154 | E17: 0.6 | F17: =D17*E17 | G17: 0.4 | H17: =F17*G17 | I17: =H17*Accounts!J17 | J17: =I17*360 | K17: =J17*0.1
A18: Hampton Inn & Suites Denver Downtown-Convention Center | B18: Hotel | D18: 120 | E18: 0.6 | F18: =D18*E18 | G18: 0.4 | H18: =F18*G18 | I18: =H18*Accounts!J18 | J18: =I18*360 | K18: =J18*0.1
A19: Tru by Hilton Denver Downtown Convention Center | B19: Hotel | D19: 176 | E19: 0.6 | F19: =D19*E19 | G19: 0.4 | H19: =F19*G19 | I19: =H19*Accounts!J19 | J19: =I19*360 | K19: =J19*0.1
A20: Home2 Suites by Hilton Denver Downtown Convention Center | B20: Hotel | D20: 206 | E20: 0.6 | F20: =D20*E20 | G20: 0.4 | H20: =F20*G20 | I20: =H20*Accounts!J20 | J20: =I20*360 | K20: =J20*0.1
A21: Homewood Suites by Hilton Denver Downtown-Convention Center | B21: Hotel | D21: 182 | E21: 0.6 | F21: =D21*E21 | G21: 0.4 | H21: =F21*G21 | I21: =H21*Accounts!J21 | J21: =I21*360 | K21: =J21*0.1
A22: Hotel Clio, a Luxury Collection Hotel, Denver Cherry Creek | B22: Hotel | C22: Pro Park | D22: 199 | E22: 0.6 | F22: =D22*E22 | G22: 0.4 | H22: =F22*G22 | I22: =H22*Accounts!J22 | J22: =I22*360 | K22: =J22*0.1
A23: Clayton Hotel & Members Club | B23: Hotel | D23: 63 | E23: 0.6 | F23: =D23*E23 | G23: 0.4 | H23: =F23*G23 | I23: =H23*Accounts!J23 | J23: =I23*360 | K23: =J23*0.1
A24: The Slate Hotel Denver Downtown, Tapestry by Hilton | B24: Hotel | D24: 251 | E24: 0.6 | F24: =D24*E24 | G24: 0.4 | H24: =F24*G24 | I24: =H24*Accounts!J24 | J24: =I24*360 | K24: =J24*0.1
A25: Kimpton Hotel Monaco Denver | B25: Hotel | C25: Towne Park | D25: 189 | E25: 0.6 | F25: =D25*E25 | G25: 0.4 | H25: =F25*G25 | I25: =H25*Accounts!J25 | J25: =I25*360 | K25: =J25*0.1
A26: Magnolia Hotel Denver, a Tribute Portfolio Hotel | B26: Hotel | D26: 297 | E26: 0.6 | F26: =D26*E26 | G26: 0.4 | H26: =F26*G26 | I26: =H26*Accounts!J26 | J26: =I26*360 | K26: =J26*0.1
A27: Hyatt Centric Downtown Denver | B27: Hotel | D27: 264 | E27: 0.6 | F27: =D27*E27 | G27: 0.4 | H27: =F27*G27 | I27: =H27*Accounts!J27 | J27: =I27*360 | K27: =J27*0.1
A28: Hotel Indigo Denver Downtown-Union Station | B28: Hotel | D28: 180 | E28: 0.6 | F28: =D28*E28 | G28: 0.4 | H28: =F28*G28 | I28: =H28*Accounts!J28 | J28: =I28*360 | K28: =J28*0.1
A29: Hotel Teatro | B29: Hotel | C29: LAZ | D29: 111 | E29: 0.6 | F29: =D29*E29 | G29: 0.4 | H29: =F29*G29 | I29: =H29*Accounts!J29 | J29: =I29*360 | K29: =J29*0.1
A30: Kimpton Claret Hotel | B30: Hotel | D30: 190 | E30: 0.6 | F30: =D30*E30 | G30: 0.4 | H30: =F30*G30 | I30: =H30*Accounts!J30 | J30: =I30*360 | K30: =J30*0.1
A31: Apiary Hotel Belleview Station | B31: Hotel | D31: 175 | E31: 0.6 | F31: =D31*E31 | G31: 0.4 | H31: =F31*G31 | I31: =H31*Accounts!J31 | J31: =I31*360 | K31: =J31*0.1
A32: The Art Hotel Denver, Curio Collection by Hilton | B32: Hotel | D32: 165 | E32: 0.6 | F32: =D32*E32 | G32: 0.4 | H32: =F32*G32 | I32: =H32*Accounts!J32 | J32: =I32*360 | K32: =J32*0.1
A33: The Westin Denver Downtown | B33: Hotel | D33: 432 | E33: 0.6 | F33: =D33*E33 | G33: 0.4 | H33: =F33*G33 | I33: =H33*Accounts!J33 | J33: =I33*360 | K33: =J33*0.1
A34: The Westin Denver International Airport | B34: Hotel | C34: Pro Park | D34: 519 | E34: 0.6 | F34: =D34*E34 | G34: 0.4 | H34: =F34*G34 | I34: =H34*Accounts!J34 | J34: =I34*360 | K34: =J34*0.1
A35: The Maven Hotel at Dairy Block | B35: Hotel | D35: 172 | E35: 0.6 | F35: =D35*E35 | G35: 0.4 | H35: =F35*G35 | I35: =H35*Accounts!J35 | J35: =I35*360 | K35: =J35*0.1
A36: Catbird Hotel | B36: Hotel | D36: 165 | E36: 0.6 | F36: =D36*E36 | G36: 0.4 | H36: =F36*G36 | I36: =H36*Accounts!J36 | J36: =I36*360 | K36: =J36*0.1
A37: Limelight Denver | B37: Hotel | D37: 200 | E37: 0.6 | F37: =D37*E37 | G37: 0.4 | H37: =F37*G37 | I37: =H37*Accounts!J37 | J37: =I37*360 | K37: =J37*0.1
A38: The Crawford Hotel | B38: Hotel | D38: 112 | E38: 0.6 | F38: =D38*E38 | G38: 0.4 | H38: =F38*G38 | I38: =H38*Accounts!J38 | J38: =I38*360 | K38: =J38*0.1
A39: Warwick Denver | B39: Hotel | C39: SP+ | D39: 216 | E39: 0.6 | F39: =D39*E39 | G39: 0.4 | H39: =F39*G39 | I39: =H39*Accounts!J39 | J39: =I39*360 | K39: =J39*0.1
A40: Moxy Denver Cherry Creek | B40: Hotel | D40: 140 | E40: 0.6 | F40: =D40*E40 | G40: 0.4 | H40: =F40*G40 | I40: =H40*Accounts!J40 | J40: =I40*360 | K40: =J40*0.1
...

Sheet Analysis
A1: SOPHI's MARKET SCORE | C1: TAM | D1: SAM | E1: SOM | G1: Total | H1: Location | I1: Connections | J1: Garage | K1: Growth | L1: Capacity | M1: Cash Flow | O1: Connection 3 | P1: Volume 2 170 + 2 100 + 1 | Q1: Location Downtown 1 Far -1 | R1: High End | S1: Garage Connection 2 location 1 | T1: Valet & Paid Self Park | U1: Points | V1: Priority
C2: =RevenueForecasting!M2
C3: Sum of all predicted valet revenues | D3: Locations likely to adopt valet/switch providers | E3: SAM / # of SAM locations (1 location landed)
C4: All valet, parking contracts, additional services | D4: Realistically obtainable | E4: Going to get (Year 1 target) | H4: 0 miles | I4: locations? 0/7 | J4: public? 8/8 | K4: Population? 4/4 | L4: personal bandwidth 0/4 | M4: costs
H5: DEN | I5: 1 connection -> 5 2+ connections -> 7 | J5: yes or no | K5: small city, medium city, large city, metropolis
I6: employees? 3 | J6: connection? 2 | K6: Events Space? 4 | L6: hire 0/3
A7: Average Self Park | B7: Average Valet | I7: # of possible employees | J7: yes or no | K7: # of markets
A8: 32.53 | B8: 54.77
A10: DENVER MARKET KEY METRICS
A12: Metro Population | C12: ~2.97 million (2025)
A13: City of Denver Population | C13: ~720,000 (2024)
A14: Annual Visitors | C14: 37.1 million (2024)
A15: Overnight Visitors | C15: 19.8 million (2024)
A16: Visitor Spending | C16: $10.3 billion (2024)
A17: DEN Passengers | C17: 82.4 million (2025 record)
A18: Hotels in Denver | C18: 169 properties
A19: Hotel Rooms | C19: 26,460 rooms
A20: Downtown Hotels | C20: 52 properties, ~12,944 rooms
A21: Downtown Occupancy | C21: 66.8% (2025)
A22: Downtown ADR | C22: $207.74 (2025)
A23: Convention Center Impact | C23: $1B+ economic impact (2025 record)
... A26: Global AVP Market | C26: $793M (2025), 32.7% CAGR to $5.6B by 2034

Sheet Market Notes
A1: Denver, CO Market Notes - 2026
A3: MAJOR PARKING OPERATORS IN DENVER
A4: Operator | B4: Focus | C4: Key Denver Locations | D4: Notes
A5: Propark Mobility | B5: Dominant hotel valet operator | C5: 12+ hotel locations incl. Hyatt Regency, Sheraton, Thompson, Westin DEN | D5: Also operates Canopy Airport Parking (4,500 spaces, LEED Gold)
A6: SP+/Metropolis | B6: Largest national operator (4,000+ locations) | C6: Coors Field lots, Cherry Creek, multiple downtown garages | D6: Merged with REEF Technology in $1.5B acquisition (May 2024)
A7: LAZ Parking | B7: Airport & entertainment venues | C7: DEN Airport (5-year contract Feb 2024), Clayton Lane, Ball Arena | D7: Largest airport parking operation in North America
A8: ABM Parking | B8: Commercial office | C8: Denver Place Garage (999 18th St) | D8: Broad client type coverage
A9: Interstate Parking | B9: Downtown LoDo focus | C9: 6 downtown facilities incl. Union Station Block A | D9: Uses Knightscope security robots
A10: Reimagined Parking (REEF/Impark) | B10: Cherry Creek district | C10: Multiple Cherry Creek North garages | D10: Operates under Impark/Lanier/Republic brands
A11: Denison Parking | B11: Retail/shopping | C11: Cherry Creek Shopping Center (5,700 spaces) | D11: Local operator
A12: Great West Parking | B12: Cherry Creek valet | C12: Cherry Creek commercial properties | D12: Local valet specialist
A13: Pro Park | B13: Hotel valet | C13: Jacquard, Hotel Clio | D13: Boutique hotel focus
A16: PARKING RATE BENCHMARKS - 2026
A17: Downtown Self-Park (Daily) | B17: $10-$35/day (lots $10-$15, garages $23-$35)
A18: Downtown Self-Park (Monthly) | B18: $155-$235 typical unreserved
A19: Hotel Valet (Luxury) | B19: $65-$72/night (Ritz-Carlton $72, Four Seasons $65, Le Méridien $72)
A20: Hotel Valet (Upscale) | B20: $50-$64/night (Thompson $64, Sheraton $67, Hyatt Regency $67)
A21: Hotel Valet (Upper-Midscale) | B21: $39-$49/night (SpringHill $49, Hilton Garden Inn $49)
A22: Cherry Creek Daily | B22: $15-$36/day (M-F max)
A23: Cherry Creek Monthly | B23: $140-$235 unreserved
A24: Event Parking (Ball Arena) | B24: $35-$95 depending on event/lot
A25: Event Parking (Coors Field) | B25: $18-$35
A26: DIA Garage | B26: $30/day, $210/week
A27: DIA Economy | B27: $18/day
A28: DIA Shuttle | B28: $8/day
A29: Rate Trend | B29: Increasing: DIA raised 25% (May 2025); downtown rates up modestly YoY
A32: COMPETITIVE LANDSCAPE & OPPORTUNITY
A33: • No automated valet operators currently in Denver - Sophi Mobility would be first-mover
A34: • Propark Mobility is dominant hotel valet player with 12+ hotel contracts
A35: • PMC Valet (similar to Charlotte) is NOT a major presence in Denver
A36: • Waymo autonomous ride-hail targeting Denver for 2026 launch - creates tech-forward awareness
A37: • Knightscope security robots already deployed in downtown garages (Interstate Parking)
A38: • Global AVP (Automated Valet Parking) market: $793M (2025), growing 32.7% CAGR to $5.6B by 2034
A39: • DEN Airport is 3rd busiest in North America - massive parking revenue opportunity
A40: • Convention center had record $1B+ economic impact in 2025 - strong event-driven demand
A41: • Denver hotel construction pipeline: several new properties opened 2024-2026 (Populus, Kimpton Claret, Apiary)

Sheet TAM_Conservative
A1: Account | B1: Account Type | C1: TAM Class | D1: Rooms/Beds | E1: Seats | F1: Occupancy % | G1: Turnover | H1: Valet Conv % | I1: Valet Rate | J1: Op Days | K1: Peak Mod | L1: Daily Rev | M1: TAM | N1: TAM Status | O1: Notes / Source
A2: Le Méridien Denver Downtown | B2: Hotel | C2: Hotel — Downtown Select-Service | D2: 272 | F2: 0.6 | H2: 0.25 | I2: 72 | J2: 360 | L2: 2937.6 | M2: 1057536 | N2: Active TAM | O2: Auto-class: downtown full-service <300 rooms. Occ 60% flat (refine w/STR).
A3: The Ritz-Carlton, Denver | B3: Hotel | C3: Hotel — Downtown Select-Service | D3: 205 | F3: 0.6 | H3: 0.25 | I3: 72 | J3: 360 | L3: 2214 | M3: 797040 | N3: Active TAM | O3: Auto-class: downtown full-service <300 rooms. Occ 60% flat (refine w/STR).
A4: AC Hotel Denver Downtown | B4: Hotel | C4: Hotel — Downtown Select-Service | D4: 223 | F4: 0.6 | H4: 0.25 | I4: 72 | J4: 360 | L4: 2408.4 | M4: 867024 | N4: Active TAM | O4: Auto-class: downtown + select-service flag [name-inferred downtown; workbook flag=No]. Occ 60% flat (refine w/STR).
A5: Embassy Suites by Hilton Denver Downtown Convention Center | B5: Hotel | C5: Hotel — Downtown+Convention | D5: 403 | F5: 0.6 | H5: 0.4 | I5: 70 | J5: 360 | L5: 6770.4 | M5: 2437344 | N5: Active TAM | O5: Auto-class: convention keyword in name. Occ 60% flat (refine w/STR).
A6: Aloft Denver Downtown | B6: Hotel | C6: Hotel — Downtown Select-Service | D6: 140 | F6: 0.6 | H6: 0.25 | I6: 68 | J6: 360 | L6: 1428 | M6: 514080 | N6: Active TAM | O6: Auto-class: downtown + select-service flag [name-inferred downtown; workbook flag=No]. Occ 60% flat (refine w/STR).
A7: Sheraton Denver Downtown Hotel | B7: Hotel | C7: Hotel — Downtown+Convention | D7: 1238 | F7: 0.6 | H7: 0.4 | I7: 67 | J7: 360 | L7: 19907.04 | M7: 7166534.4 | N7: Active TAM | O7: Auto-class: downtown + 1238 rooms (>=400). Occ 60% flat (refine w/STR).
A8: Hyatt Regency Denver at Colorado Convention Center | B8: Hotel | C8: Hotel — Downtown+Convention | D8: 1100 | F8: 0.6 | H8: 0.4 | I8: 67 | J8: 360 | L8: 17688 | M8: 6367680 | N8: Active TAM | O8: Auto-class: convention keyword in name. Occ 60% flat (refine w/STR).
A9: The Jacquard, Autograph Collection | B9: Hotel | C9: Hotel — Suburban/Airport | D9: 198 | F9: 0.6 | H9: 0.15 | I9: 65 | J9: 360 | L9: 1158.3 | M9: 416988 | N9: Active TAM | O9: Auto-class: not downtown (by flag or name). Occ 60% flat (refine w/STR).
A10: Four Seasons Hotel Denver | B10: Hotel | C10: Hotel — Downtown Select-Service | D10: 239 | F10: 0.6 | H10: 0.25 | I10: 65 | J10: 360 | L10: 2330.25 | M10: 838890 | N10: Active TAM | O10: Auto-class: downtown full-service <300 rooms. Occ 60% flat (refine w/STR).
A11: The Brown Palace Hotel and Spa, Autograph Collection | B11: Hotel | C11: Hotel — Resort | D11: 241 | F11: 0.6 | H11: 0.5 | I11: 65 | J11: 360 | L11: 4699.5 | M11: 1691820 | N11: Active TAM | O11: Auto-class: resort keyword: 'spa'. Occ 60% flat (refine w/STR).
A12: Thompson Denver, by Hyatt | B12: Hotel | C12: Hotel — Downtown Select-Service | D12: 216 | F12: 0.6 | H12: 0.25 | I12: 64 | J12: 360 | L12: 2073.6 | M12: 746496 | N12: Active TAM | O12: Auto-class: downtown full-service <300 rooms. Occ 60% flat (refine w/STR).
A13: Grand Hyatt Denver | B13: Hotel | C13: Hotel — Downtown+Convention | D13: 516 | F13: 0.6 | H13: 0.4 | I13: 64 | J13: 360 | L13: 7925.76 | M13: 2853273.6 | N13: Active TAM | O13: Auto-class: downtown + 516 rooms (>=400). Occ 60% flat (refine w/STR).
... A53: Renaissance Denver Hotel & Conference Center | B53: Hotel | C53: Hotel — Suburban/Airport | D53: 399 | F53: 0.6 | H53: 0.15 | I53: 19 | J53: 360 | L53: 682.29 | M53: 245624.4 | N53: Active TAM | O53: Auto-class: not downtown (by flag or name). Occ 60% flat (refine w/STR).
A54: DoubleTree by Hilton Hotel Denver | B54: Hotel | C54: Hotel — Suburban/Airport | D54: 561 | F54: 0.6 | H54: 0.15 | J54: 360 | N54: No Valet / TAM = $0 | O54: Hotel has no valet (rate field: 'No Valet'). Auto-class: not downtown (by flag or name). Qualitative pipeline only.
A55: Courtyard Denver Central Park | B55: Hotel | C55: Hotel — Suburban/Airport | D55: 146 | F55: 0.6 | H55: 0.15 | J55: 360 | N55: No Valet / TAM = $0 | O55: Hotel has no valet (rate field: 'No Valet'). Auto-class: not downtown (by flag or name). Qualitative pipeline only.
A56: Hampton Inn & Suites Denver-Speer Boulevard | B56: Hotel | C56: Hotel — Suburban/Airport | D56: 153 | F56: 0.6 | H56: 0.15 | J56: 360 | N56: No Valet / TAM = $0 | O56: Hotel has no valet (rate field: 'No Valet'). Auto-class: not downtown (by flag or name). Qualitative pipeline only.
A57: Drury Inn & Suites Denver Central Park | B57: Hotel | C57: Hotel — Suburban/Airport | D57: 209 | F57: 0.6 | H57: 0.15 | J57: 360 | N57: No Valet / TAM = $0 | O57: Hotel has no valet (rate field: 'No Valet'). Auto-class: not downtown (by flag or name). Qualitative pipeline only.
A58: Cambria Hotel Denver Downtown RiNo | B58: Hotel | C58: Hotel — Downtown Select-Service | D58: 153 | F58: 0.6 | H58: 0.25 | J58: 360 | N58: No Valet / TAM = $0 | O58: Hotel has no valet (rate field: 'No Valet'). Auto-class: downtown full-service <300 rooms [name-inferred downtown]. Qualitative pipeline only.
A59: The Source Hotel | B59: Hotel | C59: Hotel — Suburban/Airport | D59: 100 | F59: 0.6 | H59: 0.15 | J59: 360 | N59: No Valet / TAM = $0 | O59: Hotel has no valet (rate field: 'No Valet'). Auto-class: not downtown (by flag or name). Qualitative pipeline only.
A60: the Curtis Denver - a DoubleTree by Hilton Hotel | B60: Hotel | C60: Hotel — Downtown+Convention | D60: 336 | F60: 0.6 | H60: 0.4 | J60: 360 | N60: No Valet / TAM = $0 | O60: Hotel has no valet (rate field: 'No Valet'). Auto-class: downtown + 336 rooms. Qualitative pipeline only.
A61: Courtyard Denver Downtown | B61: Hotel | C61: Hotel — Downtown Select-Service | D61: 177 | F61: 0.6 | H61: 0.25 | J61: 360 | N61: No Valet / TAM = $0 | O61: Hotel has no valet (rate field: 'No Valet'). Auto-class: downtown + select-service flag [name-inferred downtown; workbook flag=No]. Qualitative pipeline only.
A62: Hyatt Regency Aurora-Denver Conference Center | B62: Hotel | C62: Hotel — Suburban/Airport | D62: 249 | F62: 0.6 | H62: 0.15 | J62: 360 | N62: No Valet / TAM = $0 | O62: Hotel has no valet (rate field: 0). Auto-class: not downtown (by flag or name). Qualitative pipeline only.
A63: Sonesta Denver Downtown | B63: Hotel | C63: Hotel — Downtown+Convention | D63: 380 | F63: 0.6 | H63: 0.4 | J63: 360 | N63: No Valet / TAM = $0 | O63: Hotel has no valet (rate field: 'No Valet'). Auto-class: downtown + 380 rooms. Qualitative pipeline only.
A64: Vīb Hotel by Best Western Denver RiNo | B64: Hotel | C64: Hotel — Downtown Select-Service | D64: 140 | F64: 0.6 | H64: 0.25 | J64: 360 | N64: No Valet / TAM = $0 | O64: Hotel has no valet (rate field: 'No Valet'). Auto-class: downtown + select-service flag [name-inferred downtown; workbook flag=No]. Qualitative pipeline only.
A65: Element Denver Downtown East | B65: Hotel | C65: Hotel — Downtown Select-Service | D65: 157 | F65: 0.6 | H65: 0.25 | J65: 360 | N65: No Valet / TAM = $0 | O65: Hotel has no valet (rate field: 'No Valet'). Auto-class: downtown + select-service flag [name-inferred downtown; workbook flag=No]. Qualitative pipeline only.
... A87: Home2 Suites by Hilton Denver Central Park | B87: Hotel | C87: Hotel — Suburban/Airport | D87: 117 | F87: 0.6 | H87: 0.15 | J87: 360 | N87: No Valet / TAM = $0 | O87: Hotel has no valet (rate field: 'No Valet'). Auto-class: not downtown (by flag or name). Qualitative pipeline only.
A88: The Capital Grille - Denver | B88: Restaurant | C88: Restaurant — Excluded | N88: EXCLUDED — no active valet / not eligible | O88: Not in eligible FD universe (steakhouse/fine dining with active independent valet)
A89: Ocean Prime - Denver (Larimer Square) | B89: Restaurant | C89: Restaurant — Seafood Steakhouse | E89: 225 | G89: 1.5 | H89: 0.125 | J89: 250 | K89: 1.08 | L89: 843.75 | M89: 227812.5 | N89: Active TAM (MEDIUM confidence) | O89: Ocean Prime brand-standard 200-250; 234 private dining seats across rooms confirmed. | [Ocean Prime](https://ocean-prime.com/locations-menus/denver-larimer-square/), [EventUp](https://eventup.com/venue/ocean-prime-larimer-square/)
A90: Ruth's Chris Steak House - Denver | B90: Restaurant | C90: Restaurant — Steakhouse | E90: 275 | G90: 1.5 | H90: 0.125 | J90: 250 | K90: 1.08 | L90: 1031.25 | M90: 278437.5 | N90: Active TAM (MEDIUM confidence) | O90: Brand-standard Ruth's Chris 250-300. Address note: 1445 Market closed 2009, current location 707 15th St. | [Brand standard benchmark; PRNewswire](https://www.prnewswire.com/news-releases/denver-welcomes-ruths-chris-steak-house-to-the-mile-high-city-242296641.html)
A91: STK Steakhouse Denver | B91: Restaurant | C91: Restaurant — Excluded | N91: EXCLUDED — no active valet / not eligible | O91: Not in eligible FD universe (steakhouse/fine dining with active independent valet)
A92: Guard & Grace | B92: Restaurant | C92: Restaurant — Excluded | N92: EXCLUDED — no active valet / not eligible | O92: Not in eligible FD universe (steakhouse/fine dining with active independent valet)
A93: Elway's Downtown | B93: Restaurant | C93: Restaurant — Excluded | N93: EXCLUDED — no active valet / not eligible | O93: Not in eligible FD universe (steakhouse/fine dining with active independent valet)
A94: Elway's Cherry Creek | B94: Restaurant | C94: Restaurant — Excluded | N94: EXCLUDED — no active valet / not eligible | O94: Not in eligible FD universe (steakhouse/fine dining with active independent valet)
A95: Shanahan's Steakhouse | B95: Restaurant | C95: Restaurant — Steakhouse | E95: 200 | G95: 1.5 | H95: 0.125 | J95: 250 | K95: 1.08 | L95: 750 | M95: 202500 | N95: Active TAM (LOW confidence) | O95: No published dining-room count. 200 seats is steakhouse default; private dining 72 confirmed. | [Shanahan's private dining](https://www.shanahanssteakhouse.com/private-dining)
A96: Del Frisco's Double Eagle Steakhouse | B96: Restaurant | C96: Restaurant — Steakhouse | E96: 450 | G96: 1.5 | H96: 0.125 | J96: 250 | K96: 1.08 | L96: 1687.5 | M96: 455625 | N96: Active TAM (HIGH confidence) | O96: Published 450 seats post-2018 renovation. Largest of the 7. | [303 Magazine](https://303magazine.com/2018/11/del-friscos-double-eagle-steak-house-new-menu/)
A97: Del Frisco's Grille - Cherry Creek | B97: Restaurant | C97: Restaurant — Excluded | N97: EXCLUDED — no active valet / not eligible | O97: Not in eligible FD universe (steakhouse/fine dining with active independent valet)
A98: Tavernetta | B98: Restaurant | C98: Restaurant — Excluded | N98: EXCLUDED — no active valet / not eligible | O98: Not in eligible FD universe (steakhouse/fine dining with active independent valet)
A99: Sunday Vinyl | B99: Restaurant | C99: Restaurant — Excluded | N99: EXCLUDED — no active valet / not eligible | O99: Not in eligible FD universe (steakhouse/fine dining with active independent valet)
A100: Frasca Food and Wine | B100: Restaurant | C100: Restaurant — Excluded | N100: EXCLUDED — no active valet / not eligible | O100: Not in eligible FD universe (steakhouse/fine dining with active independent valet)
...

Sheet TAM_Summary
A1: Denver — Conservative TAM Summary
A3: Account Type | B3: # Accounts | C3: TAM | D3: Status
A4: Hotel | B4: 86 | C4: 57469500 | D4: Active TAM
A5: Restaurant | B5: 7 | C5: 1817437.5 | D5: Active TAM
A6: Hospital | B6: 12 | C6: 0 | D6: Qualitative pipeline only
A7: Event Venue | B7: 14 | C7: 0 | D7: Qualitative pipeline only
A8: Airport | B8: 1 | C8: 0 | D8: Qualitative pipeline only
A9: TOTAL | B9: 120 | C9: 59286937
A11: HOTEL BREAKDOWN BY CLASS
A12: Class | B12: # Hotels | C12: Conv %
A13: Downtown+Convention | B13: 13 | C13: 0.4
A14: Downtown Select-Service | B14: 32 | C14: 0.25
A15: Resort | B15: 3 | C15: 0.5
A16: Suburban/Airport | B16: 38 | C16: 0.15
A18: RESTAURANTS WITH ACTIVE TAM
A19: Restaurant | B19: Seats | C19: TAM
A20: Del Frisco's Double Eagle Steakhouse | B20: 450 | C20: 455625
A21: Water Grill Denver | B21: 346 | C21: 350325
A22: Ruth's Chris Steak House - Denver | B22: 275 | C22: 278437.5
A23: Ocean Prime - Denver (Larimer Square) | B23: 225 | C23: 227812.5
A24: Le Colonial Denver | B24: 220 | C24: 222750
A25: Shanahan's Steakhouse | B25: 200 | C25: 202500
A26: Mizuna | B26: 79 | C26: 79987.5

Sheet TAM_Methodology
A1: SOPHI CONSERVATIVE TAM METHODOLOGY
A3: Replaces original RevenueForecasting formulas. Hospitals / Venues / Airports now qualitative only.
A5: HOTEL FORMULA
A6: TAM = Rooms × Occupancy × Valet Conversion (tiered) × Valet Rate × 360 days
A7: Occupancy: 60% flat across all hotels
A8: ⚠️ FLAG: Refine with STR actuals per-submarket before finalizing fundraise model
A9: Valet Conversion by archetype (auto-classified — review recommended):
A10: Downtown+Convention: 40%
A11: Downtown Select-Service: 25%
A12: Resort: 50%
A13: Suburban/Airport: 15%
A14: Operating Days: 360 (captures soft-closures / transition days)
... A35: 4. Hospital/venue/airport TAM dropped to $0 → build IU Health-benchmarked KPI proxy

Sheet WAS_Scoring_v2
A1: Account | B1: Type | C1: Downtown | D1: Rooms | E1: Valet Op (incumbent) | F1: Valet Rate | G1: Est. Annual Rev (TAM) | H1: Fit (25%) | I1: Size (25%) | J1: Owner Base (20%) | K1: Addr (15%) | L1: Adj (15%) | M1: Rel Lift | N1: Rel Tag | O1: WAS Raw | P1: WAS Final | Q1: Tier | R1: Y1 % | S1: Y2 % | T1: Y3 % | U1: Y4 % | V1: Y5 % | W1: Y1 Rev | X1: Y2 Rev | Y1: Y3 Rev | Z1: Y4 Rev | AA1: Y5 Rev
A2: Le Méridien Denver Downtown | B2: Hotel | C2: YES | D2: 272 | F2: 72 | G2: 1057536 | H2: 4 | I2: 3 | J2: 2 | K2: 4 | L2: 4 | M2: 0 | O2: 3.35 | P2: 3.35 | Q2: C — Opportunistic | R2: 0.02 | S2: 0.09724 | T2: 0.28625 | U2: 0.4145 | V2: 0.5 | W2: 21150.72 | X2: 102834.8 | Y2: 302719.68 | Z2: 438348.67 | AA2: 528768
A3: The Ritz-Carlton, Denver | B3: Hotel | C3: YES | D3: 205 | F3: 72 | G3: 797040 | H3: 4 | I3: 3 | J3: 3 | K3: 4 | L3: 4 | M3: 0 | O3: 3.55 | P3: 3.55 | Q3: B — Core | R3: 0.08 | S3: 0.22066 | T3: 0.560625 | U3: 0.78675 | V3: 0.9375 | W3: 63763.2 | X3: 175874.85 | Y3: 446840.55 | Z3: 627071.22 | AA3: 747225
A4: AC Hotel Denver Downtown | B4: Hotel | C4: NO | D4: 223 | E4: Towne Park | F4: 72 | G4: 867024 | H4: 3 | I4: 3 | J4: 2 | K4: 2 | L4: 2 | M4: 0 | O4: 2.5 | P4: 2.5 | Q4: C — Opportunistic | R4: 0.02 | S4: 0.09724 | T4: 0.28625 | U4: 0.4145 | V4: 0.5 | W4: 17340.48 | X4: 84309.414 | Y4: 248185.62 | Z4: 359381.45 | AA4: 433512
A5: Embassy Suites by Hilton Denver Downtown Convention Center | B5: Hotel | C5: NO | D5: 403 | E5: SP+ | F5: 70 | G5: 2437344 | H5: 4 | I5: 4 | J5: 3 | K5: 2 | L5: 2 | M5: 0.15 | N5: Brand familiarity (historical): Hilton_family | O5: 3.2 | P5: 3.35 | Q5: C — Opportunistic | R5: 0.02 | S5: 0.09724 | T5: 0.28625 | U5: 0.4145 | V5: 0.5 | W5: 48746.88 | X5: 237007.33 | Y5: 697689.72 | Z5: 1010279.1 | AA5: 1218672
A6: Aloft Denver Downtown | B6: Hotel | C6: NO | D6: 140 | E6: LAZ | F6: 68 | G6: 514080 | H6: 3 | I6: 2 | J6: 2 | K6: 2 | L6: 2 | M6: 0.3 | N6: Brand familiarity (current): Marriott_family | O6: 2.25 | P6: 2.55 | Q6: C — Opportunistic | R6: 0.02 | S6: 0.09724 | T6: 0.28625 | U6: 0.4145 | V6: 0.5 | W6: 10281.6 | X6: 49989.139 | Y6: 147155.4 | Z6: 213086.16 | AA6: 257040
A7: Sheraton Denver Downtown Hotel | B7: Hotel | C7: YES | D7: 1238 | F7: 67 | G7: 7166534.4 | H7: 5 | I7: 5 | J7: 3 | K7: 4 | L7: 4 | M7: 0.3 | N7: Brand familiarity (current): Marriott_family | O7: 4.3 | P7: 4.6 | Q7: A — Beachhead | R7: 0.4 | S7: 0.499 | T7: 0.7025 | U7: 0.851 | V7: 0.95 | W7: 2866613.8 | X7: 3576100.7 | Y7: 5034490.4 | Z7: 6098720.8 | AA7: 6808207.7
A8: Hyatt Regency Denver at Colorado Convention Center | B8: Hotel | C8: NO | D8: 1100 | F8: 67 | G8: 6367680 | H8: 5 | I8: 5 | J8: 3 | K8: 4 | L8: 2 | M8: 0 | O8: 4 | P8: 4 | Q8: B — Core | R8: 0.08 | S8: 0.22066 | T8: 0.560625 | U8: 0.78675 | V8: 0.9375 | W8: 509414.4 | X8: 1405092.3 | Y8: 3569880.6 | Z8: 5009772.2 | AA8: 5969700
A9: The Jacquard, Autograph Collection | B9: Hotel | C9: NO | D9: 198 | E9: Pro Park | F9: 65 | G9: 416988 | H9: 3 | I9: 2 | J9: 3 | K9: 3 | L9: 2 | M9: 0.3 | N9: Brand familiarity (current): Marriott_family | O9: 2.6 | P9: 2.9 | Q9: C — Opportunistic | R9: 0.02 | S9: 0.09724 | T9: 0.28625 | U9: 0.4145 | V9: 0.5 | W9: 8339.76 | X9: 40547.913 | Y9: 119362.82 | Z9: 172841.53 | AA9: 208494
A10: Four Seasons Hotel Denver | B10: Hotel | C10: YES | D10: 239 | E10: In House | F10: 65 | G10: 838890 | H10: 4 | I10: 3 | J10: 3 | K10: 5 | L10: 4 | M10: 0 | O10: 3.7 | P10: 3.7 | Q10: B — Core | R10: 0.08 | S10: 0.22066 | T10: 0.560625 | U10: 0.78675 | V10: 0.9375 | W10: 67111.2 | X10: 185109.47 | Y10: 470302.71 | Z10: 659996.71 | AA10: 786459.38
A11: The Brown Palace Hotel and Spa, Autograph Collection | B11: Hotel | C11: YES | D11: 241 | F11: 65 | G11: 1691820 | H11: 4 | I11: 4 | J11: 3 | K11: 4 | L11: 4 | M11: 0.3 | N11: Brand familiarity (current): Marriott_family | O11: 3.8 | P11: 4.1 | Q11: B — Core | R11: 0.08 | S11: 0.22066 | T11: 0.560625 | U11: 0.78675 | V11: 0.9375 | W11: 135345.6 | X11: 373317 | Y11: 948476.59 | Z11: 1331039.4 | AA11: 1586081.2
A12: Thompson Denver, by Hyatt | B12: Hotel | C12: YES | D12: 216 | F12: 64 | G12: 746496 | H12: 4 | I12: 2 | J12: 3 | K12: 4 | L12: 4 | M12: 0 | O12: 3.3 | P12: 3.3 | Q12: C — Opportunistic | R12: 0.02 | S12: 0.09724 | T12: 0.28625 | U12: 0.4145 | V12: 0.5 | W12: 14929.92 | X12: 72589.271 | Y12: 213684.48 | Z12: 309422.59 | AA12: 373248
