Workbook

Sheet Accounts
A1: =IFERROR(__xludf.DUMMYFUNCTION("if(eq(COUNTA(A2:A388) - COUNTUNIQUE(A2:A388),0),""Accounts"", CONCAT(""Accounts - Duplicate Found "",(COUNTA(A2:A388) - COUNTUNIQUE(A2:A388))))"),"Accounts") | B1: Account Type | C1: Active | D1: =IFERROR(__xludf.DUMMYFUNCTION("if(eq(COUNTA(D2:D388) - COUNTUNIQUE(D2:D388),0),""Address"", CONCAT(""Duplicate Found: "", (COUNTA(D2:D388) - COUNTUNIQUE(D2:D388))))"),"Duplicate Found: 6") | E1: Area | F1: Phone Number | G1: URL | H1: Self Parking Rate | I1: Valet Rate | J1: Room Count | K1: Parking Reviews | L1: Parking Reviews | M1: Management Group | N1: Linked Accounts | O1: Garage Operator | P1: Valet Operator | Q1: Location Notes | R1: POC | S1: Active Communications | T1: POC Name | U1: POC Role | V1: Email | W1: POC Phone Number | X1: Contact Preferences | Y1: Sales | Z1: Sales Notes Summary | AA1: 1. Linked In | AB1: 2. Cold Call | AC1: 3. In person visit | AD1: 4. First Email | AE1: 5. Cold Call | AF1: 6. Second follow up email | AG1: 7. Cold Call | AH1: 8. 2nd in person visit | AI1: 9. Cold Call or voicemail | AJ1: 10. Owner email | AK1: 11. 3rd email temp check | AM1: Notes | AN1: Sourcing Notes | AO1: a | AP1: b
A2: Kenect Phoenix | B2: Apartment | D2: 355 N Central Ave, Phoenix, AZ 85004 | E2: Downtown | F2: =16022582828 | G2: https://www.kenectphoenix.com/?utm_source=GBP&utm_medium=organic | I2: No Valet
A3: Sentral Sol Modern | B3: Apartment/Hotel | D3: 50 E Fillmore St, Phoenix, AZ 85004 | E3: Downtown | F3: =18449621670 | G3: https://sentral.com/phoenix/sol-modern/stay?utm_source=google&utm_medium=GMB-Website-Link&utm_campaign=GMB&utm_content=Sentral-Sol-Modern | H3: Included | I3: No Valet
A4: Sentral Alloy Midtown | B4: Apartment/Hotel | D4: 3010 N 2nd St, Phoenix, AZ 85012 | E4: Midtown | F4: (833) 584-1129 | G4: https://sentral.com/phoenix/alloy-midtown/stay?utm_source=google&utm_medium=gpm&utm_campaign=gpm&utm_content=phoenix-alloy-midtown | I4: No Valet
A5: Chateau Luxe Event Venue | B5: Event | C5: x | D5: 1175 E Lone Cactus Dr, Phoenix, AZ 85024 | E5: Cave Creek | F5: =16232668747 | S5: KA | T5: Ben COO | V5: info@chateauluxeaz.com | W5: Britanny
A6: Warehouse215 | B6: Event | D6: 215 E Grant St, Phoenix, AZ 85004 | E6: Downtown | G6: https://www.warehouse215.com/ | R6: Darnell- Events Manager | S6: KA | T6: Kathye Allen | U6: Executive Assitant | V6: Kathye.allen@warehouse215.com | Z6: Spoke with Kathye, they use their own service but also allow clients to bring in their own, going to send off information and she will share with Darnell who runs points on events
A7: 435 Collective | B7: Event | D7: 435 S 3rd Ave, Phoenix, AZ 85003 | E7: Downtown | F7: =14802668440 | G7: http://435collective.com/ | S7: KA | T7: Emily Bond | U7: Think owner? | V7: Ebond@arena.com
A8: The Boho Space | B8: Event | D8: 3201 N 16th St Suite 16, Phoenix, AZ 85016 | E8: Midtown | F8: =16234285577
A9: The Teapot | B9: Event | E9: Scottsdale | S9: KA | V9: no email provided, left inquiry on their website | Z9: Sent email inquiry
A10: monOrchid | B10: Event | D10: 214 E Roosevelt St, Phoenix, AZ 85004 | E10: Downtown | F10: =16024923235 | G10: https://monorchid.com/ | S10: KA | V10: event@monorchidphx.com | Z10: Sent email inquiry
A11: The Dauz Venue | B11: Event | D11: 750 W Polk St, Phoenix, AZ 85007 | E11: Downtown | F11: =16022570750 | G11: http://thedauz.com/ | S11: KA | V11: deedee@thedauz.com
A12: Antigua Garden | B12: Event | D12: 2645 N 16th St, Phoenix, AZ 85006 | E12: Downtown | F12: =16027590042 | G12: https://antiguagarden.com/ | W12: 602-759-0042
A13: The Icehouse | B13: Event | D13: 429 W Jackson St, Phoenix, AZ 85003 | E13: Downtown | F13: =14804286028 | G13: https://openvenues.com/venue/the-icehouse/ | V13: concierge@openvenues.com
A14: Encanto 18 | B14: Event | D14: 2775 N 15th Ave, Phoenix, AZ 85007 | E14: Downtown | F14: =16025344653 | U14: Event manager | V14: Michael.swartz@phoenix.gov | Y14: Owned by the city
A15: The Duce | B15: Event | D15: 525 S Central Ave, Phoenix, AZ 85004, USA | E15: Downtown
A16: Wedgewood Weddings | B16: Event | D16: 1742 N Lindsay Rd, Mesa, AZ 85213, USA | E16: Mesa | F16: 9805532210 | G16: https://www.wedgewoodweddings.com/lindsaygrove?matchtype=e&device=c&utm_source=google&utm_medium=cpc&utm_campaign={name}&utm_term=lindsay%20grove%20by%20wedgewood%20weddings&hsa_cam=11618124935&hsa_ad=774357435985&hsa_acc=1860597723&hsa_mt=e&hsa_net=adwords&hsa_ver=3&hsa_src=g&hsa_tgt=kwd-893510079835&hsa_grp=113660654112&hsa_kw=lindsay%20grove%20by%20wedgewood%20weddings&gad_source=1&gad_campaignid=11618124935&gbraid=0AAAAAD4sybBqp77uJaz5cPxSvqfv0aDIC&gclid=Cj0KCQiA6Y7KBhCkARIsAOxhqtMBkVtwqAaX4TF7kDJJWFt7CSWobTib9e3EcxKY0cwd2C9c87tjmdkaAgqAEALw_wcB | S16: KA | V16: events@wedgewoodweddings.com | Z16: Tons of locations across the country. Some in Charlotte and in Phoenix
A17: The Legacy Ballroom | B17: Event | D17: 4530 E Gold Dust Ave, Phoenix, AZ 85028 | R17: Sam | T17: info@thelegacyballroom.com
A18: TPC Scottsdale | B18: Golf | D18: 17020 Hayden Rd, Scottsdale, AZ 85255 | E18: North Scottsdale | F18: =14805854334 | G18: http://tpc.com/scottsdale | U18: Generic Email | V18: contactscottsdale@pgatourhq.com | Z18: Talked with Andrew on sales side, they have a vendor they are happy with at the moment | AA18: x
A19: Raven Golf Club | B19: Golf | D19: 3636 E Baseline Rd, Phoenix, AZ 85042 | E19: South Mountain | F19: =16022433636 | G19: https://www.ravenphx.com/ | S19: BT | T19: Chelsea- Event Manager, Matthew- GM | U19: Events and GM | V19: Cnavarrette@arcisgolf.com, Mphillips@arcisgolf.com | Z19: transfered to a sales member and he didnt know who to give my information to. He said he would ask around for me. He was excited to talk when i mentioned we have worked for qual hallow before
A20: Papago Golf Club | B20: Golf | D20: 5595 E Karsten Wy, Phoenix, AZ 85008 | E20: Tempe | F20: =16022758428 | G20: https://www.papagogolfclub.com/?utm_source=extnet&utm_medium=yext | U20: Kellil Meirick | V20: kmeirick@golfpapago.com
A21: Reliance Hospitality | B21: Hospitality Group | T21: Jason Moore VP of ops & Marcy Westrom CEO
A22: Integrity Lodging | B22: Hospitality Group | AA22: requested connecting
A23: Riot Hospitality Group | B23: Hospitality Group
A24: Heavlin Management Company (HMC) | B24: Hospitality Group
A25: Aligned Hospitality Management | B25: Hospitality Group
A26: Aimbridge Hospitality | B26: Hospitality Group
A27: Crescent Hotels & Resorts | B27: Hospitality Group
A28: Southwest Hospitality Management | B28: Hospitality Group
A29: Desert Hospitality Management | B29: Hospitality Group
A30: NCG Hospitality | B30: Hospitality Group
A31: Classic Hotels & Resorts | B31: Hospitality Group
A32: Carter Concepts Restaurant Group | B32: Hospitality Group
A33: Courtyard Phoenix Airport | B33: Hotel | D33: 2621 S 47th St, Phoenix, AZ 85034 | E33: Airport | F33: =14809664300 | G33: https://www.marriott.com/en-us/hotels/phxca-courtyard-phoenix-airport/overview/?scid=f2ae0541-1279-4f24-b197-a979c79310b0 | H33: 15 | I33: No Valet | J33: 145 | K33: 0.56 | L33: 18 | T33: Charles Padilla | U33: GM
A34: Hilton Phoenix Airport | B34: Hotel | D34: 2435 S 47th St, Phoenix, AZ 85034 | E34: Airport | F34: =14808941600 | G34: https://www.hilton.com/en/hotels/phxahhf-hilton-phoenix-airport/?SEO_id=GMB-AMER-HH-PHXAHHF&y_source=1_MTIyMDg0Ni03MTUtbG9jYXRpb24ud2Vic2l0ZQ%3D%3D | H34: 10 | I34: No Valet | J34: 259 | K34: 0.53 | L34: 51
A35: Marriott Phoenix Airport | B35: Hotel | D35: 1101 N 44th St, Phoenix, AZ 85008 | E35: Airport | F35: =16022737373 | G35: https://www.marriott.com/en-us/hotels/phxap-marriott-phoenix-airport/overview/?scid=f2ae0541-1279-4f24-b197-a979c79310b0 | H35: 10 | I35: No Valet | J35: 347 | K35: 0.65 | L35: 46
A36: Arizona Biltmore, LXR Hotels & Resorts | B36: Hotel | D36: 2400 E Missouri Ave, Phoenix, AZ 85016 | E36: Biltmore | F36: (602) 955-6600 | G36: https://www.hilton.com/en/hotels/phxbmol-arizona-biltmore/rooms/ | I36: valet only | J36: 750 | K36: 0.35 | L36: 156 | T36: Jessica Carlson | U36: Resort Manager
A37: Embassy Suites by Hilton Phoenix Biltmore | B37: Hotel | C37: x | D37: 2630 E Camelback Rd, Phoenix, AZ 85016 | E37: Blitmore | F37: =16029553992 | G37: https://www.hilton.com/en/hotels/phxcbes-embassy-suites-phoenix-biltmore/?SEO_id=GMB-AMER-ES-PHXCBES&y_source=1_MTExMDAzNC03MTUtbG9jYXRpb24ud2Vic2l0ZQ%3D%3D | H37: 14 | I37: No Valet | J37: 232 | K37: 0.2 | L37: 51 | T37: Vinnie Walia | U37: GM | V37: phxcb_embassy@hilton.com | Z37: called and talked to blake at front desk, said to call back monday for operations manager
A38: Hampton Inn Phoenix-Biltmore | B38: Hotel | D38: 2310 E Highland Ave, Phoenix, AZ 85016 | E38: Blitmore | F38: =16029565221 | G38: https://www.hilton.com/en/hotels/phxehhx-hampton-phoenix-biltmore/?SEO_id=GMB-AMER-HX-PHXEHHX&y_source=1_MjA4MzE5Ny03MTUtbG9jYXRpb24ud2Vic2l0ZQ%3D%3D | J38: 121 | K38: 0.42 | L38: 33
A39: The Camby, Autograph Collection | B39: Hotel | D39: 2401 E Camelback Rd, Phoenix, AZ 85016 | E39: Blitmore | F39: =16024680700 | G39: https://www.marriott.com/en-us/hotels/phxak-the-camby-autograph-collection/overview/?scid=f2ae0541-1279-4f24-b197-a979c79310b0 | I39: 40 | J39: 279 | K39: 0.45 | L39: 95 | T39: Christine Menzel | U39: GM | V39: Cmenzel@thecamby.com
A40: AC Hotel Phoenix Biltmore | B40: Hotel | D40: 2811 E Camelback Rd, Phoenix, AZ 85016 | E40: Blitmore | F40: =16028526500 | G40: https://www.marriott.com/en-us/hotels/phxab-ac-hotel-phoenix-biltmore/overview/?scid=f2ae0541-1279-4f24-b197-a979c79310b0 | H40: 12 | I40: No Valet | J40: 160 | K40: 0.68 | L40: 19 | T40: April Mosley | U40: GM | Z40: linked in message
...

Sheet Analysis
A1: SOPHI's MARKET SCORE | B1: =G2 | C1: TAM | D1: SAM | E1: SOM | G1: Total | H1: Location | I1: Connections | J1: Garage | K1: Growth | L1: capacity | M1: cash flow | O1: Connection 3 | P1: Volume 2 170 + 2 100 + 1 | Q1: Location Downtown 1 Far -1 | R1: High End | S1: Garage Connection 2 location 1 | T1: Valet & Paid Self Park | U1: Points | V1: Priority
C2: =SUM(RevenueForecasting!H:H) | D2: =SUMIF(#REF!,1,RevenueForecasting!H2:H36) | E2: =D2/SUM(#REF!) | G2: =SUM(H2:L2)*2 & " /100" | H2: 7 | I2: 0 | J2: 8 | K2: 7
C3: sum of predicted revenues | D3: Guess of locations that I could see being interested in introducing valet | E3: SAM / # of locations in SAM. Representing 1 Hotel landed
C4: all valet, all parking contracts, additional services, bell etc | D4: realistically obtained | E4: going to get | H4: 257 miles | I4: locations? 0/7 | J4: public? 8/8 | K4: Population? 2/4 | L4: personal bandwidth 0/4 | M4: costs
H5: SB X | I5: 1 connection -> 5 2+ connections -> 7 | J5: yes or no | K5: small city, medium city, large city, metropolis
E6: Self Park | F6: Valet | H6: CH | I6: employees? 3 | J6: connection? 2 | K6: Events Space? 4 | L6: hire 0/3
A7: Average Self Park | B7: Average Valet | E7: Downtown | F7: Downtown | I7: # of possible employees | J7: yes or no | K7: # of markets
A8: =AVERAGE(Accounts!H:H) | B8: =AVERAGE(Accounts!I:I) | E8: =AVERAGEIF(Accounts!E:E,"Downtown",Accounts!H:H) | F8: =AVERAGEIF(Accounts!E:E,F7,Accounts!I:I) | H8: 0 -> 1000+ | K8: Parking? 2 | L8: management 0/3
H9: 3 -> 700 - 1000 | K9: reducing, steady, increasing
H10: 5 -> 500 - 700
H11: 7 -> 250 - 500
H12: 10 -> 0 - 250
G14: avg + reviews
G15: =AVERAGE(Accounts!K:K)
G17: avg + reviews downtown
G18: =AVERAGEIF(Accounts!E:E,"Downtown",Accounts!K:K)

Sheet Sales Candence
A1: =Accounts!A1 | B1: Contact Created? | C1: =Accounts!T1 | D1: Ideal method of contact | E1: GM Contact Info | F1: =Accounts!F1 | G1: =Accounts!O1 | H1: =Accounts!P1 | I1: =Accounts!H1 | J1: =Accounts!I1 | K1: =#REF! | L1: SALES NOTES | N1: 1. Linked In | O1: 2. Cold Call | P1: 3. In person visit | Q1: 4. First Email | R1: 5. Cold Call | S1: 6. Second follow up email (Cusom video email if top) | T1: 7. Cold Call | U1: 8. 2nd in person visit | V1: 9. Cold Call and leave a voicemail | W1: 10. video email - owner | X1: 11. 3rd email - temp check
A2: =Accounts!A2 | B2: FALSE | C2: =Accounts!T2 | E2: jack.miller@fairmont.com | F2: =Accounts!F2 | G2: =Accounts!O2 | H2: =Accounts!P2 | I2: =Accounts!H2 | J2: =Accounts!I2 | K2: =#REF! | L2: Wasn't able to connect to anyone worth the time, need to try and ping jack miller on indeed | N2: TRUE | O2: TRUE | P2: FALSE | Q2: TRUE | R2: FALSE | S2: FALSE | T2: FALSE | U2: FALSE | V2: FALSE | W2: FALSE
A3: =Accounts!A3 | B3: FALSE | C3: =Accounts!T3 | E3: connie.ogden@marriott.com | F3: =Accounts!F3 | G3: =Accounts!O3 | H3: =Accounts!P3 | I3: =Accounts!H3 | J3: =Accounts!I3 | K3: =#REF! | L3: Going to Connies vm paiges exec assistant- left a voicemail | N3: TRUE | O3: TRUE | P3: FALSE | Q3: TRUE | R3: FALSE | S3: FALSE | T3: FALSE | U3: FALSE | V3: FALSE | W3: FALSE
A4: =#REF! | B4: FALSE | C4: =#REF! | F4: =#REF! | G4: =#REF! | H4: =#REF! | I4: =#REF! | J4: =#REF! | K4: =#REF! | L4: Front desk stopped me and wouldn't push me to the voicemail, took a note down and explained to her all that we do so she could notorize it, left another message | N4: TRUE | O4: TRUE | P4: FALSE | Q4: TRUE | R4: FALSE | S4: FALSE | T4: FALSE | U4: FALSE | V4: FALSE | W4: FALSE
A5: =Accounts!A4 | B5: FALSE | C5: =Accounts!T4 | F5: =Accounts!F4 | G5: =Accounts!O4 | H5: =Accounts!P4 | I5: =Accounts!H4 | J5: =Accounts!I4 | K5: =#REF! | L5: Going to Marie vm Derek's exec assistant- left a voicemail | N5: TRUE | O5: TRUE | P5: FALSE | Q5: FALSE | R5: FALSE | S5: FALSE | T5: FALSE | U5: FALSE | V5: FALSE | W5: FALSE
A6: =Accounts!A5 | B6: FALSE | C6: =Accounts!T5 | F6: =Accounts!F5 | G6: =Accounts!O5 | H6: =Accounts!P5 | I6: free | J6: 25 | K6: =#REF! | L6: Left voicemail on Sally's voicemail | N6: TRUE | O6: TRUE | P6: FALSE | Q6: FALSE | R6: FALSE | S6: FALSE | T6: FALSE | U6: FALSE | V6: FALSE | W6: FALSE
A7: =Accounts!A6 | B7: FALSE | C7: =Accounts!T6 | F7: =Accounts!F6 | G7: =Accounts!O6 | H7: =Accounts!P6 | I7: =Accounts!H6 | J7: =Accounts!I6 | K7: =#REF! | L7: Left a voicemail on Donalei Smiths phone | N7: TRUE | O7: TRUE | P7: FALSE | Q7: FALSE | R7: FALSE | S7: FALSE | T7: FALSE | U7: FALSE | V7: FALSE | W7: FALSE
A8: =Accounts!A7 | B8: FALSE | C8: =Accounts!T7 | E8: Sue.tan@vacationclub.com | F8: =Accounts!F7 | G8: =Accounts!O7 | H8: =Accounts!P7 | I8: =Accounts!H7 | J8: =Accounts!I7 | L8: Got emails, Sue.tan@vacationclub.com, Lane.palma@vacationclub.com | N8: TRUE | O8: TRUE | P8: FALSE | Q8: FALSE | R8: FALSE | S8: FALSE | T8: FALSE | U8: FALSE | V8: FALSE | W8: FALSE
A9: =Accounts!A8 | B9: FALSE | C9: =Accounts!T8 | F9: =Accounts!F8 | G9: =Accounts!O8 | H9: =Accounts!P8 | I9: =Accounts!H8 | J9: =Accounts!I8 | K9: =#REF! | N9: FALSE | O9: FALSE | P9: FALSE | Q9: FALSE | R9: FALSE | S9: FALSE | T9: FALSE | U9: FALSE | V9: FALSE | W9: FALSE
A10: =Accounts!A9 | B10: FALSE | C10: =Accounts!T9 | F10: =Accounts!F9 | G10: =Accounts!O9 | H10: =Accounts!P9 | I10: =Accounts!H9 | J10: =Accounts!I9 | K10: =#REF! | N10: FALSE | O10: FALSE | P10: FALSE | Q10: FALSE | R10: FALSE | S10: FALSE | T10: FALSE | U10: FALSE | V10: FALSE | W10: FALSE
A11: =Accounts!A10 | B11: FALSE | C11: =#REF! | F11: =Accounts!F10 | G11: =Accounts!O10 | H11: =Accounts!P10 | I11: =Accounts!H10 | J11: =Accounts!I10 | K11: =#REF! | N11: FALSE | O11: FALSE | P11: FALSE | Q11: FALSE | R11: FALSE | S11: FALSE | T11: FALSE | U11: FALSE | V11: FALSE | W11: FALSE
A12: =Accounts!A11 | B12: FALSE | C12: =Accounts!T11 | F12: =Accounts!F11 | G12: =Accounts!O11 | H12: =Accounts!P11 | I12: =Accounts!H11 | J12: =Accounts!I11 | K12: =#REF! | N12: FALSE | O12: FALSE | P12: FALSE | Q12: FALSE | R12: FALSE | S12: FALSE | T12: FALSE | U12: FALSE | V12: FALSE | W12: FALSE
A13: =Accounts!A12 | B13: FALSE | C13: =Accounts!T12 | F13: =Accounts!F12 | G13: =Accounts!O12 | H13: =Accounts!P12 | I13: =Accounts!H12 | J13: =Accounts!I12 | K13: =#REF! | N13: FALSE | O13: FALSE | P13: FALSE | Q13: FALSE | R13: FALSE | S13: FALSE | T13: FALSE | U13: FALSE | V13: FALSE | W13: FALSE
A14: =Accounts!A13 | B14: FALSE | C14: =Accounts!T13 | F14: =Accounts!F13 | G14: =Accounts!O13 | H14: =Accounts!P13 | I14: =Accounts!H13 | J14: =Accounts!I13 | K14: =#REF! | N14: FALSE | O14: FALSE | P14: FALSE | Q14: FALSE | R14: FALSE | S14: FALSE | T14: FALSE | U14: FALSE | V14: FALSE | W14: FALSE
A15: =#REF! | B15: FALSE | C15: =#REF! | F15: =#REF! | G15: =#REF! | H15: =#REF! | I15: =#REF! | J15: =#REF! | K15: =#REF! | N15: FALSE | O15: FALSE | P15: FALSE | Q15: FALSE | R15: FALSE | S15: FALSE | T15: FALSE | U15: FALSE | V15: FALSE | W15: FALSE
A16: =Accounts!A14 | B16: FALSE | C16: =Accounts!T14 | F16: =Accounts!F14 | G16: =Accounts!O14 | H16: =Accounts!P14 | I16: =Accounts!H14 | J16: =Accounts!I14 | K16: =#REF! | L16: Left voicemail, POC is sexy | N16: TRUE | O16: FALSE | P16: FALSE | Q16: FALSE | R16: FALSE | S16: FALSE | T16: FALSE | U16: FALSE | V16: FALSE | W16: FALSE
A17: =Accounts!A15 | B17: FALSE | C17: =Accounts!T15 | F17: =Accounts!F15 | G17: =#REF! | H17: =Accounts!P15 | I17: =Accounts!H15 | J17: =Accounts!I15 | K17: =#REF! | N17: FALSE | O17: FALSE | P17: FALSE | Q17: FALSE | R17: FALSE | S17: FALSE | T17: FALSE | U17: FALSE | V17: FALSE | W17: FALSE
A18: =Accounts!A16 | B18: FALSE | C18: =Accounts!T16 | F18: =Accounts!F16 | G18: =Accounts!O16 | H18: =Accounts!P16 | I18: =Accounts!H16 | J18: =Accounts!I16 | K18: =#REF! | N18: FALSE | O18: FALSE | P18: FALSE | Q18: FALSE | R18: FALSE | S18: FALSE | T18: FALSE | U18: FALSE | V18: FALSE | W18: FALSE
A19: =Accounts!A17 | B19: FALSE | C19: =Accounts!T17 | F19: =Accounts!F17 | G19: =Accounts!O17 | H19: =Accounts!P17 | I19: =Accounts!H17 | J19: =Accounts!I17 | K19: =#REF! | N19: FALSE | O19: FALSE | P19: FALSE | Q19: FALSE | R19: FALSE | S19: FALSE | T19: FALSE | U19: FALSE | V19: FALSE | W19: FALSE
A20: =Accounts!A18 | B20: FALSE | C20: =Accounts!T18 | F20: =Accounts!F18 | G20: =Accounts!O18 | H20: =Accounts!P18 | I20: =Accounts!H18 | J20: =Accounts!I18 | K20: =#REF! | N20: FALSE | O20: FALSE | P20: FALSE | Q20: FALSE | R20: FALSE | S20: FALSE | T20: FALSE | U20: FALSE | V20: FALSE | W20: FALSE
A21: =Accounts!A19 | B21: FALSE | C21: =Accounts!T19 | E21: Brigitte.tueros@westin.com | F21: =Accounts!F19 | G21: =Accounts!O19 | H21: =Accounts!P19 | I21: =Accounts!H19 | J21: =Accounts!I19 | K21: =#REF! | L21: Not interested in valet but wanted to showcase sophi and sent to brigitte | N21: FALSE | O21: FALSE | P21: FALSE | Q21: FALSE | R21: FALSE | S21: FALSE | T21: FALSE | U21: FALSE | V21: FALSE | W21: FALSE
A22: =Accounts!A20 | B22: FALSE | C22: =Accounts!T20 | F22: =Accounts!F20 | G22: =Accounts!O20 | H22: =Accounts!P20 | I22: =Accounts!H20 | J22: =Accounts!I20 | K22: =#REF! | L22: Left voicemail for Adam, mutual connection with Linsday on linked inn. Called and they are happy with current service and I left my contact info | N22: TRUE | O22: TRUE | P22: FALSE | Q22: TRUE | R22: FALSE | S22: FALSE | T22: FALSE | U22: FALSE | V22: FALSE | W22: FALSE
A23: =Accounts!A21 | B23: FALSE | C23: =Accounts!T21 | E23: 4802144601-direct | F23: =Accounts!F21 | G23: =Accounts!O21 | H23: =Accounts!P21 | I23: =Accounts!H21 | J23: =Accounts!I21 | K23: =#REF! | L23: DOO-Amy.donovan@andaz.com Left a voicemail for carlos, will follow up with emails this week, left vm for carlos | N23: TRUE | O23: TRUE | P23: FALSE | Q23: TRUE | R23: FALSE | S23: FALSE | T23: FALSE | U23: FALSE | V23: FALSE | W23: FALSE
A24: =Accounts!A22 | B24: FALSE | C24: =Accounts!T22 | F24: =Accounts!F22 | G24: =Accounts!O22 | H24: =Accounts!P22 | I24: =Accounts!H22 | J24: =Accounts!I22 | K24: =#REF! | L24: Left a voicemail with Director of Rooms Leo Gianulis- Leo.gianulis@hyatt.com | N24: TRUE | O24: TRUE | P24: FALSE | Q24: FALSE | R24: FALSE | S24: FALSE | T24: FALSE | U24: FALSE | V24: FALSE | W24: FALSE
A25: =Accounts!A23 | B25: FALSE | C25: =Accounts!T23 | E25: Jeffrey.Herz@casinoaz.com | F25: =Accounts!F23 | G25: =Accounts!O23 | H25: =Accounts!P23 | I25: =Accounts!H23 | J25: =Accounts!I23 | K25: =#REF! | L25: Sent connect message on Linked Inn, Jeffrey is the contact for vendor partnerships | N25: TRUE | O25: TRUE | P25: FALSE | Q25: FALSE | R25: FALSE | S25: FALSE | T25: FALSE | U25: FALSE | V25: FALSE | W25: FALSE
A26: =Accounts!A24 | B26: FALSE | C26: =Accounts!T24 | F26: =Accounts!F24 | G26: =Accounts!O24 | H26: =Accounts!P24 | I26: =Accounts!H24 | J26: =Accounts!I24 | K26: =#REF! | L26: Connected with nicholas on linked in, messaged him, and left a voicemail | N26: TRUE | O26: FALSE | P26: FALSE | Q26: FALSE | R26: FALSE | S26: FALSE | T26: FALSE | U26: FALSE | V26: FALSE | W26: FALSE
A27: =Accounts!A25 | B27: FALSE | C27: =Accounts!T25 | F27: =Accounts!F25 | G27: =Accounts!O25 | H27: =Accounts!P25 | I27: =Accounts!H25 | J27: =Accounts!I25 | K27: =#REF! | N27: FALSE | O27: FALSE | P27: FALSE | Q27: FALSE | R27: FALSE | S27: FALSE | T27: FALSE | U27: FALSE | V27: FALSE | W27: FALSE
A28: =Accounts!A26 | B28: FALSE | C28: =Accounts!T26 | F28: =Accounts!F26 | G28: =Accounts!O26 | H28: =Accounts!P26 | I28: =Accounts!H26 | J28: =Accounts!I26 | K28: =#REF! | N28: FALSE | O28: FALSE | P28: FALSE | Q28: FALSE | R28: FALSE | S28: FALSE | T28: FALSE | U28: FALSE | V28: FALSE | W28: FALSE
A29: =Accounts!A27 | B29: FALSE | C29: =Accounts!T27 | F29: =Accounts!F27 | G29: =Accounts!O27 | H29: =Accounts!P27 | I29: =Accounts!H27 | J29: =Accounts!I27 | K29: =#REF! | N29: FALSE | O29: FALSE | P29: FALSE | Q29: FALSE | R29: FALSE | S29: FALSE | T29: FALSE | U29: FALSE | V29: FALSE | W29: FALSE
A30: =Accounts!A28 | B30: FALSE | C30: =Accounts!T28 | F30: =Accounts!F28 | G30: =Accounts!O28 | H30: =Accounts!P28 | I30: =Accounts!H28 | J30: =Accounts!I28 | K30: =#REF! | N30: FALSE | O30: FALSE | P30: FALSE | Q30: FALSE | R30: FALSE | S30: FALSE | T30: FALSE | U30: FALSE | V30: FALSE | W30: FALSE
A31: =Accounts!A29 | B31: FALSE | C31: =Accounts!T29 | F31: =Accounts!F29 | G31: =Accounts!O29 | H31: =Accounts!P29 | I31: =Accounts!H29 | J31: =Accounts!I29 | K31: =#REF! | N31: FALSE | O31: FALSE | P31: FALSE | Q31: FALSE | R31: FALSE | S31: FALSE | T31: FALSE | U31: FALSE | V31: FALSE | W31: FALSE
A32: =Accounts!A30 | B32: FALSE | C32: =Accounts!T30 | F32: =Accounts!F30 | G32: =Accounts!O30 | H32: =Accounts!P30 | I32: =Accounts!H30 | J32: =Accounts!I30 | K32: =#REF! | N32: FALSE | O32: FALSE | P32: FALSE | Q32: FALSE | R32: FALSE | S32: FALSE | T32: FALSE | U32: FALSE | V32: FALSE | W32: FALSE
A33: =Accounts!A31 | B33: FALSE | C33: =Accounts!T31 | F33: =Accounts!F31 | G33: =Accounts!O31 | H33: =Accounts!P31 | I33: =Accounts!H31 | J33: =Accounts!I31 | K33: =#REF! | N33: FALSE | O33: FALSE | P33: FALSE | Q33: FALSE | R33: FALSE | S33: FALSE | T33: FALSE | U33: FALSE | V33: FALSE | W33: FALSE
A34: =Accounts!A32 | B34: FALSE | C34: =Accounts!T32 | F34: =Accounts!F32 | G34: =Accounts!O32 | H34: =Accounts!P32 | I34: =Accounts!H32 | J34: =Accounts!I32 | K34: =#REF! | N34: FALSE | O34: FALSE | P34: FALSE | Q34: FALSE | R34: FALSE | S34: FALSE | T34: FALSE | U34: FALSE | V34: FALSE | W34: FALSE
A35: =Accounts!A33 | B35: FALSE | C35: =Accounts!T33 | F35: =Accounts!F33 | G35: =Accounts!O33 | H35: =Accounts!P33 | I35: =Accounts!H33 | J35: =Accounts!I33 | K35: =#REF! | N35: FALSE | O35: FALSE | P35: FALSE | Q35: FALSE | R35: FALSE | S35: FALSE | T35: FALSE | U35: FALSE | V35: FALSE | W35: FALSE
A36: =Accounts!A34 | B36: FALSE | C36: =Accounts!T34 | F36: =Accounts!F34 | G36: =Accounts!O34 | H36: =Accounts!P34 | I36: =Accounts!H34 | J36: =Accounts!I34 | K36: =#REF! | N36: FALSE | O36: FALSE | P36: FALSE | Q36: FALSE | R36: FALSE | S36: FALSE | T36: FALSE | U36: FALSE | V36: FALSE | W36: FALSE
A37: =Accounts!A35 | B37: FALSE | C37: =Accounts!T35 | F37: =Accounts!F35 | G37: =Accounts!O35 | H37: =Accounts!P35 | I37: =Accounts!H35 | J37: =Accounts!I35 | K37: =#REF! | L37: Left a voicemail for rebecca, reviews seem okay, they might be inhouse it seems if they are only charging $15 | N37: FALSE | O37: FALSE | P37: FALSE | Q37: FALSE | R37: FALSE | S37: FALSE | T37: FALSE | U37: FALSE | V37: FALSE | W37: FALSE
A38: =Accounts!A36 | B38: FALSE | C38: =Accounts!T36 | E38: Katy Powers | F38: =Accounts!F36 | G38: =Accounts!O36 | H38: =Accounts!P36 | I38: =Accounts!H36 | J38: =Accounts!I36 | K38: =#REF! | L38: Left voicemail for Katy | N38: TRUE | O38: TRUE | P38: FALSE | Q38: FALSE | R38: FALSE | S38: FALSE | T38: FALSE | U38: FALSE | V38: FALSE | W38: FALSE
A39: =Accounts!A37 | B39: FALSE | C39: =Accounts!T37 | E39: teri.owens@atriumhotels.com | F39: =Accounts!F37 | G39: =Accounts!O37 | H39: =Accounts!P37 | I39: =Accounts!H37 | J39: =Accounts!I37 | K39: =#REF! | L39: Actually talked to the GM Teri, said things are going well! Emailing her my contact incase | N39: TRUE | O39: TRUE | P39: FALSE | Q39: TRUE | R39: FALSE | S39: FALSE | T39: FALSE | U39: FALSE | V39: FALSE | W39: FALSE
A40: =Accounts!A38 | B40: FALSE | C40: =Accounts!T38 | F40: =Accounts!F38 | G40: =Accounts!O38 | H40: =Accounts!P38 | I40: =Accounts!H38 | J40: =Accounts!I38 | K40: =#REF! | N40: FALSE | O40: FALSE | P40: FALSE | Q40: FALSE | R40: FALSE | S40: FALSE | T40: FALSE | U40: FALSE | V40: FALSE | W40: FALSE
...

Sheet Parking
A1: Loaction ID | B1: Location Name | C1: Location Type | D1: Location Area | E1: Address | F1: # Spaces | G1: Hourly Rate | H1: Unreserved Monthly Rate | I1: Operator | J1: Point of Contact | K1: POC Number | L1: URL | M1: Notes | N1: PARCs Equipment Notes | O1: Account Associated
A2: 1 | B2: Novus Place Structure | C2: Garage | D2: Tempe | E2: 747 S Packard Dr, Tempe, AZ 85281 | F2: 1801 | G2: 4 | I2: ASU | O2: North Italia & Blanco in Tempe
A3: 2 | B3: Chase Centerpoint Facility | C3: Garage | D3: Tempe | E3: 725 Ash Ave, Tempe, AZ 85281 | F3: 750 | G3: 6 | H3: NA | I3: SP+ | J3: Monthly Parking Specialists | K3: (602)-802-5487 | L3: https://parking.com/national/parking-near/33.42302890000001/-111.9418086/725-s-ash-ave?lot_id=20719&showListOnly=1&view=daily&facility&valet&general=&displayFullCity=0&start=2026-02-24T11%3A00&stop=2026-02-24T13%3A00&sw=33.42082970431528,-111.94714598144415&ne=33.42560564999984,-111.93767239855623 | O3: Flithy Animal or Other Mill Ave
A4: 3 | B4: Hayden Ferry Lakeside | C4: Garage | D4: Tempe | E4: 68 E Rio Salado Pkwy, Tempe, AZ 85281 | F4: 2704 | G4: 3 | O4: Roman (Pre Open)
A5: 4 | B5: CityScape West | C5: Garage | D5: Downtown | E5: 1 E Washington St Phoenix, AZ 85004 | G5: 5 | I5: Ace | L5: https://www.reddevelopment.com/cityscape/directory/ | M5: Garage has valet | O5: Rosso Italian, Arrogant Butcher
A6: 5 | B6: City of Phoenix Plaza Garage | C6: Garage | D6: Downtown | E6: 100 W Washington St Phoenix, AZ 85003 | F6: 1405 | G6: 4 | I6: Ace
A7: 6 | B7: Chase Tower Garage | C7: Garage | D7: Downtown | E7: 201 N 1st St Phoenix, AZ 85004 | F7: 1950 | G7: 5 | I7: Ace
A8: 7 | B8: 21 W Van Buren St | C8: Garage | D8: Downtown | E8: 21 W Van Buren St Phoenix, AZ 85004 | F8: 461 | G8: 4 | I8: LAZ
A9: 8 | B9: Ten-0-One | C9: Garage | D9: Downtown | E9: 1001 N Central Ave Phoenix, AZ 85004 | F9: 350 | I9: Ace ( I think) | O9: Palma, Churchill, Monorchid, Cambria
A10: 9 | B10: Collier Center | C10: Garage | D10: Downtown | E10: 201 E Washington St Phoenix, AZ 85004 | F10: 1476 | G10: 5 | I10: Ace | O10: Potentially Pre Open STK
A11: 10 | B11: Galleria Garage | C11: Garage | D11: Scottsdale | E11: 4301-4343 N Scottsdale Rd Scottsdale, AZ 85251 | F11: 700 | G11: Free | I11: City of Scottsdale | K11: 1 480-312-3111
A12: 11 | B12: Scottsdale Waterfront | C12: Garage | D12: Scottsdale | E12: 7135 E Camelback Rd Scottsdale, AZ 85251 | F12: 300 | G12: Free | I12: City of Scottsdale | M12: Has Valet | O12: Maple & Ash, Culinary Dropout
A13: 12 | B13: 5th Avenue Garage | C13: Garage | D13: Scottsdale | E13: 7143 E 5th Ave Scottsdale, AZ 85251 | F13: 409 | G13: Free | I13: City of Scottsdale
A14: 13 | B14: Scottsdale Mall - Pepperwood Lot | C14: Not Covered | D14: Scottsdale | E14: 7319 E 1st Ave Scottsdale, AZ 85251 | F14: 123 | G14: Free | I14: City of Scottsdale | O14: Hulas
A15: 14 | B15: Parking Corral | C15: Partially Covered | D15: Scottsdale | E15: 3806 N Brown Ave Scottsdale, AZ 85251 | F15: 224 | G15: Free | I15: City of Scottsdale | O15: STK, Mission, Uchi
A16: 15 | B16: Center for the Arts Parking Garage | C16: Garage | D16: Scottsdale | E16: 3888 N Wells Fargo Ave Scottsdale, AZ 85251 | F16: 368 | G16: Free | I16: City of Scottsdale | K16: 1 480-312-3111
A17: 16
A18: 17
A19: 18
A20: 19
A21: 20
A22: 21
A23: 22
A24: 23
A25: 24
A26: 25
A27: 26
A28: 27
... A32: 31

Sheet RevenueForecasting
A1: Account | B1: # of Rooms | C1: Occupancy Rate | D1: Forecast | E1: Valet Conversion Rate | F1: Estimated Daily Valet Count | G1: Estimated Daily Revenue | H1: Estimated Annual Revenue | I1: Estimate Net Operating Income Annually | J1: Total Daily Rev | K1: Total Annual Rev | L1: Total Annual NOI
A2: =Accounts!A2 | B2: =Accounts!J2 | C2: 0.6 | D2: =Accounts!J2*C2 | E2: 0.4 | F2: =D2*E2 | G2: =if(or(eq(Accounts!I2,"No Valet"),eq(Accounts!I2,"Has Valet")), F2 * AVERAGE(Accounts!I$2:I$34),F2*Accounts!I2) | H2: =iferror(G2*360,"") | I2: =H2*0.1 | J2: =sum(G2:G72) | K2: =sum(H2:H72) | L2: =sum(I2:I72)
A3: =Accounts!A3 | B3: =Accounts!J3 | C3: 0.6 | D3: =Accounts!J3*C3 | E3: 0.4 | F3: =D3*E3 | G3: =if(or(eq(Accounts!I3,"No Valet"),eq(Accounts!I3,"Has Valet")), F3 * AVERAGE(Accounts!I$2:I$34),F3*Accounts!I3) | H3: =iferror(G3*360,"") | I3: =H3*0.1
A4: =#REF! | B4: =#REF! | C4: 0.6 | D4: =#REF!*C4 | E4: 0.4 | F4: =D4*E4 | G4: =if(or(eq(#REF!,"No Valet"),eq(#REF!,"Has Valet")), F4 * AVERAGE(Accounts!I$2:I$34),F4*#REF!) | H4: =iferror(G4*360,"") | I4: =H4*0.1
A5: =Accounts!A4 | B5: =Accounts!J4 | C5: 0.6 | D5: =Accounts!J4*C5 | E5: 0.4 | F5: =D5*E5 | G5: =if(or(eq(Accounts!I4,"No Valet"),eq(Accounts!I4,"Has Valet")), F5 * AVERAGE(Accounts!I$2:I$34),F5*Accounts!I4) | H5: =iferror(G5*360,"") | I5: =H5*0.1
A6: =Accounts!A5 | B6: =Accounts!J5 | C6: 0.6 | D6: =Accounts!J5*C6 | E6: 0.4 | F6: =D6*E6 | G6: =if(or(eq(Accounts!I5,"No Valet"),eq(Accounts!I5,"Has Valet")), F6 * AVERAGE(Accounts!I$2:I$34),F6*Accounts!I5) | H6: =iferror(G6*360,"") | I6: =H6*0.1
A7: =Accounts!A6 | B7: =Accounts!J6 | C7: 0.6 | D7: =Accounts!J6*C7 | E7: 0.4 | F7: =D7*E7 | G7: =if(or(eq(Accounts!I6,"No Valet"),eq(Accounts!I6,"Has Valet")), F7 * AVERAGE(Accounts!I$2:I$34),F7*Accounts!I6) | H7: =iferror(G7*360,"") | I7: =H7*0.1
A8: =Accounts!A7 | B8: =Accounts!J7 | C8: 0.6 | D8: =Accounts!J7*C8 | E8: 0.4 | F8: =D8*E8 | G8: =if(or(eq(Accounts!I7,"No Valet"),eq(Accounts!I7,"Has Valet")), F8 * AVERAGE(Accounts!I$2:I$34),F8*Accounts!I7) | H8: =iferror(G8*360,"") | I8: =H8*0.1
A9: =Accounts!A8 | B9: =Accounts!J8 | C9: 0.6 | D9: =Accounts!J8*C9 | E9: 0.4 | F9: =D9*E9 | G9: =if(or(eq(Accounts!I8,"No Valet"),eq(Accounts!I8,"Has Valet")), F9 * AVERAGE(Accounts!I$2:I$34),F9*Accounts!I8) | H9: =iferror(G9*360,"") | I9: =H9*0.1
A10: =Accounts!A9 | B10: =Accounts!J9 | C10: 0.6 | D10: =Accounts!J9*C10 | E10: 0.4 | F10: =D10*E10 | G10: =if(or(eq(Accounts!I9,"No Valet"),eq(Accounts!I9,"Has Valet")), F10 * AVERAGE(Accounts!I$2:I$34),F10*Accounts!I9) | H10: =iferror(G10*360,"") | I10: =H10*0.1
A11: =Accounts!A10 | B11: =Accounts!J10 | C11: 0.6 | D11: =Accounts!J10*C11 | E11: 0.4 | F11: =D11*E11 | G11: =if(or(eq(Accounts!I10,"No Valet"),eq(Accounts!I10,"Has Valet")), F11 * AVERAGE(Accounts!I$2:I$34),F11*Accounts!I10) | H11: =iferror(G11*360,"") | I11: =H11*0.1
A12: =Accounts!A11 | B12: =Accounts!J11 | C12: 0.6 | D12: =Accounts!J11*C12 | E12: 0.4 | F12: =D12*E12 | G12: =if(or(eq(Accounts!I11,"No Valet"),eq(Accounts!I11,"Has Valet")), F12 * AVERAGE(Accounts!I$2:I$34),F12*Accounts!I11) | H12: =iferror(G12*360,"") | I12: =H12*0.1
A13: =Accounts!A12 | B13: =Accounts!J12 | C13: 0.6 | D13: =Accounts!J12*C13 | E13: 0.4 | F13: =D13*E13 | G13: =if(or(eq(Accounts!I12,"No Valet"),eq(Accounts!I12,"Has Valet")), F13 * AVERAGE(Accounts!I$2:I$34),F13*Accounts!I12) | H13: =iferror(G13*360,"") | I13: =H13*0.1
A14: =Accounts!A13 | B14: =Accounts!J13 | C14: 0.6 | D14: =Accounts!J13*C14 | E14: 0.4 | F14: =D14*E14 | G14: =if(or(eq(Accounts!I13,"No Valet"),eq(Accounts!I13,"Has Valet")), F14 * AVERAGE(Accounts!I$2:I$34),F14*Accounts!I13) | H14: =iferror(G14*360,"") | I14: =H14*0.1
A15: =#REF! | B15: =#REF! | C15: 0.6 | D15: =#REF!*C15 | E15: 0.4 | F15: =D15*E15 | G15: =if(or(eq(#REF!,"No Valet"),eq(#REF!,"Has Valet")), F15 * AVERAGE(Accounts!I$2:I$34),F15*#REF!) | H15: =iferror(G15*360,"") | I15: =H15*0.1
A16: =Accounts!A14 | B16: =Accounts!J14 | C16: 0.6 | D16: =Accounts!J14*C16 | E16: 0.4 | F16: =D16*E16 | G16: =if(or(eq(Accounts!I14,"No Valet"),eq(Accounts!I14,"Has Valet")), F16 * AVERAGE(Accounts!I$2:I$34),F16*Accounts!I14) | H16: =iferror(G16*360,"") | I16: =H16*0.1
A17: =Accounts!A15 | B17: =Accounts!J15 | C17: 0.6 | D17: =Accounts!J15*C17 | E17: 0.4 | F17: =D17*E17 | G17: =if(or(eq(Accounts!I15,"No Valet"),eq(Accounts!I15,"Has Valet")), F17 * AVERAGE(Accounts!I$2:I$34),F17*Accounts!I15) | H17: =iferror(G17*360,"") | I17: =H17*0.1
A18: =Accounts!A16 | B18: =Accounts!J16 | C18: 0.6 | D18: =Accounts!J16*C18 | E18: 0.4 | F18: =D18*E18 | G18: =if(or(eq(Accounts!I16,"No Valet"),eq(Accounts!I16,"Has Valet")), F18 * AVERAGE(Accounts!I$2:I$34),F18*Accounts!I16) | H18: =iferror(G18*360,"") | I18: =H18*0.1
A19: =Accounts!A17 | B19: =Accounts!J17 | C19: 0.6 | D19: =Accounts!J17*C19 | E19: 0.4 | F19: =D19*E19 | G19: =if(or(eq(Accounts!I17,"No Valet"),eq(Accounts!I17,"Has Valet")), F19 * AVERAGE(Accounts!I$2:I$34),F19*Accounts!I17) | H19: =iferror(G19*360,"") | I19: =H19*0.1
A20: =Accounts!A18 | B20: =Accounts!J18 | C20: 0.6 | D20: =Accounts!J18*C20 | E20: 0.4 | F20: =D20*E20 | G20: =if(or(eq(Accounts!I18,"No Valet"),eq(Accounts!I18,"Has Valet")), F20 * AVERAGE(Accounts!I$2:I$34),F20*Accounts!I18) | H20: =iferror(G20*360,"") | I20: =H20*0.1
A21: =Accounts!A19 | B21: =Accounts!J19 | C21: 0.6 | D21: =Accounts!J19*C21 | E21: 0.4 | F21: =D21*E21 | G21: =if(or(eq(Accounts!I19,"No Valet"),eq(Accounts!I19,"Has Valet")), F21 * AVERAGE(Accounts!I$2:I$34),F21*Accounts!I19) | H21: =iferror(G21*360,"") | I21: =H21*0.1
A22: =Accounts!A20 | B22: =Accounts!J20 | C22: 0.6 | D22: =Accounts!J20*C22 | E22: 0.4 | F22: =D22*E22 | G22: =if(or(eq(Accounts!I20,"No Valet"),eq(Accounts!I20,"Has Valet")), F22 * AVERAGE(Accounts!I$2:I$34),F22*Accounts!I20) | H22: =iferror(G22*360,"") | I22: =H22*0.1
A23: =Accounts!A21 | B23: =Accounts!J21 | C23: 0.6 | D23: =Accounts!J21*C23 | E23: 0.4 | F23: =D23*E23 | G23: =if(or(eq(Accounts!I21,"No Valet"),eq(Accounts!I21,"Has Valet")), F23 * AVERAGE(Accounts!I$2:I$34),F23*Accounts!I21) | H23: =iferror(G23*360,"") | I23: =H23*0.1
A24: =Accounts!A22 | B24: =Accounts!J22 | C24: 0.6 | D24: =Accounts!J22*C24 | E24: 0.4 | F24: =D24*E24 | G24: =if(or(eq(Accounts!I22,"No Valet"),eq(Accounts!I22,"Has Valet")), F24 * AVERAGE(Accounts!I$2:I$34),F24*Accounts!I22) | H24: =iferror(G24*360,"") | I24: =H24*0.1
A25: =Accounts!A23 | B25: =Accounts!J23 | C25: 0.6 | D25: =Accounts!J23*C25 | E25: 0.4 | F25: =D25*E25 | G25: =if(or(eq(Accounts!I23,"No Valet"),eq(Accounts!I23,"Has Valet")), F25 * AVERAGE(Accounts!I$2:I$34),F25*Accounts!I23) | H25: =iferror(G25*360,"") | I25: =H25*0.1
A26: =Accounts!A24 | B26: =Accounts!J24 | C26: 0.6 | D26: =Accounts!J24*C26 | E26: 0.4 | F26: =D26*E26 | G26: =if(or(eq(Accounts!I24,"No Valet"),eq(Accounts!I24,"Has Valet")), F26 * AVERAGE(Accounts!I$2:I$34),F26*Accounts!I24) | H26: =iferror(G26*360,"") | I26: =H26*0.1
A27: =Accounts!A25 | B27: =Accounts!J25 | C27: 0.6 | D27: =Accounts!J25*C27 | E27: 0.4 | F27: =D27*E27 | G27: =if(or(eq(Accounts!I25,"No Valet"),eq(Accounts!I25,"Has Valet")), F27 * AVERAGE(Accounts!I$2:I$34),F27*Accounts!I25) | H27: =iferror(G27*360,"") | I27: =H27*0.1
... A40: =Accounts!A38 | B40: =Accounts!J38 | C40: 0.6 | D40: =Accounts!J38*C40 | E40: 0.4 | F40: =D40*E40 | G40: =if(or(eq(Accounts!I38,"No Valet"),eq(Accounts!I38,"Has Valet")), F40 * AVERAGE(Accounts!I$2:I$34),F40*Accounts!I38) | H40: =iferror(G40*360,"") | I40: =H40*0.1
A41: =Accounts!A39 | B41: =Accounts!J39 | C41: 0.6 | D41: =#REF!*C41 | E41: 0.4 | F41: =D41*E41 | G41: =if(or(eq(#REF!,"No Valet"),eq(#REF!,"Has Valet")), F41 * AVERAGE(Accounts!I$2:I$34),F41*#REF!) | H41: =iferror(G41*360,"") | I41: =H41*0.1
A42: =Accounts!A40 | B42: =Accounts!J40 | C42: 0.6 | D42: =Accounts!J39*C42 | E42: 0.4 | F42: =D42*E42 | G42: =if(or(eq(Accounts!I39,"No Valet"),eq(Accounts!I39,"Has Valet")), F42 * AVERAGE(Accounts!I$2:I$34),F42*Accounts!I39) | H42: =iferror(G42*360,"") | I42: =H42*0.1
A43: =Accounts!A41 | B43: =Accounts!J41 | C43: 0.6 | D43: =Accounts!J40*C43 | E43: 0.4 | F43: =D43*E43 | G43: =if(or(eq(Accounts!I40,"No Valet"),eq(Accounts!I40,"Has Valet")), F43 * AVERAGE(Accounts!I$2:I$34),F43*Accounts!I40) | H43: =iferror(G43*360,"") | I43: =H43*0.1
A44: =Accounts!A42 | B44: =Accounts!J42 | C44: 0.6 | D44: =Accounts!J41*C44 | E44: 0.4 | F44: =D44*E44 | G44: =if(or(eq(Accounts!I41,"No Valet"),eq(Accounts!I41,"Has Valet")), F44 * AVERAGE(Accounts!I$2:I$34),F44*Accounts!I41) | H44: =iferror(G44*360,"") | I44: =H44*0.1
A45: =Accounts!A43 | B45: =Accounts!J43 | C45: 0.6 | D45: =Accounts!J42*C45 | E45: 0.4 | F45: =D45*E45 | G45: =if(or(eq(Accounts!I42,"No Valet"),eq(Accounts!I42,"Has Valet")), F45 * AVERAGE(Accounts!I$2:I$34),F45*Accounts!I42) | H45: =iferror(G45*360,"") | I45: =H45*0.1
A46: =Accounts!A44 | B46: =Accounts!J44 | C46: 0.6 | D46: =Accounts!J43*C46 | E46: 0.4 | F46: =D46*E46 | G46: =if(or(eq(Accounts!I43,"No Valet"),eq(Accounts!I43,"Has Valet")), F46 * AVERAGE(Accounts!I$2:I$34),F46*Accounts!I43) | H46: =iferror(G46*360,"") | I46: =H46*0.1
A47: =Accounts!A45 | B47: =Accounts!J45 | C47: 0.6 | D47: =Accounts!J44*C47 | E47: 0.4 | F47: =D47*E47 | G47: =if(or(eq(#REF!,"No Valet"),eq(#REF!,"Has Valet")), F47 * AVERAGE(Accounts!I$2:I$34),F47*#REF!) | H47: =iferror(G47*360,"") | I47: =H47*0.1
A48: =Accounts!A46 | B48: =Accounts!J46 | C48: 0.6 | D48: =Accounts!J45*C48 | E48: 0.4 | F48: =D48*E48 | G48: =if(or(eq(Accounts!I44,"No Valet"),eq(Accounts!I44,"Has Valet")), F48 * AVERAGE(Accounts!I$2:I$34),F48*Accounts!I44) | H48: =iferror(G48*360,"") | I48: =H48*0.1
A49: =Accounts!A47 | B49: =Accounts!J47 | C49: 0.6 | D49: =#REF!*C49 | E49: 0.4 | F49: =D49*E49 | G49: =if(or(eq(#REF!,"No Valet"),eq(#REF!,"Has Valet")), F49 * AVERAGE(Accounts!I$2:I$34),F49*#REF!) | H49: =iferror(G49*360,"") | I49: =H49*0.1
A50: =Accounts!A48 | B50: =Accounts!J48 | C50: 0.6 | D50: =#REF!*C50 | E50: 0.4 | F50: =D50*E50 | G50: =if(or(eq(#REF!,"No Valet"),eq(#REF!,"Has Valet")), F50 * AVERAGE(Accounts!I$2:I$34),F50*#REF!) | H50: =iferror(G50*360,"") | I50: =H50*0.1
A51: =Accounts!A49 | B51: =Accounts!J49 | C51: 0.6 | D51: =Accounts!J46*C51 | E51: 0.4 | F51: =D51*E51 | G51: =if(or(eq(Accounts!I46,"No Valet"),eq(Accounts!I46,"Has Valet")), F51 * AVERAGE(Accounts!I$2:I$34),F51*Accounts!I46) | H51: =iferror(G51*360,"") | I51: =H51*0.1
A52: =Accounts!A50 | B52: =Accounts!J50 | C52: 0.6 | D52: =Accounts!J47*C52 | E52: 0.4 | F52: =D52*E52 | G52: =if(or(eq(Accounts!I47,"No Valet"),eq(Accounts!I47,"Has Valet")), F52 * AVERAGE(Accounts!I$2:I$34),F52*Accounts!I47) | H52: =iferror(G52*360,"") | I52: =H52*0.1
...

Sheet Competition Analysis
A1: Company | B1: Role | C1: Low Pay | D1: High Play | E1: Type | F1: SOPHI role Equivalance | G1: Benefits | H1: Bonus?
A2: Crescent | B2: PT Overnight Valet Attendant | C2: 13.5 | D2: 17.5 | E2: PT | F2: Overnight | G2: Retirement, PTO | J2: OVERNIGHT SUPER | K2: OVERNIGHT ASSOC | L2: ASSOCIATE | M2: SUPERVISOR
A3: PMC | B3: Overnight Valet Attendant | C3: 14.69 | D3: 14.69 | E3: PT | F3: Overnight | J3: =AVERAGE(D2:D7) | K3: =AVERAGE(C2:C7) | L3: =AVERAGE(C8:C17) | M3: =AVERAGE(D8:D17)
A4: Crescent | B4: FT Overnight Valet Attendant | C4: 13.5 | D4: 18 | E4: FT | F4: Overnight
A5: SP+ | B5: Overnight Valet Driver | C5: 16.5 | D5: 16.5 | E5: FT | F5: Overnight
A6: PMC | B6: Overnight Valet Attendant | C6: 14.69 | D6: 14.69 | E6: FT | F6: Overnight
A7: SP+ | B7: Valet Driver Overnight | C7: 15 | D7: 20 | E7: FT | F7: Overnight
A8: FreedomPark | B8: Valet - Sky Harbor Airport | C8: 16.5 | D8: 18.5 | E8: FT
A9: EPIC | B9: Valet Parking Attendant | C9: 13.5 | D9: 17.75 | E9: PT
A10: Elevate Parking | B10: Valet | C10: 20 | D10: 35 | E10: FT
A11: Hyatt Andaz | B11: Bellman/Valet | C11: 14 | D11: 18.75 | E11: FT | G11: Medical Dental Vision Retirement
A12: PRS Management | B12: Driver/Valet | C12: 13.5 | D12: 18 | E12: FT | G12: Retirement, PTO
A13: Desert Mountain | B13: Valet Attendant | C13: 14 | D13: 18.25 | E13: PT | G13: Medical Dental Vision PTO 401k match
A14: ACE Parking | B14: VALET | C14: 15 | D14: 19.75 | E14: FT | G14: Medical Dental Vision PTO 401k match
A15: Desert Highlands | B15: Seasonal Valet | C15: 20 | D15: 23 | E15: FT
A16: PMC | B16: Valet Attendant | C16: 11.7 | D16: 11.7 | E16: PT/FT | G16: Medical Dental Vision PTO 401k match
A17: Troon Golf | B17: Valet Parking Attendant | C17: 17 | D17: 17 | E17: PT | H17: NO TIPS

Sheet Employees
A1: Employees | B1: Contacted | C1: Avalibility | D1: Contact Info | E1: Interested? | F1: Notes
B2: FALSE | E2: FALSE
B3: FALSE | E3: FALSE
B4: FALSE | E4: FALSE
B5: FALSE | E5: FALSE
B6: FALSE | E6: FALSE
B7: FALSE | E7: FALSE
B8: FALSE | E8: FALSE
B9: FALSE | E9: FALSE
B10: FALSE | E10: FALSE
B11: FALSE | E11: FALSE
B12: FALSE | E12: FALSE
B13: FALSE | E13: FALSE
... B36: FALSE | E36: FALSE

Sheet Market Notes
A1: NOTES
A2: Hospitality Groups | B2: Partners | C2: POC

Sheet TAM_Conservative
A1: Account | B1: Account Type | C1: TAM Class | D1: Rooms/Beds | E1: Seats | F1: Occupancy % | G1: Turnover | H1: Valet Conv % | I1: Valet Rate | J1: Op Days | K1: Peak Mod | L1: Daily Rev | M1: TAM | N1: TAM Status | O1: Notes / Source
A2: Kenect Phoenix | B2: Apartment | C2: Unknown type: Apartment | N2: REVIEW
A3: Sentral Sol Modern | B3: Apartment/Hotel | C3: Hotel — Downtown Select-Service | F3: 0.6 | H3: 0.25 | J3: 360 | N3: No Valet / TAM = $0 | O3: Hotel has no valet (rate field: 'No Valet'). Auto-class: downtown full-service <300 rooms. Qualitative pipeline only.
A4: Sentral Alloy Midtown | B4: Apartment/Hotel | C4: Hotel — Suburban/Airport | F4: 0.6 | H4: 0.15 | J4: 360 | N4: No Valet / TAM = $0 | O4: Hotel has no valet (rate field: 'No Valet'). Auto-class: not downtown (by flag or name). Qualitative pipeline only.
A5: Chateau Luxe Event Venue | B5: Event | C5: Unknown type: Event | N5: REVIEW
A6: Warehouse215 | B6: Event | C6: Unknown type: Event | N6: REVIEW
A7: 435 Collective | B7: Event | C7: Unknown type: Event | N7: REVIEW
A8: The Boho Space | B8: Event | C8: Unknown type: Event | N8: REVIEW
A9: The Teapot | B9: Event | C9: Unknown type: Event | N9: REVIEW
A10: monOrchid | B10: Event | C10: Unknown type: Event | N10: REVIEW
A11: The Dauz Venue | B11: Event | C11: Unknown type: Event | N11: REVIEW
A12: Antigua Garden | B12: Event | C12: Unknown type: Event | N12: REVIEW
A13: The Icehouse | B13: Event | C13: Unknown type: Event | N13: REVIEW
A14: Encanto 18 | B14: Event | C14: Unknown type: Event | N14: REVIEW
A15: The Duce | B15: Event | C15: Unknown type: Event | N15: REVIEW
A16: Wedgewood Weddings | B16: Event | C16: Unknown type: Event | N16: REVIEW
... A20: Papago Golf Club | B20: Golf | C20: Unknown type: Golf | N20: REVIEW
A21: Reliance Hospitality | B21: Hospitality Group | C21: Hospital — Qualitative | N21: PIPELINE ONLY | O21: Hospital deals are RFP/profit-share; excluded from TAM until IU Health benchmark formalized
A22: Integrity Lodging | B22: Hospitality Group | C22: Hospital — Qualitative | N22: PIPELINE ONLY | O22: Hospital deals are RFP/profit-share; excluded from TAM until IU Health benchmark formalized
A23: Riot Hospitality Group | B23: Hospitality Group | C23: Hospital — Qualitative | N23: PIPELINE ONLY | O23: Hospital deals are RFP/profit-share; excluded from TAM until IU Health benchmark formalized
A24: Heavlin Management Company (HMC) | B24: Hospitality Group | C24: Hospital — Qualitative | N24: PIPELINE ONLY | O24: Hospital deals are RFP/profit-share; excluded from TAM until IU Health benchmark formalized
A25: Aligned Hospitality Management | B25: Hospitality Group | C25: Hospital — Qualitative | N25: PIPELINE ONLY | O25: Hospital deals are RFP/profit-share; excluded from TAM until IU Health benchmark formalized
A26: Aimbridge Hospitality | B26: Hospitality Group | C26: Hospital — Qualitative | N26: PIPELINE ONLY | O26: Hospital deals are RFP/profit-share; excluded from TAM until IU Health benchmark formalized
A27: Crescent Hotels & Resorts | B27: Hospitality Group | C27: Hospital — Qualitative | N27: PIPELINE ONLY | O27: Hospital deals are RFP/profit-share; excluded from TAM until IU Health benchmark formalized
A28: Southwest Hospitality Management | B28: Hospitality Group | C28: Hospital — Qualitative | N28: PIPELINE ONLY | O28: Hospital deals are RFP/profit-share; excluded from TAM until IU Health benchmark formalized
A29: Desert Hospitality Management | B29: Hospitality Group | C29: Hospital — Qualitative | N29: PIPELINE ONLY | O29: Hospital deals are RFP/profit-share; excluded from TAM until IU Health benchmark formalized
A30: NCG Hospitality | B30: Hospitality Group | C30: Hospital — Qualitative | N30: PIPELINE ONLY | O30: Hospital deals are RFP/profit-share; excluded from TAM until IU Health benchmark formalized
A31: Classic Hotels & Resorts | B31: Hospitality Group | C31: Hospital — Qualitative | N31: PIPELINE ONLY | O31: Hospital deals are RFP/profit-share; excluded from TAM until IU Health benchmark formalized
A32: Carter Concepts Restaurant Group | B32: Hospitality Group | C32: Hospital — Qualitative | N32: PIPELINE ONLY | O32: Hospital deals are RFP/profit-share; excluded from TAM until IU Health benchmark formalized
A33: Courtyard Phoenix Airport | B33: Hotel | C33: Hotel — Suburban/Airport | D33: 145 | F33: 0.6 | H33: 0.15 | J33: 360 | N33: No Valet / TAM = $0 | O33: Hotel has no valet (rate field: 'No Valet'). Auto-class: not downtown (by flag or name). Qualitative pipeline only.
A34: Hilton Phoenix Airport | B34: Hotel | C34: Hotel — Suburban/Airport | D34: 259 | F34: 0.6 | H34: 0.15 | J34: 360 | N34: No Valet / TAM = $0 | O34: Hotel has no valet (rate field: 'No Valet'). Auto-class: not downtown (by flag or name). Qualitative pipeline only.
A35: Marriott Phoenix Airport | B35: Hotel | C35: Hotel — Suburban/Airport | D35: 347 | F35: 0.6 | H35: 0.15 | J35: 360 | N35: No Valet / TAM = $0 | O35: Hotel has no valet (rate field: 'No Valet'). Auto-class: not downtown (by flag or name). Qualitative pipeline only.
A36: Arizona Biltmore, LXR Hotels & Resorts | B36: Hotel | C36: Hotel — Resort | D36: 750 | F36: 0.6 | H36: 0.5 | I36: 30 | J36: 360 | L36: 6750 | M36: 2430000 | N36: Active TAM | O36: Auto-class: resort keyword: 'resort'. Occ 60% flat (refine w/STR).
A37: Embassy Suites by Hilton Phoenix Biltmore | B37: Hotel | C37: Hotel — Suburban/Airport | D37: 232 | F37: 0.6 | H37: 0.15 | J37: 360 | N37: No Valet / TAM = $0 | O37: Hotel has no valet (rate field: 'No Valet'). Auto-class: not downtown (by flag or name). Qualitative pipeline only.
A38: Hampton Inn Phoenix-Biltmore | B38: Hotel | C38: Hotel — Suburban/Airport | D38: 121 | F38: 0.6 | H38: 0.15 | J38: 360 | N38: No Valet / TAM = $0 | O38: Hotel has no valet (rate field: None). Auto-class: not downtown (by flag or name). Qualitative pipeline only.
A39: The Camby, Autograph Collection | B39: Hotel | C39: Hotel — Suburban/Airport | D39: 279 | F39: 0.6 | H39: 0.15 | I39: 40 | J39: 360 | L39: 1004.4 | M39: 361584 | N39: Active TAM | O39: Auto-class: not downtown (by flag or name). Occ 60% flat (refine w/STR).
A40: AC Hotel Phoenix Biltmore | B40: Hotel | C40: Hotel — Suburban/Airport | D40: 160 | F40: 0.6 | H40: 0.15 | J40: 360 | N40: No Valet / TAM = $0 | O40: Hotel has no valet (rate field: 'No Valet'). Auto-class: not downtown (by flag or name). Qualitative pipeline only.
A41: Sonesta Select Phoenix Camelback | B41: Hotel | C41: Hotel — Suburban/Airport | D41: 155 | F41: 0.6 | H41: 0.15 | J41: 360 | N41: No Valet / TAM = $0 | O41: Hotel has no valet (rate field: None). Auto-class: not downtown (by flag or name). Qualitative pipeline only.
A42: Hilton Garden Inn Chandler Downtown | B42: Hotel | C42: Hotel — Downtown Select-Service | D42: 110 | F42: 0.6 | H42: 0.25 | J42: 360 | N42: No Valet / TAM = $0 | O42: Hotel has no valet (rate field: 'No Valet'). Auto-class: downtown full-service <300 rooms [name-inferred downtown]. Qualitative pipeline only.
A43: Element Chandler Fashion Center | B43: Hotel | C43: Hotel — Suburban/Airport | D43: 107 | F43: 0.6 | H43: 0.15 | J43: 360 | N43: No Valet / TAM = $0 | O43: Hotel has no valet (rate field: 'No Valet'). Auto-class: not downtown (by flag or name). Qualitative pipeline only.
...

Sheet TAM_Summary
A1: Phoenix — Conservative TAM Summary
A3: Account Type | B3: # Accounts | C3: TAM | D3: Status
A4: Hotel | B4: 239 | C4: 37116392 | D4: Active TAM
A5: Restaurant | B5: 8 | C5: 1913625 | D5: Active TAM
A6: Hospital | B6: 12 | C6: 0 | D6: Qualitative pipeline only
A7: Unknown | B7: 28 | C7: 0 | D7: ⚠️ Review
A8: TOTAL | B8: 287 | C8: 39030017
A10: HOTEL BREAKDOWN BY CLASS
A11: Class | B11: # Hotels | C11: Conv %
A12: Downtown+Convention | B12: 4 | C12: 0.4
A13: Downtown Select-Service | B13: 21 | C13: 0.25
A14: Resort | B14: 35 | C14: 0.5
A15: Suburban/Airport | B15: 179 | C15: 0.15
A17: RESTAURANTS WITH ACTIVE TAM
A18: Restaurant | B18: Seats | C18: TAM
A19: Maple & Ash | B19: 350 | C19: 318937.5
A20: Ocean 44 | B20: 325 | C20: 296156.25
A21: North Italia | B21: 300 | C21: 273375
A22: STK Steakhouse - Scottsdale | B22: 275 | C22: 250593.75
A23: Toca Madera Scottsdale | B23: 275 | C23: 250593.75
A24: Three Thirty Three Restaurant | B24: 200 | C24: 182250
A25: Montauk | B25: 200 | C25: 182250
A26: Diego Pops | B26: 175 | C26: 159468.75

Sheet TAM_Methodology
A1: SOPHI CONSERVATIVE TAM METHODOLOGY
A3: Replaces original RevenueForecasting formulas. Hospitals / Venues / Airports now qualitative only.
A5: HOTEL FORMULA
A6: TAM = Rooms × Occupancy × Valet Conversion (tiered) × Valet Rate × 360 days
A7: Occupancy: 60% flat across all hotels
A8: ⚠️ FLAG: Refine with STR actuals per-submarket before finalizing fundraise model
A9: Valet Conversion by archetype (auto-classified — review recommended):
A10: Downtown+Convention: 40%
A11: Downtown Select-Service: 25%
A12: Resort: 50%
A13: Suburban/Airport: 15%
A14: Operating Days: 360 (captures soft-closures / transition days)
... A35: 4. Hospital/venue/airport TAM dropped to $0 → build IU Health-benchmarked KPI proxy

Sheet WAS_Scoring_v2
A1: Account | B1: Type | C1: Downtown | D1: Rooms | E1: Valet Op (incumbent) | F1: Valet Rate | G1: Est. Annual Rev (TAM) | H1: Fit (25%) | I1: Size (25%) | J1: Owner Base (20%) | K1: Addr (15%) | L1: Adj (15%) | M1: Rel Lift | N1: Rel Tag | O1: WAS Raw | P1: WAS Final | Q1: Tier | R1: Y1 % | S1: Y2 % | T1: Y3 % | U1: Y4 % | V1: Y5 % | W1: Y1 Rev | X1: Y2 Rev | Y1: Y3 Rev | Z1: Y4 Rev | AA1: Y5 Rev
A2: Kenect Phoenix | B2: Apartment | C2: YES | D2: 0 | F2: No Valet | G2: 0 | H2: 2 | I2: 1 | J2: 2 | K2: 4 | L2: 4 | M2: 0 | O2: 2.35 | P2: 2.35 | Q2: D — Deprioritized | R2: 0 | S2: 0.018 | T2: 0.055 | U2: 0.082 | V2: 0.1 | W2: 0 | X2: 0 | Y2: 0 | Z2: 0 | AA2: 0
A3: Sentral Sol Modern | B3: Apartment/Hotel | C3: YES | D3: 0 | F3: No Valet | G3: 0 | H3: 2 | I3: 1 | J3: 2 | K3: 4 | L3: 4 | M3: 0 | O3: 2.35 | P3: 2.35 | Q3: D — Deprioritized | R3: 0 | S3: 0.018 | T3: 0.055 | U3: 0.082 | V3: 0.1 | W3: 0 | X3: 0 | Y3: 0 | Z3: 0 | AA3: 0
A4: Sentral Alloy Midtown | B4: Apartment/Hotel | C4: NO | D4: 0 | F4: No Valet | G4: 0 | H4: 2 | I4: 1 | J4: 2 | K4: 4 | L4: 2 | M4: 0 | O4: 2.05 | P4: 2.05 | Q4: D — Deprioritized | R4: 0 | S4: 0.018 | T4: 0.055 | U4: 0.082 | V4: 0.1 | W4: 0 | X4: 0 | Y4: 0 | Z4: 0 | AA4: 0
A5: Chateau Luxe Event Venue | B5: Event | C5: NO | D5: 0 | G5: 0 | H5: 2 | I5: 1 | J5: 2 | K5: 4 | L5: 2 | M5: 0 | O5: 2.05 | P5: 2.05 | Q5: D — Deprioritized | R5: 0 | S5: 0.018 | T5: 0.055 | U5: 0.082 | V5: 0.1 | W5: 0 | X5: 0 | Y5: 0 | Z5: 0 | AA5: 0
A6: Warehouse215 | B6: Event | C6: YES | D6: 0 | G6: 0 | H6: 2 | I6: 1 | J6: 2 | K6: 4 | L6: 4 | M6: 0 | O6: 2.35 | P6: 2.35 | Q6: D — Deprioritized | R6: 0 | S6: 0.018 | T6: 0.055 | U6: 0.082 | V6: 0.1 | W6: 0 | X6: 0 | Y6: 0 | Z6: 0 | AA6: 0
A7: 435 Collective | B7: Event | C7: YES | D7: 0 | G7: 0 | H7: 2 | I7: 1 | J7: 2 | K7: 4 | L7: 4 | M7: 0 | O7: 2.35 | P7: 2.35 | Q7: D — Deprioritized | R7: 0 | S7: 0.018 | T7: 0.055 | U7: 0.082 | V7: 0.1 | W7: 0 | X7: 0 | Y7: 0 | Z7: 0 | AA7: 0
A8: The Boho Space | B8: Event | C8: NO | D8: 0 | G8: 0 | H8: 2 | I8: 1 | J8: 2 | K8: 4 | L8: 2 | M8: 0 | O8: 2.05 | P8: 2.05 | Q8: D — Deprioritized | R8: 0 | S8: 0.018 | T8: 0.055 | U8: 0.082 | V8: 0.1 | W8: 0 | X8: 0 | Y8: 0 | Z8: 0 | AA8: 0
A9: The Teapot | B9: Event | C9: NO | D9: 0 | G9: 0 | H9: 2 | I9: 1 | J9: 2 | K9: 4 | L9: 2 | M9: 0 | O9: 2.05 | P9: 2.05 | Q9: D — Deprioritized | R9: 0 | S9: 0.018 | T9: 0.055 | U9: 0.082 | V9: 0.1 | W9: 0 | X9: 0 | Y9: 0 | Z9: 0 | AA9: 0
A10: monOrchid | B10: Event | C10: YES | D10: 0 | G10: 0 | H10: 2 | I10: 1 | J10: 2 | K10: 4 | L10: 4 | M10: 0 | O10: 2.35 | P10: 2.35 | Q10: D — Deprioritized | R10: 0 | S10: 0.018 | T10: 0.055 | U10: 0.082 | V10: 0.1 | W10: 0 | X10: 0 | Y10: 0 | Z10: 0 | AA10: 0
A11: The Dauz Venue | B11: Event | C11: YES | D11: 0 | G11: 0 | H11: 2 | I11: 1 | J11: 2 | K11: 4 | L11: 4 | M11: 0 | O11: 2.35 | P11: 2.35 | Q11: D — Deprioritized | R11: 0 | S11: 0.018 | T11: 0.055 | U11: 0.082 | V11: 0.1 | W11: 0 | X11: 0 | Y11: 0 | Z11: 0 | AA11: 0
A12: Antigua Garden | B12: Event | C12: YES | D12: 0 | G12: 0 | H12: 2 | I12: 1 | J12: 2 | K12: 4 | L12: 4 | M12: 0 | O12: 2.35 | P12: 2.35 | Q12: D — Deprioritized | R12: 0 | S12: 0.018 | T12: 0.055 | U12: 0.082 | V12: 0.1 | W12: 0 | X12: 0 | Y12: 0 | Z12: 0 | AA12: 0
A13: The Icehouse | B13: Event | C13: YES | D13: 0 | G13: 0 | H13: 2 | I13: 1 | J13: 2 | K13: 4 | L13: 4 | M13: 0 | O13: 2.35 | P13: 2.35 | Q13: D — Deprioritized | R13: 0 | S13: 0.018 | T13: 0.055 | U13: 0.082 | V13: 0.1 | W13: 0 | X13: 0 | Y13: 0 | Z13: 0 | AA13: 0
A14: Encanto 18 | B14: Event | C14: YES | D14: 0 | G14: 0 | H14: 2 | I14: 1 | J14: 2 | K14: 4 | L14: 4 | M14: 0 | O14: 2.35 | P14: 2.35 | Q14: D — Deprioritized | R14: 0 | S14: 0.018 | T14: 0.055 | U14: 0.082 | V14: 0.1 | W14: 0 | X14: 0 | Y14: 0 | Z14: 0 | AA14: 0
A15: The Duce | B15: Event | C15: YES | D15: 0 | G15: 0 | H15: 2 | I15: 1 | J15: 2 | K15: 4 | L15: 4 | M15: 0 | O15: 2.35 | P15: 2.35 | Q15: D — Deprioritized | R15: 0 | S15: 0.018 | T15: 0.055 | U15: 0.082 | V15: 0.1 | W15: 0 | X15: 0 | Y15: 0 | Z15: 0 | AA15: 0
A16: Wedgewood Weddings | B16: Event | C16: NO | D16: 0 | G16: 0 | H16: 2 | I16: 1 | J16: 2 | K16: 4 | L16: 2 | M16: 0 | O16: 2.05 | P16: 2.05 | Q16: D — Deprioritized | R16: 0 | S16: 0.018 | T16: 0.055 | U16: 0.082 | V16: 0.1 | W16: 0 | X16: 0 | Y16: 0 | Z16: 0 | AA16: 0
... A32: Carter Concepts Restaurant Group | B32: Hospitality Group | C32: NO | D32: 0 | G32: 0 | H32: 3 | I32: 1 | J32: 2 | K32: 4 | L32: 2 | M32: 0 | O32: 2.3 | P32: 2.3 | Q32: D — Deprioritized | R32: 0 | S32: 0.018 | T32: 0.055 | U32: 0.082 | V32: 0.1 | W32: 0 | X32: 0 | Y32: 0 | Z32: 0 | AA32: 0
A33: Courtyard Phoenix Airport | B33: Hotel | C33: NO | D33: 145 | F33: No Valet | G33: 0 | H33: 3 | I33: 1 | J33: 3 | K33: 4 | L33: 2 | M33: 0 | O33: 2.5 | P33: 2.5 | Q33: C — Opportunistic | R33: 0.02 | S33: 0.09724 | T33: 0.28625 | U33: 0.4145 | V33: 0.5 | W33: 0 | X33: 0 | Y33: 0 | Z33: 0 | AA33: 0
A34: Hilton Phoenix Airport | B34: Hotel | C34: NO | D34: 259 | F34: No Valet | G34: 0 | H34: 4 | I34: 1 | J34: 3 | K34: 4 | L34: 2 | M34: 0.15 | N34: Brand familiarity (historical): Hilton_family | O34: 2.75 | P34: 2.9 | Q34: C — Opportunistic | R34: 0.02 | S34: 0.09724 | T34: 0.28625 | U34: 0.4145 | V34: 0.5 | W34: 0 | X34: 0 | Y34: 0 | Z34: 0 | AA34: 0
A35: Marriott Phoenix Airport | B35: Hotel | C35: NO | D35: 347 | F35: No Valet | G35: 0 | H35: 4 | I35: 1 | J35: 3 | K35: 4 | L35: 2 | M35: 0.3 | N35: Brand familiarity (current): Marriott_family | O35: 2.75 | P35: 3.05 | Q35: C — Opportunistic | R35: 0.02 | S35: 0.09724 | T35: 0.28625 | U35: 0.4145 | V35: 0.5 | W35: 0 | X35: 0 | Y35: 0 | Z35: 0 | AA35: 0
A36: Arizona Biltmore, LXR Hotels & Resorts | B36: Hotel | C36: NO | D36: 750 | F36: valet only | G36: 2430000 | H36: 5 | I36: 4 | J36: 2 | K36: 4 | L36: 2 | M36: 0.15 | N36: Brand familiarity (historical): Hilton_family | O36: 3.55 | P36: 3.7 | Q36: B — Core | R36: 0.08 | S36: 0.22066 | T36: 0.560625 | U36: 0.78675 | V36: 0.9375 | W36: 194400 | X36: 536203.8 | Y36: 1362318.8 | Z36: 1911802.5 | AA36: 2278125
A37: Embassy Suites by Hilton Phoenix Biltmore | B37: Hotel | C37: NO | D37: 232 | F37: No Valet | G37: 0 | H37: 3 | I37: 1 | J37: 3 | K37: 4 | L37: 2 | M37: 0.15 | N37: Brand familiarity (historical): Hilton_family | O37: 2.5 | P37: 2.65 | Q37: C — Opportunistic | R37: 0.02 | S37: 0.09724 | T37: 0.28625 | U37: 0.4145 | V37: 0.5 | W37: 0 | X37: 0 | Y37: 0 | Z37: 0 | AA37: 0
A38: Hampton Inn Phoenix-Biltmore | B38: Hotel | C38: NO | D38: 121 | G38: 0 | H38: 3 | I38: 1 | J38: 3 | K38: 4 | L38: 2 | M38: 0.15 | N38: Brand familiarity (historical): Hilton_family | O38: 2.5 | P38: 2.65 | Q38: C — Opportunistic | R38: 0.02 | S38: 0.09724 | T38: 0.28625 | U38: 0.4145 | V38: 0.5 | W38: 0 | X38: 0 | Y38: 0 | Z38: 0 | AA38: 0
A39: The Camby, Autograph Collection | B39: Hotel | C39: NO | D39: 279 | F39: 40 | G39: 361584 | H39: 4 | I39: 2 | J39: 3 | K39: 4 | L39: 2 | M39: 0.3 | N39: Brand familiarity (current): Marriott_family | O39: 3 | P39: 3.3 | Q39: C — Opportunistic | R39: 0.02 | S39: 0.09724 | T39: 0.28625 | U39: 0.4145 | V39: 0.5 | W39: 7231.68 | X39: 35160.428 | Y39: 103503.42 | Z39: 149876.57 | AA39: 180792
A40: AC Hotel Phoenix Biltmore | B40: Hotel | C40: NO | D40: 160 | F40: No Valet | G40: 0 | H40: 3 | I40: 1 | J40: 2 | K40: 4 | L40: 2 | M40: 0 | O40: 2.3 | P40: 2.3 | Q40: D — Deprioritized | R40: 0 | S40: 0.018 | T40: 0.055 | U40: 0.082 | V40: 0.1 | W40: 0 | X40: 0 | Y40: 0 | Z40: 0 | AA40: 0
A41: Sonesta Select Phoenix Camelback | B41: Hotel | C41: NO | D41: 155 | G41: 0 | H41: 3 | I41: 1 | J41: 2 | K41: 4 | L41: 2 | M41: 0 | O41: 2.3 | P41: 2.3 | Q41: D — Deprioritized | R41: 0 | S41: 0.018 | T41: 0.055 | U41: 0.082 | V41: 0.1 | W41: 0 | X41: 0 | Y41: 0 | Z41: 0 | AA41: 0
A42: Hilton Garden Inn Chandler Downtown | B42: Hotel | C42: NO | D42: 110 | F42: No Valet | G42: 0 | H42: 3 | I42: 1 | J42: 3 | K42: 4 | L42: 2 | M42: 0.15 | N42: Brand familiarity (historical): Hilton_family | O42: 2.5 | P42: 2.65 | Q42: C — Opportunistic | R42: 0.02 | S42: 0.09724 | T42: 0.28625 | U42: 0.4145 | V42: 0.5 | W42: 0 | X42: 0 | Y42: 0 | Z42: 0 | AA42: 0
A43: Element Chandler Fashion Center | B43: Hotel | C43: NO | D43: 107 | F43: No Valet | G43: 0 | H43: 3 | I43: 1 | J43: 2 | K43: 4 | L43: 2 | M43: 0 | O43: 2.3 | P43: 2.3 | Q43: D — Deprioritized | R43: 0 | S43: 0.018 | T43: 0.055 | U43: 0.082 | V43: 0.1 | W43: 0 | X43: 0 | Y43: 0 | Z43: 0 | AA43: 0
A44: AC Hotel Phoenix Downtown | B44: Hotel | C44: YES | D44: 199 | F44: No Valet | G44: 0 | H44: 4 | I44: 1 | J44: 2 | K44: 4 | L44: 4 | M44: 0 | O44: 2.85 | P44: 2.85 | Q44: C — Opportunistic | R44: 0.02 | S44: 0.09724 | T44: 0.28625 | U44: 0.4145 | V44: 0.5 | W44: 0 | X44: 0 | Y44: 0 | Z44: 0 | AA44: 0
A45: Embassy Suites by Hilton Phoenix Downtown North | B45: Hotel | C45: YES | D45: 242 | F45: No Valet | G45: 0 | H45: 4 | I45: 1 | J45: 3 | K45: 4 | L45: 4 | M45: 0.15 | N45: Brand familiarity (historical): Hilton_family | O45: 3.05 | P45: 3.2 | Q45: C — Opportunistic | R45: 0.02 | S45: 0.09724 | T45: 0.28625 | U45: 0.4145 | V45: 0.5 | W45: 0 | X45: 0 | Y45: 0 | Z45: 0 | AA45: 0
A46: Cambria Hotel Downtown Phoenix Convention Center | B46: Hotel | C46: YES | D46: 127 | E46: Premium Parking | F46: 41 | G46: 449884.8 | H46: 3 | I46: 2 | J46: 2 | K46: 3 | L46: 4 | M46: 0 | O46: 2.7 | P46: 2.7 | Q46: C — Opportunistic | R46: 0.02 | S46: 0.09724 | T46: 0.28625 | U46: 0.4145 | V46: 0.5 | W46: 8997.696 | X46: 43746.798 | Y46: 128779.52 | Z46: 186477.25 | AA46: 224942.4
